Workbook

Sheet Proyecto
B2: Datos del proyecto
B3: Las celdas en ambar son las que hay que llenar. Vienen con Cajamarca de ejemplo.
B6: IDENTIFICACION
B7: Nombre del proyecto | D7: PTAR Ficticia
B8: Moneda | D8: S/ miles | E8: todo el libro en la misma unidad
B9: CRONOGRAMA
B10: Fecha de cierre del contrato | D10: 2027-01-31
B11: Fecha de cierre financiero | D11: 2028-03-31
B12: Inicio de obras | D12: 2028-04-30
B13: Fin de obras y puesta en marcha | D13: 2031-03-31
B14: Inicio de operacion | D14: 2031-03-31 | E14: arranca el PPDMO
B15: Fin de la concesion | D15: 2051-03-31
B16: Curva de la construccion | D16: malla | E16: malla | uniforme | adelantada | S simetrica | atrasada | beta
B17: Parametro a de la curva | D17: 1.25 | E17: solo con `beta`; Cajamarca 1.35, San Martin 1.20
B18: Parametro b de la curva | D18: 2 | E18: solo con `beta`; Cajamarca 2.45, San Martin 1.75
B19: Desembolso inicial de obra | D19: 0 | E19: % del CAPEX de la ventana de obra que cae entero en su primer mes; no aplica con `malla`
B20: ESQUEMA DE PAGO
B21: Regimen de la APP | D21: autofinanciada | E21: cofinanciada (activo financiero) | autofinanciada (activo intangible)
B22: Pago del PPDI | D22: por hitos | E22: al final de obra | por hitos
B23: Numero de cuotas del PPDI | D23: 48 | E23: trimestrales
B24: Factor de conversion a kg DBO5 | D24: 0.38 | E24: kg por m3
B25: FINANCIAMIENTO
B26: Tamano de deuda | D26: 0.7 | E26: % del costo de obra
B27: Spread sobre el soberano | D27: 0.04 | E27: sondeo de mercado
B28: Servicio de la deuda | D28: lo fija el esquema de pago | E28: al final de obra = cuota constante | por hitos = por cobertura
B29: Inicio del pago de deuda | D29: 2031-04-30
B30: Fin del pago de deuda | D30: 2043-03-31
B31: Costo de estructuracion | D31: 0.015 | E31: sobre la linea aprobada
B32: Comision por no uso | D32: 0.0075 | E32: anual, sobre la linea no utilizada
B33: Cobertura minima RCSD | D33: 1.25 | E33: SOLO en la rama por hitos; la de final de obra la ignora
B34: Cuenta de reserva CRSD | D34: 0.5 | E34: SOLO en la rama por hitos; del servicio del ano siguiente
B35: REAJUSTE
B36: IPM, reajuste de ingresos | D36: 0.0267 | E36: anual
B37: Gatillo del reajuste | D37: 0.03 | E37: acumulado que dispara el ajuste
B38: IPC, reajuste de costos | D38: 0.02 | E38: anual, sin gatillo
B39: Indice de costos al inicio de O&M | D39: 1.1095603 | E39: IPC acumulado desde la fecha de los precios constantes
B40: Indice de CAPEX al cierre del contrato | D40: 1.0216846 | E40: IPC acumulado desde la fecha de los precios constantes
B41: TRIBUTOS Y MARGENES
B42: IGV | D42: 0.18
B43: Zona con exoneracion de IGV (ley de la Amazonia) | D43: 0 | E43: 1 = el PPD no lleva IGV y el de O&M es costo no recuperable | 0 = se repercute y se acredita
...

Sheet Cronograma
B2: Cronograma por hitos
B3: Con la forma de la hoja `Inputs` del libro de Cajamarca. Los meses se cuentan desde el cierre del contrato; las fechas se derivan solas.
B5: Etapa | D5: Desde (mes) | E5: Hasta (mes) | F5: Meses | G5: F. Inicio | H5: F. Fin | I5: En el libro
B6: ESTUDIOS TECNICOS
B7: Elaboracion y presentacion completa | F7: =E7-D7 | G7: =IF(D7=0,Proyecto!$D$10,TEXT(EOMONTH(DATEVALUE(Proyecto!$D$10),D7-1),"yyyy-mm-dd")) | H7: =IF(E7=0,Proyecto!$D$10,TEXT(EOMONTH(DATEVALUE(Proyecto!$D$10),E7-1),"yyyy-mm-dd")) | I7: Inputs!110
B8: Conformidad | F8: =E8-D8 | G8: =IF(D8=0,Proyecto!$D$10,TEXT(EOMONTH(DATEVALUE(Proyecto!$D$10),D8-1),"yyyy-mm-dd")) | H8: =IF(E8=0,Proyecto!$D$10,TEXT(EOMONTH(DATEVALUE(Proyecto!$D$10),E8-1),"yyyy-mm-dd")) | I8: Inputs!111
B9: CIERRE FINANCIERO
B10: Fecha de cierre financiero | D10: 15 | E10: 15 | F10: =E10-D10 | G10: =IF(D10=0,Proyecto!$D$10,TEXT(EOMONTH(DATEVALUE(Proyecto!$D$10),D10-1),"yyyy-mm-dd")) | H10: =IF(E10=0,Proyecto!$D$10,TEXT(EOMONTH(DATEVALUE(Proyecto!$D$10),E10-1),"yyyy-mm-dd")) | I10: Inputs!113
B11: OBRAS
B12: Inicio de obra | D12: 16 | E12: 16 | F12: =E12-D12 | G12: =IF(D12=0,Proyecto!$D$10,TEXT(EOMONTH(DATEVALUE(Proyecto!$D$10),D12-1),"yyyy-mm-dd")) | H12: =IF(E12=0,Proyecto!$D$10,TEXT(EOMONTH(DATEVALUE(Proyecto!$D$10),E12-1),"yyyy-mm-dd")) | I12: Inputs!115
B13: Fin de obra | F13: =E13-D13 | G13: =IF(D13=0,Proyecto!$D$10,TEXT(EOMONTH(DATEVALUE(Proyecto!$D$10),D13-1),"yyyy-mm-dd")) | H13: =IF(E13=0,Proyecto!$D$10,TEXT(EOMONTH(DATEVALUE(Proyecto!$D$10),E13-1),"yyyy-mm-dd")) | I13: Inputs!116
B14: Puesta en marcha | F14: =E14-D14 | G14: =IF(D14=0,Proyecto!$D$10,TEXT(EOMONTH(DATEVALUE(Proyecto!$D$10),D14-1),"yyyy-mm-dd")) | H14: =IF(E14=0,Proyecto!$D$10,TEXT(EOMONTH(DATEVALUE(Proyecto!$D$10),E14-1),"yyyy-mm-dd")) | I14: Inputs!118
B15: Certificacion de obra | F15: =E15-D15 | G15: =IF(D15=0,Proyecto!$D$10,TEXT(EOMONTH(DATEVALUE(Proyecto!$D$10),D15-1),"yyyy-mm-dd")) | H15: =IF(E15=0,Proyecto!$D$10,TEXT(EOMONTH(DATEVALUE(Proyecto!$D$10),E15-1),"yyyy-mm-dd")) | I15: Inputs!119
B16: Certificado de puesta en marcha | F16: =E16-D16 | G16: =IF(D16=0,Proyecto!$D$10,TEXT(EOMONTH(DATEVALUE(Proyecto!$D$10),D16-1),"yyyy-mm-dd")) | H16: =IF(E16=0,Proyecto!$D$10,TEXT(EOMONTH(DATEVALUE(Proyecto!$D$10),E16-1),"yyyy-mm-dd")) | I16: Inputs!121
B17: Ejecucion de obras y puesta en marcha | D17: 16 | E17: 51 | F17: =E17-D17 | G17: =IF(D17=0,Proyecto!$D$10,TEXT(EOMONTH(DATEVALUE(Proyecto!$D$10),D17-1),"yyyy-mm-dd")) | H17: =IF(E17=0,Proyecto!$D$10,TEXT(EOMONTH(DATEVALUE(Proyecto!$D$10),E17-1),"yyyy-mm-dd")) | I17: Inputs!122
B18: PAGOS
B19: Vigencia del periodo de PPDI | F19: =E19-D19 | G19: =IF(D19=0,Proyecto!$D$10,TEXT(EOMONTH(DATEVALUE(Proyecto!$D$10),D19-1),"yyyy-mm-dd")) | H19: =IF(E19=0,Proyecto!$D$10,TEXT(EOMONTH(DATEVALUE(Proyecto!$D$10),E19-1),"yyyy-mm-dd")) | I19: Inputs!124
B20: PPDMO | F20: =E20-D20 | G20: =IF(D20=0,Proyecto!$D$10,TEXT(EOMONTH(DATEVALUE(Proyecto!$D$10),D20-1),"yyyy-mm-dd")) | H20: =IF(E20=0,Proyecto!$D$10,TEXT(EOMONTH(DATEVALUE(Proyecto!$D$10),E20-1),"yyyy-mm-dd")) | I20: Inputs!127:128
B21: Pago de deuda | D21: 52 | E21: 195 | F21: =E21-D21 | G21: =IF(D21=0,Proyecto!$D$10,TEXT(EOMONTH(DATEVALUE(Proyecto!$D$10),D21-1),"yyyy-mm-dd")) | H21: =IF(E21=0,Proyecto!$D$10,TEXT(EOMONTH(DATEVALUE(Proyecto!$D$10),E21-1),"yyyy-mm-dd")) | I21: Inputs!130
B22: Periodo de O&M | D22: 51 | E22: 291 | F22: =E22-D22 | G22: =IF(D22=0,Proyecto!$D$10,TEXT(EOMONTH(DATEVALUE(Proyecto!$D$10),D22-1),"yyyy-mm-dd")) | H22: =IF(E22=0,Proyecto!$D$10,TEXT(EOMONTH(DATEVALUE(Proyecto!$D$10),E22-1),"yyyy-mm-dd")) | I22: Inputs!143
B24: Las fechas sueltas de `Proyecto` salen de esta hoja: el motor prefiere el cronograma y solo cae a `Proyecto` si esta hoja no esta.

Sheet CAPEX
B2: CAPEX
B3: Malla mensual de inversion a PRECIOS CONSTANTES, en S/ miles, sin IGV. El motor le aplica el indice de CAPEX.
B5: Mes | D5: Inversion
B6: 2027-01-31 | D6: 0
B7: 2027-02-28 | D7: 420
B8: 2027-03-31 | D8: 420
B9: 2027-04-30 | D9: 420
B10: 2027-05-31 | D10: 420
B11: 2027-06-30 | D11: 420
B12: 2027-07-31 | D12: 420
B13: 2027-08-31 | D13: 420
B14: 2027-09-30 | D14: 420
B15: 2027-10-31 | D15: 420
B16: 2027-11-30 | D16: 420
B17: 2027-12-31 | D17: 420
... B317: 2052-12-31 | D317: 0

Sheet OPEX
B2: OPEX y demanda
B3: Por ano de concesion, en soles del ano base. El reajuste lo pone el motor.
B5: Ano de concesion | D5: 5 | E5: 6 | F5: 7 | G5: 8 | H5: 9 | I5: 10 | J5: 11 | K5: 12 | L5: 13 | M5: 14 | N5: 15 | O5: 16 | P5: 17 | Q5: 18 | R5: 19 | S5: 20 | T5: 21 | U5: 22 | V5: 23 | W5: 24 | X5: 25
B6: Ano calendario | D6: 2031 | E6: 2032 | F6: 2033 | G6: 2034 | H6: 2035 | I6: 2036 | J6: 2037 | K6: 2038 | L6: 2039 | M6: 2040 | N6: 2041 | O6: 2042 | P6: 2043 | Q6: 2044 | R6: 2045 | S6: 2046 | T6: 2047 | U6: 2048 | V6: 2049 | W6: 2050 | X6: 2051
B8: FIJOS
B9: Personal | D9: 2050000 | E9: 2050000 | F9: 2050000 | G9: 2050000 | H9: 2050000 | I9: 2050000 | J9: 2050000 | K9: 2050000 | L9: 2050000 | M9: 2050000 | N9: 2050000 | O9: 2050000 | P9: 2050000 | Q9: 2050000 | R9: 2050000 | S9: 2050000 | T9: 2050000 | U9: 2050000 | V9: 2050000 | W9: 2050000 | X9: 2050000
B10: Mantenimiento de obra civil | D10: 480000 | E10: 480000 | F10: 480000 | G10: 480000 | H10: 480000 | I10: 480000 | J10: 480000 | K10: 480000 | L10: 480000 | M10: 480000 | N10: 480000 | O10: 480000 | P10: 480000 | Q10: 480000 | R10: 480000 | S10: 480000 | T10: 480000 | U10: 480000 | V10: 480000 | W10: 480000 | X10: 480000
B11: Mantenimiento de colectores | D11: 310000 | E11: 310000 | F11: 310000 | G11: 310000 | H11: 310000 | I11: 310000 | J11: 310000 | K11: 310000 | L11: 310000 | M11: 310000 | N11: 310000 | O11: 310000 | P11: 310000 | Q11: 310000 | R11: 310000 | S11: 310000 | T11: 310000 | U11: 310000 | V11: 310000 | W11: 310000 | X11: 310000
B12: Energia electrica | D12: 920000 | E12: 920000 | F12: 920000 | G12: 920000 | H12: 920000 | I12: 920000 | J12: 920000 | K12: 920000 | L12: 920000 | M12: 920000 | N12: 920000 | O12: 920000 | P12: 920000 | Q12: 920000 | R12: 920000 | S12: 920000 | T12: 920000 | U12: 920000 | V12: 920000 | W12: 920000 | X12: 920000
B13: Productos, materiales y servicios | D13: 660000 | E13: 660000 | F13: 660000 | G13: 660000 | H13: 660000 | I13: 660000 | J13: 660000 | K13: 660000 | L13: 660000 | M13: 660000 | N13: 660000 | O13: 660000 | P13: 660000 | Q13: 660000 | R13: 660000 | S13: 660000 | T13: 660000 | U13: 660000 | V13: 660000 | W13: 660000 | X13: 660000
B14: Gestion, monitoreo y ensayos | D14: 340000 | E14: 340000 | F14: 340000 | G14: 340000 | H14: 340000 | I14: 340000 | J14: 340000 | K14: 340000 | L14: 340000 | M14: 340000 | N14: 340000 | O14: 340000 | P14: 340000 | Q14: 340000 | R14: 340000 | S14: 340000 | T14: 340000 | U14: 340000 | V14: 340000 | W14: 340000 | X14: 340000
B15: Reposiciones | D15: 0 | E15: 0 | F15: 0 | G15: 0 | H15: 0 | I15: 0 | J15: 0 | K15: 0 | L15: 0 | M15: 3600000 | N15: 0 | O15: 0 | P15: 0 | Q15: 0 | R15: 3600000 | S15: 0 | T15: 0 | U15: 0 | V15: 0 | W15: 3600000 | X15: 0
B16: VARIABLES
B17: Energia de la PTAR | D17: 1750000 | E17: 1771000 | F17: 1792252 | G17: 1813759 | H17: 1835524.1 | I17: 1857550.4 | J17: 1879841 | K17: 1902399.1 | L17: 1925227.9 | M17: 1948330.6 | N17: 1971710.6 | O17: 1995371.1 | P17: 2019315.6 | Q17: 2043547.4 | R17: 2068069.9 | S17: 2092886.8 | T17: 2118001.4 | U17: 2143417.4 | V17: 2169138.5 | W17: 2195168.1 | X17: 2221510.1
B18: Consumo de reactivos | D18: 610000 | E18: 617320 | F18: 624727.84 | G18: 632224.57 | H18: 639811.27 | I18: 647489 | J18: 655258.87 | K18: 663121.98 | L18: 671079.44 | M18: 679132.4 | N18: 687281.98 | O18: 695529.37 | P18: 703875.72 | Q18: 712322.23 | R18: 720870.1 | S18: 729520.54 | T18: 738274.78 | U18: 747134.08 | V18: 756099.69 | W18: 765172.89 | X18: 774354.96
B19: Retirada de residuos | D19: 395000 | E19: 399740 | F19: 404536.88 | G19: 409391.32 | H19: 414304.02 | I19: 419275.67 | J19: 424306.97 | K19: 429398.66 | L19: 434551.44 | M19: 439766.06 | N19: 445043.25 | O19: 450383.77 | P19: 455788.38 | Q19: 461257.84 | R19: 466792.93 | S19: 472394.45 | T19: 478063.18 | U19: 483799.94 | V19: 489605.54 | W19: 495480.8 | X19: 501426.57
B20: OTROS
B21: Gastos de la SPV | D21: 520000 | E21: 520000 | F21: 520000 | G21: 520000 | H21: 520000 | I21: 520000 | J21: 520000 | K21: 520000 | L21: 520000 | M21: 520000 | N21: 520000 | O21: 520000 | P21: 520000 | Q21: 520000 | R21: 520000 | S21: 520000 | T21: 520000 | U21: 520000 | V21: 520000 | W21: 520000 | X21: 520000
B22: DEMANDA
B23: Demanda tratada, m3 al ano | D23: 8400000 | E23: 8500800 | F23: 8602809.6 | G23: 8706043.3 | H23: 8810515.8 | I23: 8916242 | J23: 9023236.9 | K23: 9131515.8 | L23: 9241094 | M23: 9351987.1 | N23: 9464210.9 | O23: 9577781.5 | P23: 9692714.8 | Q23: 9809027.4 | R23: 9926735.8 | S23: 10045857 | T23: 10166407 | U23: 10288404 | V23: 10411865 | W23: 10536807 | X23: 10663249

Sheet Otros
B2: Otros costos
B3: Malla mensual en S/ miles. Si el proyecto nuevo no los tiene, van en cero.
D4: PERIODO DE CONSTRUCCION | J4: PERIODO DE OPERACION
B5: Mes | D5: Seguros | E5: Fianzas | F5: Fideicomiso | G5: Gastos de promocion | H5: Garantias | I5: Reembolsos | J5: Seguros | K5: Fianzas | L5: Fideicomiso | M5: Gastos de promocion
B6: 2027-01-31 | D6: 0 | E6: 0 | F6: 0 | G6: 0 | H6: 0 | I6: 6100 | J6: 0 | K6: 0 | L6: 0 | M6: 0
B7: 2027-02-28 | D7: 0 | E7: 0 | F7: 0 | G7: 0 | H7: 0 | I7: 0 | J7: 0 | K7: 0 | L7: 0 | M7: 0
B8: 2027-03-31 | D8: 0 | E8: 0 | F8: 0 | G8: 0 | H8: 0 | I8: 0 | J8: 0 | K8: 0 | L8: 0 | M8: 0
B9: 2027-04-30 | D9: 0 | E9: 0 | F9: 0 | G9: 0 | H9: 0 | I9: 0 | J9: 0 | K9: 0 | L9: 0 | M9: 0
B10: 2027-05-31 | D10: 0 | E10: 0 | F10: 0 | G10: 0 | H10: 0 | I10: 0 | J10: 0 | K10: 0 | L10: 0 | M10: 0
B11: 2027-06-30 | D11: 0 | E11: 0 | F11: 0 | G11: 0 | H11: 0 | I11: 0 | J11: 0 | K11: 0 | L11: 0 | M11: 0
B12: 2027-07-31 | D12: 0 | E12: 0 | F12: 0 | G12: 0 | H12: 0 | I12: 0 | J12: 0 | K12: 0 | L12: 0 | M12: 0
B13: 2027-08-31 | D13: 0 | E13: 0 | F13: 0 | G13: 0 | H13: 0 | I13: 0 | J13: 0 | K13: 0 | L13: 0 | M13: 0
B14: 2027-09-30 | D14: 0 | E14: 0 | F14: 0 | G14: 0 | H14: 0 | I14: 0 | J14: 0 | K14: 0 | L14: 0 | M14: 0
B15: 2027-10-31 | D15: 0 | E15: 0 | F15: 0 | G15: 0 | H15: 0 | I15: 0 | J15: 0 | K15: 0 | L15: 0 | M15: 0
B16: 2027-11-30 | D16: 0 | E16: 0 | F16: 0 | G16: 0 | H16: 0 | I16: 0 | J16: 0 | K16: 0 | L16: 0 | M16: 0
B17: 2027-12-31 | D17: 0 | E17: 0 | F17: 0 | G17: 0 | H17: 0 | I17: 0 | J17: 0 | K17: 0 | L17: 0 | M17: 0
... B317: 2052-12-31 | D317: 0 | E317: 0 | F317: 0 | G317: 0 | H317: 0 | I317: 0 | J317: 0 | K317: 0 | L317: 0 | M317: 0

Sheet Hitos
B2: Hitos funcionales
B3: Solo para el esquema de pago por hitos. Precargada con San Martin.
B6: CRONOGRAMA DEL CONTRATO
B7: Primer ano de la malla | D7: 2027 | E7: la malla arranca en enero de ese ano
B8: Meses de la malla | D8: 312
B9: Inicio del periodo D + C + PM | D9: 2027-02 | E9: AAAA-MM
B10: Fin del periodo D + C + PM | D10: 2031-03 | E10: AAAA-MM
B11: Primer pago del PPDI | D11: 2031-06 | E11: AAAA-MM, luego trimestral
B12: Fin de la operacion | D12: 2051-03 | E12: AAAA-MM, ultimo mes de O&M
B13: Mes del cierre financiero | D13: 15 | E13: contado desde el inicio de D+C+PM
B14: FINANCIAMIENTO
B15: Apalancamiento | D15: 0.7 | E15: deuda sobre necesidades totales
B16: Comision de estructuracion | D16: 0.015 | E16: sobre el total desembolsado
B17: Comision por no uso | D17: 0.0075 | E17: anual, sobre el saldo no desembolsado
B18: APORTES DE CAPITAL
B19: Aporte 1, porcentaje | D19: 0.25
B20: Aporte 1, mes del contrato | D20: 1
B21: Aporte 2, porcentaje | D21: 0.25
B22: Aporte 2, mes del contrato | D22: 10
B23: Aporte 3, porcentaje | D23: 0.5
B24: Aporte 3, mes del contrato | D24: 16
B25: IMPORTES DE UNA VEZ
B26: Capital de trabajo inicial | D26: 1200 | E26: se carga al cierre de la construccion
B27: Periodo medio de pago a proveedores | D27: 1 | E27: meses
B28: REPARTO DEL O&M POR HITO
B29: Hito 1, reparto del O&M | D29: 0.45
B30: Hito 2, reparto del O&M | D30: 0.2
B31: Hito 3, reparto del O&M | D31: 0.2
B32: Hito 4, reparto del O&M | D32: 0.15
B33: CARGA ORGANICA DE REFERENCIA
B34: Sistema 1, kg DBO al ano | D34: 2872800 | E34: la de diseno, no la del primer ano
B35: Sistema 2, kg DBO al ano | D35: 319200
B37: REPARTO DEL CAPEX POR HITO
B38: Hito 1 | D38: 0.7596494
B39: Hito 2 | D39: 0.062513374
B40: Hito 3 | D40: 0.022824984
B41: Hito 4 | D41: 0.15501225

Sheet OPEX hitos
B2: OPEX del esquema por hitos
B3: Por ano calendario y a precios constantes. REGLA: la suma de las cuatro patas por hito de un ano tiene que ser el OPEX de ese ano en la hoja `OPEX`; `opex_consistente.derivar` la escribe sola desde alli. Las lineas con IGV van aparte porque no todas las partidas lo llevan. Precargada con San Martin, que no es el proyecto de la hoja `OPEX`, asi que tal cual viene NO cumple la regla: es solo el ejemplo de la forma.
B5: Ano calendario | D5: 2027 | E5: 2028 | F5: 2029 | G5: 2030 | H5: 2031 | I5: 2032 | J5: 2033 | K5: 2034 | L5: 2035 | M5: 2036 | N5: 2037 | O5: 2038 | P5: 2039 | Q5: 2040 | R5: 2041 | S5: 2042 | T5: 2043 | U5: 2044 | V5: 2045 | W5: 2046 | X5: 2047 | Y5: 2048 | Z5: 2049 | AA5: 2050 | AB5: 2051 | AC5: 2052
B7: COSTOS FIJOS DE O&M, POR HITO
B8: Hito 1 | D8: 0 | E8: 0 | F8: 0 | G8: 0 | H8: 2142 | I8: 2142 | J8: 2142 | K8: 2142 | L8: 2142 | M8: 2142 | N8: 2142 | O8: 2142 | P8: 2142 | Q8: 2142 | R8: 2142 | S8: 2142 | T8: 2142 | U8: 2142 | V8: 2142 | W8: 2142 | X8: 2142 | Y8: 2142 | Z8: 2142 | AA8: 2142 | AB8: 2142 | AC8: 0
B9: Hito 2 | D9: 0 | E9: 0 | F9: 0 | G9: 0 | H9: 952 | I9: 952 | J9: 952 | K9: 952 | L9: 952 | M9: 952 | N9: 952 | O9: 952 | P9: 952 | Q9: 952 | R9: 952 | S9: 952 | T9: 952 | U9: 952 | V9: 952 | W9: 952 | X9: 952 | Y9: 952 | Z9: 952 | AA9: 952 | AB9: 952 | AC9: 0
B10: Hito 3 | D10: 0 | E10: 0 | F10: 0 | G10: 0 | H10: 952 | I10: 952 | J10: 952 | K10: 952 | L10: 952 | M10: 952 | N10: 952 | O10: 952 | P10: 952 | Q10: 952 | R10: 952 | S10: 952 | T10: 952 | U10: 952 | V10: 952 | W10: 952 | X10: 952 | Y10: 952 | Z10: 952 | AA10: 952 | AB10: 952 | AC10: 0
B11: Hito 4 | D11: 0 | E11: 0 | F11: 0 | G11: 0 | H11: 714 | I11: 714 | J11: 714 | K11: 714 | L11: 714 | M11: 714 | N11: 714 | O11: 714 | P11: 714 | Q11: 714 | R11: 714 | S11: 714 | T11: 714 | U11: 714 | V11: 714 | W11: 714 | X11: 714 | Y11: 714 | Z11: 714 | AA11: 714 | AB11: 714 | AC11: 0
B12: LOS MISMOS COSTOS FIJOS, CON IGV
B13: Hito 1 con IGV | D13: 0 | E13: 0 | F13: 0 | G13: 0 | H13: 2463.3 | I13: 2463.3 | J13: 2463.3 | K13: 2463.3 | L13: 2463.3 | M13: 2463.3 | N13: 2463.3 | O13: 2463.3 | P13: 2463.3 | Q13: 2463.3 | R13: 2463.3 | S13: 2463.3 | T13: 2463.3 | U13: 2463.3 | V13: 2463.3 | W13: 2463.3 | X13: 2463.3 | Y13: 2463.3 | Z13: 2463.3 | AA13: 2463.3 | AB13: 2463.3 | AC13: 0
B14: Hito 2 con IGV | D14: 0 | E14: 0 | F14: 0 | G14: 0 | H14: 1094.8 | I14: 1094.8 | J14: 1094.8 | K14: 1094.8 | L14: 1094.8 | M14: 1094.8 | N14: 1094.8 | O14: 1094.8 | P14: 1094.8 | Q14: 1094.8 | R14: 1094.8 | S14: 1094.8 | T14: 1094.8 | U14: 1094.8 | V14: 1094.8 | W14: 1094.8 | X14: 1094.8 | Y14: 1094.8 | Z14: 1094.8 | AA14: 1094.8 | AB14: 1094.8 | AC14: 0
B15: Hito 3 con IGV | D15: 0 | E15: 0 | F15: 0 | G15: 0 | H15: 1094.8 | I15: 1094.8 | J15: 1094.8 | K15: 1094.8 | L15: 1094.8 | M15: 1094.8 | N15: 1094.8 | O15: 1094.8 | P15: 1094.8 | Q15: 1094.8 | R15: 1094.8 | S15: 1094.8 | T15: 1094.8 | U15: 1094.8 | V15: 1094.8 | W15: 1094.8 | X15: 1094.8 | Y15: 1094.8 | Z15: 1094.8 | AA15: 1094.8 | AB15: 1094.8 | AC15: 0
B16: Hito 4 con IGV | D16: 0 | E16: 0 | F16: 0 | G16: 0 | H16: 821.1 | I16: 821.1 | J16: 821.1 | K16: 821.1 | L16: 821.1 | M16: 821.1 | N16: 821.1 | O16: 821.1 | P16: 821.1 | Q16: 821.1 | R16: 821.1 | S16: 821.1 | T16: 821.1 | U16: 821.1 | V16: 821.1 | W16: 821.1 | X16: 821.1 | Y16: 821.1 | Z16: 821.1 | AA16: 821.1 | AB16: 821.1 | AC16: 0
B17: COSTOS VARIABLES DE O&M
B18: Total sin IGV | D18: 0 | E18: 0 | F18: 0 | G18: 0 | H18: 2755 | I18: 2788.06 | J18: 2821.5167 | K18: 2855.3749 | L18: 2889.6394 | M18: 2924.3151 | N18: 2959.4069 | O18: 2994.9198 | P18: 3030.8588 | Q18: 3067.2291 | R18: 3104.0358 | S18: 3141.2843 | T18: 3178.9797 | U18: 3217.1274 | V18: 3255.733 | W18: 3294.8018 | X18: 3334.3394 | Y18: 3374.3515 | Z18: 3414.8437 | AA18: 3455.8218 | AB18: 3497.2917 | AC18: 0
B19: Sistema 1, con IGV | D19: 0 | E19: 0 | F19: 0 | G19: 0 | H19: 2851.425 | I19: 2885.6421 | J19: 2920.2698 | K19: 2955.313 | L19: 2990.7768 | M19: 3026.6661 | N19: 3062.9861 | O19: 3099.7419 | P19: 3136.9389 | Q19: 3174.5821 | R19: 3212.6771 | S19: 3251.2292 | T19: 3290.244 | U19: 3329.7269 | V19: 3369.6836 | W19: 3410.1198 | X19: 3451.0413 | Y19: 3492.4538 | Z19: 3534.3632 | AA19: 3576.7756 | AB19: 3619.6969 | AC19: 0
B20: Sistema 2, con IGV | D20: 0 | E20: 0 | F20: 0 | G20: 0 | H20: 316.825 | I20: 320.6269 | J20: 324.47442 | K20: 328.36812 | L20: 332.30853 | M20: 336.29624 | N20: 340.33179 | O20: 344.41577 | P20: 348.54876 | Q20: 352.73135 | R20: 356.96412 | S20: 361.24769 | T20: 365.58266 | U20: 369.96966 | V20: 374.40929 | W20: 378.9022 | X20: 383.44903 | Y20: 388.05042 | Z20: 392.70702 | AA20: 397.41951 | AB20: 402.18854 | AC20: 0
B21: OTRAS LINEAS DE OPERACION
B22: Gastos generales y utilidad | D22: 0 | E22: 0 | F22: 0 | G22: 0 | H22: 800 | I22: 800 | J22: 800 | K22: 800 | L22: 800 | M22: 800 | N22: 800 | O22: 800 | P22: 800 | Q22: 800 | R22: 800 | S22: 800 | T22: 800 | U22: 800 | V22: 800 | W22: 800 | X22: 800 | Y22: 800 | Z22: 800 | AA22: 800 | AB22: 800 | AC22: 0
B23: Otros costos de la concesion | D23: 0 | E23: 0 | F23: 0 | G23: 0 | H23: 450 | I23: 450 | J23: 450 | K23: 450 | L23: 450 | M23: 450 | N23: 450 | O23: 450 | P23: 450 | Q23: 450 | R23: 450 | S23: 450 | T23: 450 | U23: 450 | V23: 450 | W23: 450 | X23: 450 | Y23: 450 | Z23: 450 | AA23: 450 | AB23: 450 | AC23: 0
B24: IGV de operacion | D24: 0 | E24: 0 | F24: 0 | G24: 0 | H24: 300 | I24: 300 | J24: 300 | K24: 300 | L24: 300 | M24: 300 | N24: 300 | O24: 300 | P24: 300 | Q24: 300 | R24: 300 | S24: 300 | T24: 300 | U24: 300 | V24: 300 | W24: 300 | X24: 300 | Y24: 300 | Z24: 300 | AA24: 300 | AB24: 300 | AC24: 0
B25: Reposiciones | D25: 0 | E25: 0 | F25: 0 | G25: 0 | H25: 0 | I25: 0 | J25: 0 | K25: 0 | L25: 0 | M25: 0 | N25: 0 | O25: 0 | P25: 0 | Q25: 3600 | R25: 0 | S25: 0 | T25: 0 | U25: 0 | V25: 3600 | W25: 0 | X25: 0 | Y25: 0 | Z25: 0 | AA25: 3600 | AB25: 0 | AC25: 0
B26: Pago por obras | D26: 0 | E26: 0 | F26: 0 | G26: 0 | H26: 0 | I26: 0 | J26: 0 | K26: 0 | L26: 0 | M26: 0 | N26: 0 | O26: 0 | P26: 0 | Q26: 0 | R26: 0 | S26: 0 | T26: 0 | U26: 0 | V26: 0 | W26: 0 | X26: 0 | Y26: 0 | Z26: 0 | AA26: 0 | AB26: 0 | AC26: 0
B27: Costos de cierre | D27: 0 | E27: 0 | F27: 0 | G27: 0 | H27: 0 | I27: 0 | J27: 0 | K27: 0 | L27: 0 | M27: 0 | N27: 0 | O27: 0 | P27: 0 | Q27: 0 | R27: 0 | S27: 0 | T27: 0 | U27: 0 | V27: 0 | W27: 0 | X27: 0 | Y27: 0 | Z27: 0 | AA27: 0 | AB27: 0 | AC27: 0
B28: CARGA ORGANICA REMOVIDA, kg DBO AL ANO
B29: Sistema 1 | D29: 2872800 | E29: 2872800 | F29: 2872800 | G29: 2872800 | H29: 2872800 | I29: 2907273.6 | J29: 2942160.9 | K29: 2977466.8 | L29: 3013196.4 | M29: 3049354.8 | N29: 3085947 | O29: 3122978.4 | P29: 3160454.1 | Q29: 3198379.6 | R29: 3236760.1 | S29: 3275601.3 | T29: 3314908.5 | U29: 3354687.4 | V29: 3394943.6 | W29: 3435683 | X29: 3476911.1 | Y29: 3518634.1 | Z29: 3560857.7 | AA29: 3603588 | AB29: 3646831 | AC29: 3690593
B30: Sistema 2 | D30: 319200 | E30: 319200 | F30: 319200 | G30: 319200 | H30: 319200 | I30: 323030.4 | J30: 326906.76 | K30: 330829.65 | L30: 334799.6 | M30: 338817.2 | N30: 342883 | O30: 346997.6 | P30: 351161.57 | Q30: 355375.51 | R30: 359640.02 | S30: 363955.7 | T30: 368323.16 | U30: 372743.04 | V30: 377215.96 | W30: 381742.55 | X30: 386323.46 | Y30: 390959.34 | Z30: 395650.85 | AA30: 400398.66 | AB30: 405203.45 | AC30: 410065.89
