Workbook
Name p_costo_obra: Inputs!$D$6
Name p_tamano_deuda: Inputs!$D$7
Name p_kd: Inputs!$D$8
Name p_spread: Inputs!$D$9
Name p_ke: Inputs!$D$10
Name p_wacc: Inputs!$D$11
Name p_pagos: Inputs!$D$12
Name p_ipm: Inputs!$D$13
Name p_gatillo: Inputs!$D$14
Name p_ipc: Inputs!$D$15
Name p_ir: Inputs!$D$16
Name p_part: Inputs!$D$17
Name p_superv: Inputs!$D$18
Name p_igv: Inputs!$D$19
Name p_tarifa_usuario: Inputs!$D$20
Name p_margen_om: Inputs!$D$21

Sheet Resumen
B2: Resumen del modelo, APP autofinanciada
B3: S/ miles sin IGV. No hay PPDI ni PPDMO: el proyecto se paga con la tarifa al usuario.
B6: Tarifa al usuario, S/ por kg DBO5 | D6: =p_tarifa_usuario
B7: Ingreso tarifario, primer mes de operacion anualizado | D7: =SUMPRODUCT(Ingresos!$D$15:$LI$15,Ingresos!$D$14:$LI$14)*12
B8: Ingreso tarifario, promedio mensual de la operacion | D8: =SUMPRODUCT(Ingresos!$D$7:$LI$7,Ingresos!$D$14:$LI$14)/SUM(Ingresos!$D$7:$LI$7)
B9: Tarifa que paga la operacion con su margen, S/ por kg DBO5 | D9: =p_tarifa_usuario*'Reparto de la tarifa'!$D$26
B10: Tarifa que repaga la inversion, S/ por kg DBO5 | D10: =p_tarifa_usuario*'Reparto de la tarifa'!$D$27
B11: VAN del ingreso tarifario | D11: ='Reparto de la tarifa'!$D$22
B12: del que va a la operacion | D12: ='Reparto de la tarifa'!$D$24
B13: del que repaga la inversion | D13: ='Reparto de la tarifa'!$D$25
B14: Activo intangible al termino de obra | D14: ='Activo intangible'!$D$8
B15: Amortizacion lineal mensual | D15: ='Activo intangible'!$D$9
B16: Meses de operacion | D16: ='Activo intangible'!$D$7
B17: Saldo final del intangible, debe ser cero | D17: ='Activo intangible'!$LI$18
B18: VAN financiero, debe ser cero | D18: =Flujo!$D$29
B19: WACC | D19: =p_wacc
B20: Kd | D20: =p_kd
B21: Ke | D21: =p_ke

Sheet Inputs
B2: Parametros del modelo
B3: Las celdas en ambar son de entrada. Las dos ultimas las resuelve el cierre.
B6: Costo de obra a financiar | D6: 261144.81 | E6: S/ miles
B7: Tamano de deuda | D7: 0.8 | E7: % del costo de obra
B8: Kd, costo de la deuda | D8: 0.10092957 | E8: soberano a vida media + spread
B9: Spread de deuda | D9: 0.035 | E9: sondeo de mercado
B10: Ke, costo del patrimonio | D10: 0.12622649 | E10: CAPM en USD + riesgo pais + devaluacion
B11: WACC | D11: 0.097303479 | E11: despues de impuestos
B12: Numero de pagos de la deuda | D12: 144 | E12: meses
B13: IPM, reajuste de ingresos | D13: 0.0267 | E13: anual
B14: Gatillo del reajuste | D14: 0.03 | E14: acumulado que dispara el ajuste
B15: IPC, reajuste de costos | D15: 0.02 | E15: anual, sin gatillo
B16: Tasa de Impuesto a la Renta | D16: 0.295
B17: Participacion de trabajadores | D17: 0.05
B18: Supervision del regulador | D18: 0.01 | E18: % del ingreso tarifario
B19: IGV | D19: 0.18 | E19: lo paga el usuario sobre la tarifa
B20: Tarifa al usuario | D20: 9.4608605 | E20: S/ por kg DBO5 - LA CIERRA Buscar Objetivo
B21: Margen del operador | D21: 0.15 | E21: sobre todo el costo de O&M; aca no hay pata fija y variable

Sheet Deuda
B2: Deuda financiera
B3: Cuota constante: el servicio sale de PMT y la amortizacion es el residuo.
B6: Mes | D6: 2026-10-31 | E6: 2026-11-30 | F6: 2026-12-31 | G6: 2027-01-31 | H6: 2027-02-28 | I6: 2027-03-31 | J6: 2027-04-30 | K6: 2027-05-31 | L6: 2027-06-30 | M6: 2027-07-31 | N6: 2027-08-31 | O6: 2027-09-30 | P6: 2027-10-31 | Q6: 2027-11-30 | R6: 2027-12-31 | S6: 2028-01-31 | T6: 2028-02-29 | U6: 2028-03-31 | V6: 2028-04-30 | W6: 2028-05-31 | X6: 2028-06-30 | Y6: 2028-07-31 | Z6: 2028-08-31 | AA6: 2028-09-30 | AB6: 2028-10-31 | AC6: 2028-11-30 | AD6: 2028-12-31 | AE6: 2029-01-31 | AF6: 2029-02-28 | AG6: 2029-03-31 | AH6: 2029-04-30 | AI6: 2029-05-31 | AJ6: 2029-06-30 | AK6: 2029-07-31 | AL6: 2029-08-31 | AM6: 2029-09-30 | AN6: 2029-10-31 | AO6: 2029-11-30 | AP6: 2029-12-31 | AQ6: 2030-01-31 | AR6: 2030-02-28 | AS6: 2030-03-31 | AT6: 2030-04-30 | AU6: 2030-05-31 | AV6: 2030-06-30 | AW6: 2030-07-31 | AX6: 2030-08-31 | AY6: 2030-09-30 | AZ6: 2030-10-31 | BA6: 2030-11-30 | BB6: 2030-12-31 | BC6: 2031-01-31 | BD6: 2031-02-28 | BE6: 2031-03-31 | BF6: 2031-04-30 | BG6: 2031-05-31 | BH6: 2031-06-30 | BI6: 2031-07-31 | BJ6: 2031-08-31 | BK6: 2031-09-30 | BL6: 2031-10-31 | BM6: 2031-11-30 | BN6: 2031-12-31 | BO6: 2032-01-31 | BP6: 2032-02-29 | BQ6: 2032-03-31 | BR6: 2032-04-30 | BS6: 2032-05-31 | BT6: 2032-06-30 | BU6: 2032-07-31 | BV6: 2032-08-31 | BW6: 2032-09-30 | BX6: 2032-10-31 | BY6: 2032-11-30 | BZ6: 2032-12-31 | CA6: 2033-01-31 | CB6: 2033-02-28 | CC6: 2033-03-31 | CD6: 2033-04-30 | CE6: 2033-05-31 | CF6: 2033-06-30 | CG6: 2033-07-31 | CH6: 2033-08-31 | CI6: 2033-09-30 | CJ6: 2033-10-31 | CK6: 2033-11-30 | CL6: 2033-12-31 | CM6: 2034-01-31 | CN6: 2034-02-28 | CO6: 2034-03-31 | CP6: 2034-04-30 | CQ6: 2034-05-31 | CR6: 2034-06-30 | CS6: 2034-07-31 | CT6: 2034-08-31 | CU6: 2034-09-30 | CV6: 2034-10-31 | CW6: 2034-11-30 | CX6: 2034-12-31 | CY6: 2035-01-31 | CZ6: 2035-02-28 | DA6: 2035-03-31 | DB6: 2035-04-30 | DC6: 2035-05-31 | DD6: 2035-06-30 | DE6: 2035-07-31 | DF6: 2035-08-31 | DG6: 2035-09-30 | DH6: 2035-10-31 | DI6: 2035-11-30 | DJ6: 2035-12-31 | DK6: 2036-01-31 | DL6: 2036-02-29 | DM6: 2036-03-31 | DN6: 2036-04-30 | DO6: 2036-05-31 | DP6: 2036-06-30 | DQ6: 2036-07-31 | DR6: 2036-08-31 | DS6: 2036-09-30 | DT6: 2036-10-31 | DU6: 2036-11-30 | DV6: 2036-12-31 | DW6: 2037-01-31 | DX6: 2037-02-28 | DY6: 2037-03-31 | DZ6: 2037-04-30 | EA6: 2037-05-31 | EB6: 2037-06-30 | EC6: 2037-07-31 | ED6: 2037-08-31 | EE6: 2037-09-30 | EF6: 2037-10-31 | EG6: 2037-11-30 | EH6: 2037-12-31 | EI6: 2038-01-31 | EJ6: 2038-02-28 | EK6: 2038-03-31 | EL6: 2038-04-30 | EM6: 2038-05-31 | EN6: 2038-06-30 | EO6: 2038-07-31 | EP6: 2038-08-31 | EQ6: 2038-09-30 | ER6: 2038-10-31 | ES6: 2038-11-30 | ET6: 2038-12-31 | EU6: 2039-01-31 | EV6: 2039-02-28 | EW6: 2039-03-31 | EX6: 2039-04-30 | EY6: 2039-05-31 | EZ6: 2039-06-30 | FA6: 2039-07-31 | FB6: 2039-08-31 | FC6: 2039-09-30 | FD6: 2039-10-31 | FE6: 2039-11-30 | FF6: 2039-12-31 | FG6: 2040-01-31 | FH6: 2040-02-29 | FI6: 2040-03-31 | FJ6: 2040-04-30 | FK6: 2040-05-31 | FL6: 2040-06-30 | FM6: 2040-07-31 | FN6: 2040-08-31 | FO6: 2040-09-30 | FP6: 2040-10-31 | FQ6: 2040-11-30 | FR6: 2040-12-31 | FS6: 2041-01-31 | FT6: 2041-02-28 | FU6: 2041-03-31 | FV6: 2041-04-30 | FW6: 2041-05-31 | FX6: 2041-06-30 | FY6: 2041-07-31 | FZ6: 2041-08-31 | GA6: 2041-09-30 | GB6: 2041-10-31 | GC6: 2041-11-30 | GD6: 2041-12-31 | GE6: 2042-01-31 | GF6: 2042-02-28 | GG6: 2042-03-31 | GH6: 2042-04-30 | GI6: 2042-05-31 | GJ6: 2042-06-30 | GK6: 2042-07-31 | GL6: 2042-08-31 | GM6: 2042-09-30 | GN6: 2042-10-31 | GO6: 2042-11-30 | GP6: 2042-12-31 | GQ6: 2043-01-31 | GR6: 2043-02-28 | GS6: 2043-03-31 | GT6: 2043-04-30 | GU6: 2043-05-31 | GV6: 2043-06-30 | GW6: 2043-07-31 | GX6: 2043-08-31 | GY6: 2043-09-30 | GZ6: 2043-10-31 | HA6: 2043-11-30 | HB6: 2043-12-31 | HC6: 2044-01-31 | HD6: 2044-02-29 | HE6: 2044-03-31 | HF6: 2044-04-30 | HG6: 2044-05-31 | HH6: 2044-06-30 | HI6: 2044-07-31 | HJ6: 2044-08-31 | HK6: 2044-09-30 | HL6: 2044-10-31 | HM6: 2044-11-30 | HN6: 2044-12-31 | HO6: 2045-01-31 | HP6: 2045-02-28 | HQ6: 2045-03-31 | HR6: 2045-04-30 | HS6: 2045-05-31 | HT6: 2045-06-30 | HU6: 2045-07-31 | HV6: 2045-08-31 | HW6: 2045-09-30 | HX6: 2045-10-31 | HY6: 2045-11-30 | HZ6: 2045-12-31 | IA6: 2046-01-31 | IB6: 2046-02-28 | IC6: 2046-03-31 | ID6: 2046-04-30 | IE6: 2046-05-31 | IF6: 2046-06-30 | IG6: 2046-07-31 | IH6: 2046-08-31 | II6: 2046-09-30 | IJ6: 2046-10-31 | IK6: 2046-11-30 | IL6: 2046-12-31 | IM6: 2047-01-31 | IN6: 2047-02-28 | IO6: 2047-03-31 | IP6: 2047-04-30 | IQ6: 2047-05-31 | IR6: 2047-06-30 | IS6: 2047-07-31 | IT6: 2047-08-31 | IU6: 2047-09-30 | IV6: 2047-10-31 | IW6: 2047-11-30 | IX6: 2047-12-31 | IY6: 2048-01-31 | IZ6: 2048-02-29 | JA6: 2048-03-31 | JB6: 2048-04-30 | JC6: 2048-05-31 | JD6: 2048-06-30 | JE6: 2048-07-31 | JF6: 2048-08-31 | JG6: 2048-09-30 | JH6: 2048-10-31 | JI6: 2048-11-30 | JJ6: 2048-12-31 | JK6: 2049-01-31 | JL6: 2049-02-28 | JM6: 2049-03-31 | JN6: 2049-04-30 | JO6: 2049-05-31 | JP6: 2049-06-30 | JQ6: 2049-07-31 | JR6: 2049-08-31 | JS6: 2049-09-30 | JT6: 2049-10-31 | JU6: 2049-11-30 | JV6: 2049-12-31 | JW6: 2050-01-31 | JX6: 2050-02-28 | JY6: 2050-03-31 | JZ6: 2050-04-30 | KA6: 2050-05-31 | KB6: 2050-06-30 | KC6: 2050-07-31 | KD6: 2050-08-31 | KE6: 2050-09-30 | KF6: 2050-10-31 | KG6: 2050-11-30 | KH6: 2050-12-31 | KI6: 2051-01-31 | KJ6: 2051-02-28 | KK6: 2051-03-31 | KL6: 2051-04-30 | KM6: 2051-05-31 | KN6: 2051-06-30 | KO6: 2051-07-31 | KP6: 2051-08-31 | KQ6: 2051-09-30 | KR6: 2051-10-31 | KS6: 2051-11-30 | KT6: 2051-12-31 | KU6: 2052-01-31 | KV6: 2052-02-29 | KW6: 2052-03-31 | KX6: 2052-04-30 | KY6: 2052-05-31 | KZ6: 2052-06-30 | LA6: 2052-07-31 | LB6: 2052-08-31 | LC6: 2052-09-30 | LD6: 2052-10-31 | LE6: 2052-11-30 | LF6: 2052-12-31 | LG6: 2053-01-31 | LH6: 2053-02-28 | LI6: 2053-03-31
B7: Flag obra y puesta en marcha | D7: 0 | E7: 0 | F7: 0 | G7: 0 | H7: 0 | I7: 0 | J7: 0 | K7: 0 | L7: 0 | M7: 0 | N7: 0 | O7: 0 | P7: 0 | Q7: 0 | R7: 0 | S7: 0 | T7: 0 | U7: 0 | V7: 0 | W7: 0 | X7: 0 | Y7: 1 | Z7: 1 | AA7: 1 | AB7: 1 | AC7: 1 | AD7: 1 | AE7: 1 | AF7: 1 | AG7: 1 | AH7: 1 | AI7: 1 | AJ7: 1 | AK7: 1 | AL7: 1 | AM7: 1 | AN7: 1 | AO7: 1 | AP7: 1 | AQ7: 1 | AR7: 1 | AS7: 1 | AT7: 1 | AU7: 1 | AV7: 1 | AW7: 1 | AX7: 1 | AY7: 1 | AZ7: 0 | BA7: 0 | BB7: 0 | BC7: 0 | BD7: 0 | BE7: 0 | BF7: 0 | BG7: 0 | BH7: 0 | BI7: 0 | BJ7: 0 | BK7: 0 | BL7: 0 | BM7: 0 | BN7: 0 | BO7: 0 | BP7: 0 | BQ7: 0 | BR7: 0 | BS7: 0 | BT7: 0 | BU7: 0 | BV7: 0 | BW7: 0 | BX7: 0 | BY7: 0 | BZ7: 0 | CA7: 0 | CB7: 0 | CC7: 0 | CD7: 0 | CE7: 0 | CF7: 0 | CG7: 0 | CH7: 0 | CI7: 0 | CJ7: 0 | CK7: 0 | CL7: 0 | CM7: 0 | CN7: 0 | CO7: 0 | CP7: 0 | CQ7: 0 | CR7: 0 | CS7: 0 | CT7: 0 | CU7: 0 | CV7: 0 | CW7: 0 | CX7: 0 | CY7: 0 | CZ7: 0 | DA7: 0 | DB7: 0 | DC7: 0 | DD7: 0 | DE7: 0 | DF7: 0 | DG7: 0 | DH7: 0 | DI7: 0 | DJ7: 0 | DK7: 0 | DL7: 0 | DM7: 0 | DN7: 0 | DO7: 0 | DP7: 0 | DQ7: 0 | DR7: 0 | DS7: 0 | DT7: 0 | DU7: 0 | DV7: 0 | DW7: 0 | DX7: 0 | DY7: 0 | DZ7: 0 | EA7: 0 | EB7: 0 | EC7: 0 | ED7: 0 | EE7: 0 | EF7: 0 | EG7: 0 | EH7: 0 | EI7: 0 | EJ7: 0 | EK7: 0 | EL7: 0 | EM7: 0 | EN7: 0 | EO7: 0 | EP7: 0 | EQ7: 0 | ER7: 0 | ES7: 0 | ET7: 0 | EU7: 0 | EV7: 0 | EW7: 0 | EX7: 0 | EY7: 0 | EZ7: 0 | FA7: 0 | FB7: 0 | FC7: 0 | FD7: 0 | FE7: 0 | FF7: 0 | FG7: 0 | FH7: 0 | FI7: 0 | FJ7: 0 | FK7: 0 | FL7: 0 | FM7: 0 | FN7: 0 | FO7: 0 | FP7: 0 | FQ7: 0 | FR7: 0 | FS7: 0 | FT7: 0 | FU7: 0 | FV7: 0 | FW7: 0 | FX7: 0 | FY7: 0 | FZ7: 0 | GA7: 0 | GB7: 0 | GC7: 0 | GD7: 0 | GE7: 0 | GF7: 0 | GG7: 0 | GH7: 0 | GI7: 0 | GJ7: 0 | GK7: 0 | GL7: 0 | GM7: 0 | GN7: 0 | GO7: 0 | GP7: 0 | GQ7: 0 | GR7: 0 | GS7: 0 | GT7: 0 | GU7: 0 | GV7: 0 | GW7: 0 | GX7: 0 | GY7: 0 | GZ7: 0 | HA7: 0 | HB7: 0 | HC7: 0 | HD7: 0 | HE7: 0 | HF7: 0 | HG7: 0 | HH7: 0 | HI7: 0 | HJ7: 0 | HK7: 0 | HL7: 0 | HM7: 0 | HN7: 0 | HO7: 0 | HP7: 0 | HQ7: 0 | HR7: 0 | HS7: 0 | HT7: 0 | HU7: 0 | HV7: 0 | HW7: 0 | HX7: 0 | HY7: 0 | HZ7: 0 | IA7: 0 | IB7: 0 | IC7: 0 | ID7: 0 | IE7: 0 | IF7: 0 | IG7: 0 | IH7: 0 | II7: 0 | IJ7: 0 | IK7: 0 | IL7: 0 | IM7: 0 | IN7: 0 | IO7: 0 | IP7: 0 | IQ7: 0 | IR7: 0 | IS7: 0 | IT7: 0 | IU7: 0 | IV7: 0 | IW7: 0 | IX7: 0 | IY7: 0 | IZ7: 0 | JA7: 0 | JB7: 0 | JC7: 0 | JD7: 0 | JE7: 0 | JF7: 0 | JG7: 0 | JH7: 0 | JI7: 0 | JJ7: 0 | JK7: 0 | JL7: 0 | JM7: 0 | JN7: 0 | JO7: 0 | JP7: 0 | JQ7: 0 | JR7: 0 | JS7: 0 | JT7: 0 | JU7: 0 | JV7: 0 | JW7: 0 | JX7: 0 | JY7: 0 | JZ7: 0 | KA7: 0 | KB7: 0 | KC7: 0 | KD7: 0 | KE7: 0 | KF7: 0 | KG7: 0 | KH7: 0 | KI7: 0 | KJ7: 0 | KK7: 0 | KL7: 0 | KM7: 0 | KN7: 0 | KO7: 0 | KP7: 0 | KQ7: 0 | KR7: 0 | KS7: 0 | KT7: 0 | KU7: 0 | KV7: 0 | KW7: 0 | KX7: 0 | KY7: 0 | KZ7: 0 | LA7: 0 | LB7: 0 | LC7: 0 | LD7: 0 | LE7: 0 | LF7: 0 | LG7: 0 | LH7: 0 | LI7: 0
B8: Flag de pago de deuda | D8: 0 | E8: 0 | F8: 0 | G8: 0 | H8: 0 | I8: 0 | J8: 0 | K8: 0 | L8: 0 | M8: 0 | N8: 0 | O8: 0 | P8: 0 | Q8: 0 | R8: 0 | S8: 0 | T8: 0 | U8: 0 | V8: 0 | W8: 0 | X8: 0 | Y8: 0 | Z8: 0 | AA8: 0 | AB8: 0 | AC8: 0 | AD8: 0 | AE8: 0 | AF8: 0 | AG8: 0 | AH8: 0 | AI8: 0 | AJ8: 0 | AK8: 0 | AL8: 0 | AM8: 0 | AN8: 0 | AO8: 0 | AP8: 0 | AQ8: 0 | AR8: 0 | AS8: 0 | AT8: 0 | AU8: 0 | AV8: 0 | AW8: 0 | AX8: 0 | AY8: 0 | AZ8: 1 | BA8: 1 | BB8: 1 | BC8: 1 | BD8: 1 | BE8: 1 | BF8: 1 | BG8: 1 | BH8: 1 | BI8: 1 | BJ8: 1 | BK8: 1 | BL8: 1 | BM8: 1 | BN8: 1 | BO8: 1 | BP8: 1 | BQ8: 1 | BR8: 1 | BS8: 1 | BT8: 1 | BU8: 1 | BV8: 1 | BW8: 1 | BX8: 1 | BY8: 1 | BZ8: 1 | CA8: 1 | CB8: 1 | CC8: 1 | CD8: 1 | CE8: 1 | CF8: 1 | CG8: 1 | CH8: 1 | CI8: 1 | CJ8: 1 | CK8: 1 | CL8: 1 | CM8: 1 | CN8: 1 | CO8: 1 | CP8: 1 | CQ8: 1 | CR8: 1 | CS8: 1 | CT8: 1 | CU8: 1 | CV8: 1 | CW8: 1 | CX8: 1 | CY8: 1 | CZ8: 1 | DA8: 1 | DB8: 1 | DC8: 1 | DD8: 1 | DE8: 1 | DF8: 1 | DG8: 1 | DH8: 1 | DI8: 1 | DJ8: 1 | DK8: 1 | DL8: 1 | DM8: 1 | DN8: 1 | DO8: 1 | DP8: 1 | DQ8: 1 | DR8: 1 | DS8: 1 | DT8: 1 | DU8: 1 | DV8: 1 | DW8: 1 | DX8: 1 | DY8: 1 | DZ8: 1 | EA8: 1 | EB8: 1 | EC8: 1 | ED8: 1 | EE8: 1 | EF8: 1 | EG8: 1 | EH8: 1 | EI8: 1 | EJ8: 1 | EK8: 1 | EL8: 1 | EM8: 1 | EN8: 1 | EO8: 1 | EP8: 1 | EQ8: 1 | ER8: 1 | ES8: 1 | ET8: 1 | EU8: 1 | EV8: 1 | EW8: 1 | EX8: 1 | EY8: 1 | EZ8: 1 | FA8: 1 | FB8: 1 | FC8: 1 | FD8: 1 | FE8: 1 | FF8: 1 | FG8: 1 | FH8: 1 | FI8: 1 | FJ8: 1 | FK8: 1 | FL8: 1 | FM8: 1 | FN8: 1 | FO8: 1 | FP8: 1 | FQ8: 1 | FR8: 1 | FS8: 1 | FT8: 1 | FU8: 1 | FV8: 1 | FW8: 1 | FX8: 1 | FY8: 1 | FZ8: 1 | GA8: 1 | GB8: 1 | GC8: 1 | GD8: 1 | GE8: 1 | GF8: 1 | GG8: 1 | GH8: 1 | GI8: 1 | GJ8: 1 | GK8: 1 | GL8: 1 | GM8: 1 | GN8: 0 | GO8: 0 | GP8: 0 | GQ8: 0 | GR8: 0 | GS8: 0 | GT8: 0 | GU8: 0 | GV8: 0 | GW8: 0 | GX8: 0 | GY8: 0 | GZ8: 0 | HA8: 0 | HB8: 0 | HC8: 0 | HD8: 0 | HE8: 0 | HF8: 0 | HG8: 0 | HH8: 0 | HI8: 0 | HJ8: 0 | HK8: 0 | HL8: 0 | HM8: 0 | HN8: 0 | HO8: 0 | HP8: 0 | HQ8: 0 | HR8: 0 | HS8: 0 | HT8: 0 | HU8: 0 | HV8: 0 | HW8: 0 | HX8: 0 | HY8: 0 | HZ8: 0 | IA8: 0 | IB8: 0 | IC8: 0 | ID8: 0 | IE8: 0 | IF8: 0 | IG8: 0 | IH8: 0 | II8: 0 | IJ8: 0 | IK8: 0 | IL8: 0 | IM8: 0 | IN8: 0 | IO8: 0 | IP8: 0 | IQ8: 0 | IR8: 0 | IS8: 0 | IT8: 0 | IU8: 0 | IV8: 0 | IW8: 0 | IX8: 0 | IY8: 0 | IZ8: 0 | JA8: 0 | JB8: 0 | JC8: 0 | JD8: 0 | JE8: 0 | JF8: 0 | JG8: 0 | JH8: 0 | JI8: 0 | JJ8: 0 | JK8: 0 | JL8: 0 | JM8: 0 | JN8: 0 | JO8: 0 | JP8: 0 | JQ8: 0 | JR8: 0 | JS8: 0 | JT8: 0 | JU8: 0 | JV8: 0 | JW8: 0 | JX8: 0 | JY8: 0 | JZ8: 0 | KA8: 0 | KB8: 0 | KC8: 0 | KD8: 0 | KE8: 0 | KF8: 0 | KG8: 0 | KH8: 0 | KI8: 0 | KJ8: 0 | KK8: 0 | KL8: 0 | KM8: 0 | KN8: 0 | KO8: 0 | KP8: 0 | KQ8: 0 | KR8: 0 | KS8: 0 | KT8: 0 | KU8: 0 | KV8: 0 | KW8: 0 | KX8: 0 | KY8: 0 | KZ8: 0 | LA8: 0 | LB8: 0 | LC8: 0 | LD8: 0 | LE8: 0 | LF8: 0 | LG8: 0 | LH8: 0 | LI8: 0
B9: Inversion a financiarse | D9: 0 | E9: 0 | F9: 0 | G9: 0 | H9: 0 | I9: 0 | J9: 0 | K9: 0 | L9: 0 | M9: 0 | N9: 0 | O9: 0 | P9: 0 | Q9: 0 | R9: 0 | S9: 0 | T9: 0 | U9: 0 | V9: 0 | W9: 0 | X9: 0 | Y9: 42887.065 | Z9: 6255.7562 | AA9: 6266.0881 | AB9: 6276.4371 | AC9: 6286.8031 | AD9: 6297.1863 | AE9: 15790.504 | AF9: 15816.583 | AG9: 15842.705 | AH9: 15868.871 | AI9: 15642.805 | AJ9: 15633.192 | AK9: 13673.055 | AL9: 13671.281 | AM9: 13091.902 | AN9: 13113.525 | AO9: 14842.491 | AP9: 14831.203 | AQ9: 2451.2709 | AR9: 2455.3194 | AS9: 1600.067 | AT9: 1602.7096 | AU9: 188.97311 | AV9: 189.28521 | AW9: 189.59783 | AX9: 189.91097 | AY9: 190.22462 | AZ9: 0 | BA9: 0 | BB9: 0 | BC9: 0 | BD9: 0 | BE9: 0 | BF9: 0 | BG9: 0 | BH9: 0 | BI9: 0 | BJ9: 0 | BK9: 0 | BL9: 0 | BM9: 0 | BN9: 0 | BO9: 0 | BP9: 0 | BQ9: 0 | BR9: 0 | BS9: 0 | BT9: 0 | BU9: 0 | BV9: 0 | BW9: 0 | BX9: 0 | BY9: 0 | BZ9: 0 | CA9: 0 | CB9: 0 | CC9: 0 | CD9: 0 | CE9: 0 | CF9: 0 | CG9: 0 | CH9: 0 | CI9: 0 | CJ9: 0 | CK9: 0 | CL9: 0 | CM9: 0 | CN9: 0 | CO9: 0 | CP9: 0 | CQ9: 0 | CR9: 0 | CS9: 0 | CT9: 0 | CU9: 0 | CV9: 0 | CW9: 0 | CX9: 0 | CY9: 0 | CZ9: 0 | DA9: 0 | DB9: 0 | DC9: 0 | DD9: 0 | DE9: 0 | DF9: 0 | DG9: 0 | DH9: 0 | DI9: 0 | DJ9: 0 | DK9: 0 | DL9: 0 | DM9: 0 | DN9: 0 | DO9: 0 | DP9: 0 | DQ9: 0 | DR9: 0 | DS9: 0 | DT9: 0 | DU9: 0 | DV9: 0 | DW9: 0 | DX9: 0 | DY9: 0 | DZ9: 0 | EA9: 0 | EB9: 0 | EC9: 0 | ED9: 0 | EE9: 0 | EF9: 0 | EG9: 0 | EH9: 0 | EI9: 0 | EJ9: 0 | EK9: 0 | EL9: 0 | EM9: 0 | EN9: 0 | EO9: 0 | EP9: 0 | EQ9: 0 | ER9: 0 | ES9: 0 | ET9: 0 | EU9: 0 | EV9: 0 | EW9: 0 | EX9: 0 | EY9: 0 | EZ9: 0 | FA9: 0 | FB9: 0 | FC9: 0 | FD9: 0 | FE9: 0 | FF9: 0 | FG9: 0 | FH9: 0 | FI9: 0 | FJ9: 0 | FK9: 0 | FL9: 0 | FM9: 0 | FN9: 0 | FO9: 0 | FP9: 0 | FQ9: 0 | FR9: 0 | FS9: 0 | FT9: 0 | FU9: 0 | FV9: 0 | FW9: 0 | FX9: 0 | FY9: 0 | FZ9: 0 | GA9: 0 | GB9: 0 | GC9: 0 | GD9: 0 | GE9: 0 | GF9: 0 | GG9: 0 | GH9: 0 | GI9: 0 | GJ9: 0 | GK9: 0 | GL9: 0 | GM9: 0 | GN9: 0 | GO9: 0 | GP9: 0 | GQ9: 0 | GR9: 0 | GS9: 0 | GT9: 0 | GU9: 0 | GV9: 0 | GW9: 0 | GX9: 0 | GY9: 0 | GZ9: 0 | HA9: 0 | HB9: 0 | HC9: 0 | HD9: 0 | HE9: 0 | HF9: 0 | HG9: 0 | HH9: 0 | HI9: 0 | HJ9: 0 | HK9: 0 | HL9: 0 | HM9: 0 | HN9: 0 | HO9: 0 | HP9: 0 | HQ9: 0 | HR9: 0 | HS9: 0 | HT9: 0 | HU9: 0 | HV9: 0 | HW9: 0 | HX9: 0 | HY9: 0 | HZ9: 0 | IA9: 0 | IB9: 0 | IC9: 0 | ID9: 0 | IE9: 0 | IF9: 0 | IG9: 0 | IH9: 0 | II9: 0 | IJ9: 0 | IK9: 0 | IL9: 0 | IM9: 0 | IN9: 0 | IO9: 0 | IP9: 0 | IQ9: 0 | IR9: 0 | IS9: 0 | IT9: 0 | IU9: 0 | IV9: 0 | IW9: 0 | IX9: 0 | IY9: 0 | IZ9: 0 | JA9: 0 | JB9: 0 | JC9: 0 | JD9: 0 | JE9: 0 | JF9: 0 | JG9: 0 | JH9: 0 | JI9: 0 | JJ9: 0 | JK9: 0 | JL9: 0 | JM9: 0 | JN9: 0 | JO9: 0 | JP9: 0 | JQ9: 0 | JR9: 0 | JS9: 0 | JT9: 0 | JU9: 0 | JV9: 0 | JW9: 0 | JX9: 0 | JY9: 0 | JZ9: 0 | KA9: 0 | KB9: 0 | KC9: 0 | KD9: 0 | KE9: 0 | KF9: 0 | KG9: 0 | KH9: 0 | KI9: 0 | KJ9: 0 | KK9: 0 | KL9: 0 | KM9: 0 | KN9: 0 | KO9: 0 | KP9: 0 | KQ9: 0 | KR9: 0 | KS9: 0 | KT9: 0 | KU9: 0 | KV9: 0 | KW9: 0 | KX9: 0 | KY9: 0 | KZ9: 0 | LA9: 0 | LB9: 0 | LC9: 0 | LD9: 0 | LE9: 0 | LF9: 0 | LG9: 0 | LH9: 0 | LI9: 0
B10: Desembolsos | D10: =D7*D9*p_tamano_deuda | E10: =E7*E9*p_tamano_deuda | F10: =F7*F9*p_tamano_deuda | G10: =G7*G9*p_tamano_deuda | H10: =H7*H9*p_tamano_deuda | I10: =I7*I9*p_tamano_deuda | J10: =J7*J9*p_tamano_deuda | K10: =K7*K9*p_tamano_deuda | ... LI10: =LI7*LI9*p_tamano_deuda
B11: Tasa mensual | D11: =(1+p_kd)^(1/12)-1
B12: Saldo de obra capitalizado (base de la cuota) | D12: =0*(1+$D$11)+D10 | E12: =D12*(1+$D$11)+E10 | F12: =E12*(1+$D$11)+F10 | G12: =F12*(1+$D$11)+G10 | H12: =G12*(1+$D$11)+H10 | I12: =H12*(1+$D$11)+I10 | J12: =I12*(1+$D$11)+J10 | K12: =J12*(1+$D$11)+K10 | L12: =K12*(1+$D$11)+L10 | ... AY12: =AX12*(1+$D$11)+AY10 | AZ12: 0 | BA12: 0 | BB12: 0 | BC12: 0 | BD12: 0 | BE12: 0 | BF12: 0 | BG12: 0 | BH12: 0 | BI12: 0 | BJ12: 0 | BK12: 0 | BL12: 0 | BM12: 0 | BN12: 0 | BO12: 0 | BP12: 0 | BQ12: 0 | BR12: 0 | BS12: 0 | BT12: 0 | BU12: 0 | BV12: 0 | BW12: 0 | BX12: 0 | BY12: 0 | BZ12: 0 | CA12: 0 | CB12: 0 | CC12: 0 | CD12: 0 | CE12: 0 | CF12: 0 | CG12: 0 | CH12: 0 | CI12: 0 | CJ12: 0 | CK12: 0 | CL12: 0 | CM12: 0 | CN12: 0 | CO12: 0 | CP12: 0 | CQ12: 0 | CR12: 0 | CS12: 0 | CT12: 0 | CU12: 0 | CV12: 0 | CW12: 0 | CX12: 0 | CY12: 0 | CZ12: 0 | DA12: 0 | DB12: 0 | DC12: 0 | DD12: 0 | DE12: 0 | DF12: 0 | DG12: 0 | DH12: 0 | DI12: 0 | DJ12: 0 | DK12: 0 | DL12: 0 | DM12: 0 | DN12: 0 | DO12: 0 | DP12: 0 | DQ12: 0 | DR12: 0 | DS12: 0 | DT12: 0 | DU12: 0 | DV12: 0 | DW12: 0 | DX12: 0 | DY12: 0 | DZ12: 0 | EA12: 0 | EB12: 0 | EC12: 0 | ED12: 0 | EE12: 0 | EF12: 0 | EG12: 0 | EH12: 0 | EI12: 0 | EJ12: 0 | EK12: 0 | EL12: 0 | EM12: 0 | EN12: 0 | EO12: 0 | EP12: 0 | EQ12: 0 | ER12: 0 | ES12: 0 | ET12: 0 | EU12: 0 | EV12: 0 | EW12: 0 | EX12: 0 | EY12: 0 | EZ12: 0 | FA12: 0 | FB12: 0 | FC12: 0 | FD12: 0 | FE12: 0 | FF12: 0 | FG12: 0 | FH12: 0 | FI12: 0 | FJ12: 0 | FK12: 0 | FL12: 0 | FM12: 0 | FN12: 0 | FO12: 0 | FP12: 0 | FQ12: 0 | FR12: 0 | FS12: 0 | FT12: 0 | FU12: 0 | FV12: 0 | FW12: 0 | FX12: 0 | FY12: 0 | FZ12: 0 | GA12: 0 | GB12: 0 | GC12: 0 | GD12: 0 | GE12: 0 | GF12: 0 | GG12: 0 | GH12: 0 | GI12: 0 | GJ12: 0 | GK12: 0 | GL12: 0 | GM12: 0 | GN12: 0 | GO12: 0 | GP12: 0 | GQ12: 0 | GR12: 0 | GS12: 0 | GT12: 0 | GU12: 0 | GV12: 0 | GW12: 0 | GX12: 0 | GY12: 0 | GZ12: 0 | HA12: 0 | HB12: 0 | HC12: 0 | HD12: 0 | HE12: 0 | HF12: 0 | HG12: 0 | HH12: 0 | HI12: 0 | HJ12: 0 | HK12: 0 | HL12: 0 | HM12: 0 | HN12: 0 | HO12: 0 | HP12: 0 | HQ12: 0 | HR12: 0 | HS12: 0 | HT12: 0 | HU12: 0 | HV12: 0 | HW12: 0 | HX12: 0 | HY12: 0 | HZ12: 0 | IA12: 0 | IB12: 0 | IC12: 0 | ID12: 0 | IE12: 0 | IF12: 0 | IG12: 0 | IH12: 0 | II12: 0 | IJ12: 0 | IK12: 0 | IL12: 0 | IM12: 0 | IN12: 0 | IO12: 0 | IP12: 0 | IQ12: 0 | IR12: 0 | IS12: 0 | IT12: 0 | IU12: 0 | IV12: 0 | IW12: 0 | IX12: 0 | IY12: 0 | IZ12: 0 | JA12: 0 | JB12: 0 | JC12: 0 | JD12: 0 | JE12: 0 | JF12: 0 | JG12: 0 | JH12: 0 | JI12: 0 | JJ12: 0 | JK12: 0 | JL12: 0 | JM12: 0 | JN12: 0 | JO12: 0 | JP12: 0 | JQ12: 0 | JR12: 0 | JS12: 0 | JT12: 0 | JU12: 0 | JV12: 0 | JW12: 0 | JX12: 0 | JY12: 0 | JZ12: 0 | KA12: 0 | KB12: 0 | KC12: 0 | KD12: 0 | KE12: 0 | KF12: 0 | KG12: 0 | KH12: 0 | KI12: 0 | KJ12: 0 | KK12: 0 | KL12: 0 | KM12: 0 | KN12: 0 | KO12: 0 | KP12: 0 | KQ12: 0 | KR12: 0 | KS12: 0 | KT12: 0 | KU12: 0 | KV12: 0 | KW12: 0 | KX12: 0 | KY12: 0 | KZ12: 0 | LA12: 0 | LB12: 0 | LC12: 0 | LD12: 0 | LE12: 0 | LF12: 0 | LG12: 0 | LH12: 0 | LI12: 0
B13: Cuota constante | D13: =-PMT($D$11,p_pagos,AY12)
B14: Interes | D14: 0 | E14: =D17*$D$11 | F14: =E17*$D$11 | G14: =F17*$D$11 | H14: =G17*$D$11 | I14: =H17*$D$11 | J14: =I17*$D$11 | K14: =J17*$D$11 | L14: =K17*$D$11 | ... LI14: =LH17*$D$11
B15: Amortizacion | D15: =D16-D14 | E15: =E16-E14 | F15: =F16-F14 | G15: =G16-G14 | H15: =H16-H14 | I15: =I16-I14 | J15: =J16-J14 | K15: =K16-K14 | ... LI15: =LI16-LI14
B16: Servicio de deuda | D16: =D8*$D$13 | E16: =E8*$D$13 | F16: =F8*$D$13 | G16: =G8*$D$13 | H16: =H8*$D$13 | I16: =I8*$D$13 | J16: =J8*$D$13 | K16: =K8*$D$13 | ... LI16: =LI8*$D$13
B17: Saldo deudor | D17: =0+D10-D15 | E17: =D17+E10-E15 | F17: =E17+F10-F15 | G17: =F17+G10-G15 | H17: =G17+H10-H15 | I17: =H17+I10-I15 | J17: =I17+J10-J15 | K17: =J17+K10-K15 | L17: =K17+L10-L15 | ... LI17: =LH17+LI10-LI15

Sheet Ingresos
B2: Ingreso tarifario al usuario
B3: Mismo reajuste por IPM con gatillo que la pata variable; aqui es todo el ingreso del proyecto.
B6: Mes | D6: 2026-10-31 | E6: 2026-11-30 | F6: 2026-12-31 | G6: 2027-01-31 | H6: 2027-02-28 | I6: 2027-03-31 | J6: 2027-04-30 | K6: 2027-05-31 | L6: 2027-06-30 | M6: 2027-07-31 | N6: 2027-08-31 | O6: 2027-09-30 | P6: 2027-10-31 | Q6: 2027-11-30 | R6: 2027-12-31 | S6: 2028-01-31 | T6: 2028-02-29 | U6: 2028-03-31 | V6: 2028-04-30 | W6: 2028-05-31 | X6: 2028-06-30 | Y6: 2028-07-31 | Z6: 2028-08-31 | AA6: 2028-09-30 | AB6: 2028-10-31 | AC6: 2028-11-30 | AD6: 2028-12-31 | AE6: 2029-01-31 | AF6: 2029-02-28 | AG6: 2029-03-31 | AH6: 2029-04-30 | AI6: 2029-05-31 | AJ6: 2029-06-30 | AK6: 2029-07-31 | AL6: 2029-08-31 | AM6: 2029-09-30 | AN6: 2029-10-31 | AO6: 2029-11-30 | AP6: 2029-12-31 | AQ6: 2030-01-31 | AR6: 2030-02-28 | AS6: 2030-03-31 | AT6: 2030-04-30 | AU6: 2030-05-31 | AV6: 2030-06-30 | AW6: 2030-07-31 | AX6: 2030-08-31 | AY6: 2030-09-30 | AZ6: 2030-10-31 | BA6: 2030-11-30 | BB6: 2030-12-31 | BC6: 2031-01-31 | BD6: 2031-02-28 | BE6: 2031-03-31 | BF6: 2031-04-30 | BG6: 2031-05-31 | BH6: 2031-06-30 | BI6: 2031-07-31 | BJ6: 2031-08-31 | BK6: 2031-09-30 | BL6: 2031-10-31 | BM6: 2031-11-30 | BN6: 2031-12-31 | BO6: 2032-01-31 | BP6: 2032-02-29 | BQ6: 2032-03-31 | BR6: 2032-04-30 | BS6: 2032-05-31 | BT6: 2032-06-30 | BU6: 2032-07-31 | BV6: 2032-08-31 | BW6: 2032-09-30 | BX6: 2032-10-31 | BY6: 2032-11-30 | BZ6: 2032-12-31 | CA6: 2033-01-31 | CB6: 2033-02-28 | CC6: 2033-03-31 | CD6: 2033-04-30 | CE6: 2033-05-31 | CF6: 2033-06-30 | CG6: 2033-07-31 | CH6: 2033-08-31 | CI6: 2033-09-30 | CJ6: 2033-10-31 | CK6: 2033-11-30 | CL6: 2033-12-31 | CM6: 2034-01-31 | CN6: 2034-02-28 | CO6: 2034-03-31 | CP6: 2034-04-30 | CQ6: 2034-05-31 | CR6: 2034-06-30 | CS6: 2034-07-31 | CT6: 2034-08-31 | CU6: 2034-09-30 | CV6: 2034-10-31 | CW6: 2034-11-30 | CX6: 2034-12-31 | CY6: 2035-01-31 | CZ6: 2035-02-28 | DA6: 2035-03-31 | DB6: 2035-04-30 | DC6: 2035-05-31 | DD6: 2035-06-30 | DE6: 2035-07-31 | DF6: 2035-08-31 | DG6: 2035-09-30 | DH6: 2035-10-31 | DI6: 2035-11-30 | DJ6: 2035-12-31 | DK6: 2036-01-31 | DL6: 2036-02-29 | DM6: 2036-03-31 | DN6: 2036-04-30 | DO6: 2036-05-31 | DP6: 2036-06-30 | DQ6: 2036-07-31 | DR6: 2036-08-31 | DS6: 2036-09-30 | DT6: 2036-10-31 | DU6: 2036-11-30 | DV6: 2036-12-31 | DW6: 2037-01-31 | DX6: 2037-02-28 | DY6: 2037-03-31 | DZ6: 2037-04-30 | EA6: 2037-05-31 | EB6: 2037-06-30 | EC6: 2037-07-31 | ED6: 2037-08-31 | EE6: 2037-09-30 | EF6: 2037-10-31 | EG6: 2037-11-30 | EH6: 2037-12-31 | EI6: 2038-01-31 | EJ6: 2038-02-28 | EK6: 2038-03-31 | EL6: 2038-04-30 | EM6: 2038-05-31 | EN6: 2038-06-30 | EO6: 2038-07-31 | EP6: 2038-08-31 | EQ6: 2038-09-30 | ER6: 2038-10-31 | ES6: 2038-11-30 | ET6: 2038-12-31 | EU6: 2039-01-31 | EV6: 2039-02-28 | EW6: 2039-03-31 | EX6: 2039-04-30 | EY6: 2039-05-31 | EZ6: 2039-06-30 | FA6: 2039-07-31 | FB6: 2039-08-31 | FC6: 2039-09-30 | FD6: 2039-10-31 | FE6: 2039-11-30 | FF6: 2039-12-31 | FG6: 2040-01-31 | FH6: 2040-02-29 | FI6: 2040-03-31 | FJ6: 2040-04-30 | FK6: 2040-05-31 | FL6: 2040-06-30 | FM6: 2040-07-31 | FN6: 2040-08-31 | FO6: 2040-09-30 | FP6: 2040-10-31 | FQ6: 2040-11-30 | FR6: 2040-12-31 | FS6: 2041-01-31 | FT6: 2041-02-28 | FU6: 2041-03-31 | FV6: 2041-04-30 | FW6: 2041-05-31 | FX6: 2041-06-30 | FY6: 2041-07-31 | FZ6: 2041-08-31 | GA6: 2041-09-30 | GB6: 2041-10-31 | GC6: 2041-11-30 | GD6: 2041-12-31 | GE6: 2042-01-31 | GF6: 2042-02-28 | GG6: 2042-03-31 | GH6: 2042-04-30 | GI6: 2042-05-31 | GJ6: 2042-06-30 | GK6: 2042-07-31 | GL6: 2042-08-31 | GM6: 2042-09-30 | GN6: 2042-10-31 | GO6: 2042-11-30 | GP6: 2042-12-31 | GQ6: 2043-01-31 | GR6: 2043-02-28 | GS6: 2043-03-31 | GT6: 2043-04-30 | GU6: 2043-05-31 | GV6: 2043-06-30 | GW6: 2043-07-31 | GX6: 2043-08-31 | GY6: 2043-09-30 | GZ6: 2043-10-31 | HA6: 2043-11-30 | HB6: 2043-12-31 | HC6: 2044-01-31 | HD6: 2044-02-29 | HE6: 2044-03-31 | HF6: 2044-04-30 | HG6: 2044-05-31 | HH6: 2044-06-30 | HI6: 2044-07-31 | HJ6: 2044-08-31 | HK6: 2044-09-30 | HL6: 2044-10-31 | HM6: 2044-11-30 | HN6: 2044-12-31 | HO6: 2045-01-31 | HP6: 2045-02-28 | HQ6: 2045-03-31 | HR6: 2045-04-30 | HS6: 2045-05-31 | HT6: 2045-06-30 | HU6: 2045-07-31 | HV6: 2045-08-31 | HW6: 2045-09-30 | HX6: 2045-10-31 | HY6: 2045-11-30 | HZ6: 2045-12-31 | IA6: 2046-01-31 | IB6: 2046-02-28 | IC6: 2046-03-31 | ID6: 2046-04-30 | IE6: 2046-05-31 | IF6: 2046-06-30 | IG6: 2046-07-31 | IH6: 2046-08-31 | II6: 2046-09-30 | IJ6: 2046-10-31 | IK6: 2046-11-30 | IL6: 2046-12-31 | IM6: 2047-01-31 | IN6: 2047-02-28 | IO6: 2047-03-31 | IP6: 2047-04-30 | IQ6: 2047-05-31 | IR6: 2047-06-30 | IS6: 2047-07-31 | IT6: 2047-08-31 | IU6: 2047-09-30 | IV6: 2047-10-31 | IW6: 2047-11-30 | IX6: 2047-12-31 | IY6: 2048-01-31 | IZ6: 2048-02-29 | JA6: 2048-03-31 | JB6: 2048-04-30 | JC6: 2048-05-31 | JD6: 2048-06-30 | JE6: 2048-07-31 | JF6: 2048-08-31 | JG6: 2048-09-30 | JH6: 2048-10-31 | JI6: 2048-11-30 | JJ6: 2048-12-31 | JK6: 2049-01-31 | JL6: 2049-02-28 | JM6: 2049-03-31 | JN6: 2049-04-30 | JO6: 2049-05-31 | JP6: 2049-06-30 | JQ6: 2049-07-31 | JR6: 2049-08-31 | JS6: 2049-09-30 | JT6: 2049-10-31 | JU6: 2049-11-30 | JV6: 2049-12-31 | JW6: 2050-01-31 | JX6: 2050-02-28 | JY6: 2050-03-31 | JZ6: 2050-04-30 | KA6: 2050-05-31 | KB6: 2050-06-30 | KC6: 2050-07-31 | KD6: 2050-08-31 | KE6: 2050-09-30 | KF6: 2050-10-31 | KG6: 2050-11-30 | KH6: 2050-12-31 | KI6: 2051-01-31 | KJ6: 2051-02-28 | KK6: 2051-03-31 | KL6: 2051-04-30 | KM6: 2051-05-31 | KN6: 2051-06-30 | KO6: 2051-07-31 | KP6: 2051-08-31 | KQ6: 2051-09-30 | KR6: 2051-10-31 | KS6: 2051-11-30 | KT6: 2051-12-31 | KU6: 2052-01-31 | KV6: 2052-02-29 | KW6: 2052-03-31 | KX6: 2052-04-30 | KY6: 2052-05-31 | KZ6: 2052-06-30 | LA6: 2052-07-31 | LB6: 2052-08-31 | LC6: 2052-09-30 | LD6: 2052-10-31 | LE6: 2052-11-30 | LF6: 2052-12-31 | LG6: 2053-01-31 | LH6: 2053-02-28 | LI6: 2053-03-31
B7: Flag de operacion | D7: 0 | E7: 0 | F7: 0 | G7: 0 | H7: 0 | I7: 0 | J7: 0 | K7: 0 | L7: 0 | M7: 0 | N7: 0 | O7: 0 | P7: 0 | Q7: 0 | R7: 0 | S7: 0 | T7: 0 | U7: 0 | V7: 0 | W7: 0 | X7: 0 | Y7: 0 | Z7: 0 | AA7: 0 | AB7: 0 | AC7: 0 | AD7: 0 | AE7: 0 | AF7: 0 | AG7: 0 | AH7: 0 | AI7: 0 | AJ7: 0 | AK7: 0 | AL7: 0 | AM7: 0 | AN7: 0 | AO7: 0 | AP7: 0 | AQ7: 0 | AR7: 0 | AS7: 0 | AT7: 0 | AU7: 0 | AV7: 0 | AW7: 0 | AX7: 0 | AY7: 0 | AZ7: 1 | BA7: 1 | BB7: 1 | BC7: 1 | BD7: 1 | BE7: 1 | BF7: 1 | BG7: 1 | BH7: 1 | BI7: 1 | BJ7: 1 | BK7: 1 | BL7: 1 | BM7: 1 | BN7: 1 | BO7: 1 | BP7: 1 | BQ7: 1 | BR7: 1 | BS7: 1 | BT7: 1 | BU7: 1 | BV7: 1 | BW7: 1 | BX7: 1 | BY7: 1 | BZ7: 1 | CA7: 1 | CB7: 1 | CC7: 1 | CD7: 1 | CE7: 1 | CF7: 1 | CG7: 1 | CH7: 1 | CI7: 1 | CJ7: 1 | CK7: 1 | CL7: 1 | CM7: 1 | CN7: 1 | CO7: 1 | CP7: 1 | CQ7: 1 | CR7: 1 | CS7: 1 | CT7: 1 | CU7: 1 | CV7: 1 | CW7: 1 | CX7: 1 | CY7: 1 | CZ7: 1 | DA7: 1 | DB7: 1 | DC7: 1 | DD7: 1 | DE7: 1 | DF7: 1 | DG7: 1 | DH7: 1 | DI7: 1 | DJ7: 1 | DK7: 1 | DL7: 1 | DM7: 1 | DN7: 1 | DO7: 1 | DP7: 1 | DQ7: 1 | DR7: 1 | DS7: 1 | DT7: 1 | DU7: 1 | DV7: 1 | DW7: 1 | DX7: 1 | DY7: 1 | DZ7: 1 | EA7: 1 | EB7: 1 | EC7: 1 | ED7: 1 | EE7: 1 | EF7: 1 | EG7: 1 | EH7: 1 | EI7: 1 | EJ7: 1 | EK7: 1 | EL7: 1 | EM7: 1 | EN7: 1 | EO7: 1 | EP7: 1 | EQ7: 1 | ER7: 1 | ES7: 1 | ET7: 1 | EU7: 1 | EV7: 1 | EW7: 1 | EX7: 1 | EY7: 1 | EZ7: 1 | FA7: 1 | FB7: 1 | FC7: 1 | FD7: 1 | FE7: 1 | FF7: 1 | FG7: 1 | FH7: 1 | FI7: 1 | FJ7: 1 | FK7: 1 | FL7: 1 | FM7: 1 | FN7: 1 | FO7: 1 | FP7: 1 | FQ7: 1 | FR7: 1 | FS7: 1 | FT7: 1 | FU7: 1 | FV7: 1 | FW7: 1 | FX7: 1 | FY7: 1 | FZ7: 1 | GA7: 1 | GB7: 1 | GC7: 1 | GD7: 1 | GE7: 1 | GF7: 1 | GG7: 1 | GH7: 1 | GI7: 1 | GJ7: 1 | GK7: 1 | GL7: 1 | GM7: 1 | GN7: 1 | GO7: 1 | GP7: 1 | GQ7: 1 | GR7: 1 | GS7: 1 | GT7: 1 | GU7: 1 | GV7: 1 | GW7: 1 | GX7: 1 | GY7: 1 | GZ7: 1 | HA7: 1 | HB7: 1 | HC7: 1 | HD7: 1 | HE7: 1 | HF7: 1 | HG7: 1 | HH7: 1 | HI7: 1 | HJ7: 1 | HK7: 1 | HL7: 1 | HM7: 1 | HN7: 1 | HO7: 1 | HP7: 1 | HQ7: 1 | HR7: 1 | HS7: 1 | HT7: 1 | HU7: 1 | HV7: 1 | HW7: 1 | HX7: 1 | HY7: 1 | HZ7: 1 | IA7: 1 | IB7: 1 | IC7: 1 | ID7: 1 | IE7: 1 | IF7: 1 | IG7: 1 | IH7: 1 | II7: 1 | IJ7: 1 | IK7: 1 | IL7: 1 | IM7: 1 | IN7: 1 | IO7: 1 | IP7: 1 | IQ7: 1 | IR7: 1 | IS7: 1 | IT7: 1 | IU7: 1 | IV7: 1 | IW7: 1 | IX7: 1 | IY7: 1 | IZ7: 1 | JA7: 1 | JB7: 1 | JC7: 1 | JD7: 1 | JE7: 1 | JF7: 1 | JG7: 1 | JH7: 1 | JI7: 1 | JJ7: 1 | JK7: 1 | JL7: 1 | JM7: 1 | JN7: 1 | JO7: 1 | JP7: 1 | JQ7: 1 | JR7: 1 | JS7: 1 | JT7: 1 | JU7: 1 | JV7: 1 | JW7: 1 | JX7: 1 | JY7: 1 | JZ7: 1 | KA7: 1 | KB7: 1 | KC7: 1 | KD7: 1 | KE7: 1 | KF7: 1 | KG7: 1 | KH7: 1 | KI7: 1 | KJ7: 1 | KK7: 1 | KL7: 1 | KM7: 1 | KN7: 1 | KO7: 1 | KP7: 1 | KQ7: 1 | KR7: 1 | KS7: 1 | KT7: 1 | KU7: 1 | KV7: 1 | KW7: 1 | KX7: 1 | KY7: 1 | KZ7: 1 | LA7: 1 | LB7: 1 | LC7: 1 | LD7: 0 | LE7: 0 | LF7: 0 | LG7: 0 | LH7: 0 | LI7: 0
B8: Trimestre del mes | D8: 1 | E8: 1 | F8: 1 | G8: 2 | H8: 2 | I8: 2 | J8: 3 | K8: 3 | L8: 3 | M8: 4 | N8: 4 | O8: 4 | P8: 5 | Q8: 5 | R8: 5 | S8: 6 | T8: 6 | U8: 6 | V8: 7 | W8: 7 | X8: 7 | Y8: 8 | Z8: 8 | AA8: 8 | AB8: 9 | AC8: 9 | AD8: 9 | AE8: 10 | AF8: 10 | AG8: 10 | AH8: 11 | AI8: 11 | AJ8: 11 | AK8: 12 | AL8: 12 | AM8: 12 | AN8: 13 | AO8: 13 | AP8: 13 | AQ8: 14 | AR8: 14 | AS8: 14 | AT8: 15 | AU8: 15 | AV8: 15 | AW8: 16 | AX8: 16 | AY8: 16 | AZ8: 17 | BA8: 17 | BB8: 17 | BC8: 18 | BD8: 18 | BE8: 18 | BF8: 19 | BG8: 19 | BH8: 19 | BI8: 20 | BJ8: 20 | BK8: 20 | BL8: 21 | BM8: 21 | BN8: 21 | BO8: 22 | BP8: 22 | BQ8: 22 | BR8: 23 | BS8: 23 | BT8: 23 | BU8: 24 | BV8: 24 | BW8: 24 | BX8: 25 | BY8: 25 | BZ8: 25 | CA8: 26 | CB8: 26 | CC8: 26 | CD8: 27 | CE8: 27 | CF8: 27 | CG8: 28 | CH8: 28 | CI8: 28 | CJ8: 29 | CK8: 29 | CL8: 29 | CM8: 30 | CN8: 30 | CO8: 30 | CP8: 31 | CQ8: 31 | CR8: 31 | CS8: 32 | CT8: 32 | CU8: 32 | CV8: 33 | CW8: 33 | CX8: 33 | CY8: 34 | CZ8: 34 | DA8: 34 | DB8: 35 | DC8: 35 | DD8: 35 | DE8: 36 | DF8: 36 | DG8: 36 | DH8: 37 | DI8: 37 | DJ8: 37 | DK8: 38 | DL8: 38 | DM8: 38 | DN8: 39 | DO8: 39 | DP8: 39 | DQ8: 40 | DR8: 40 | DS8: 40 | DT8: 41 | DU8: 41 | DV8: 41 | DW8: 42 | DX8: 42 | DY8: 42 | DZ8: 43 | EA8: 43 | EB8: 43 | EC8: 44 | ED8: 44 | EE8: 44 | EF8: 45 | EG8: 45 | EH8: 45 | EI8: 46 | EJ8: 46 | EK8: 46 | EL8: 47 | EM8: 47 | EN8: 47 | EO8: 48 | EP8: 48 | EQ8: 48 | ER8: 49 | ES8: 49 | ET8: 49 | EU8: 50 | EV8: 50 | EW8: 50 | EX8: 51 | EY8: 51 | EZ8: 51 | FA8: 52 | FB8: 52 | FC8: 52 | FD8: 53 | FE8: 53 | FF8: 53 | FG8: 54 | FH8: 54 | FI8: 54 | FJ8: 55 | FK8: 55 | FL8: 55 | FM8: 56 | FN8: 56 | FO8: 56 | FP8: 57 | FQ8: 57 | FR8: 57 | FS8: 58 | FT8: 58 | FU8: 58 | FV8: 59 | FW8: 59 | FX8: 59 | FY8: 60 | FZ8: 60 | GA8: 60 | GB8: 61 | GC8: 61 | GD8: 61 | GE8: 62 | GF8: 62 | GG8: 62 | GH8: 63 | GI8: 63 | GJ8: 63 | GK8: 64 | GL8: 64 | GM8: 64 | GN8: 65 | GO8: 65 | GP8: 65 | GQ8: 66 | GR8: 66 | GS8: 66 | GT8: 67 | GU8: 67 | GV8: 67 | GW8: 68 | GX8: 68 | GY8: 68 | GZ8: 69 | HA8: 69 | HB8: 69 | HC8: 70 | HD8: 70 | HE8: 70 | HF8: 71 | HG8: 71 | HH8: 71 | HI8: 72 | HJ8: 72 | HK8: 72 | HL8: 73 | HM8: 73 | HN8: 73 | HO8: 74 | HP8: 74 | HQ8: 74 | HR8: 75 | HS8: 75 | HT8: 75 | HU8: 76 | HV8: 76 | HW8: 76 | HX8: 77 | HY8: 77 | HZ8: 77 | IA8: 78 | IB8: 78 | IC8: 78 | ID8: 79 | IE8: 79 | IF8: 79 | IG8: 80 | IH8: 80 | II8: 80 | IJ8: 81 | IK8: 81 | IL8: 81 | IM8: 82 | IN8: 82 | IO8: 82 | IP8: 83 | IQ8: 83 | IR8: 83 | IS8: 84 | IT8: 84 | IU8: 84 | IV8: 85 | IW8: 85 | IX8: 85 | IY8: 86 | IZ8: 86 | JA8: 86 | JB8: 87 | JC8: 87 | JD8: 87 | JE8: 88 | JF8: 88 | JG8: 88 | JH8: 89 | JI8: 89 | JJ8: 89 | JK8: 90 | JL8: 90 | JM8: 90 | JN8: 91 | JO8: 91 | JP8: 91 | JQ8: 92 | JR8: 92 | JS8: 92 | JT8: 93 | JU8: 93 | JV8: 93 | JW8: 94 | JX8: 94 | JY8: 94 | JZ8: 95 | KA8: 95 | KB8: 95 | KC8: 96 | KD8: 96 | KE8: 96 | KF8: 97 | KG8: 97 | KH8: 97 | KI8: 98 | KJ8: 98 | KK8: 98 | KL8: 99 | KM8: 99 | KN8: 99 | KO8: 100 | KP8: 100 | KQ8: 100 | KR8: 101 | KS8: 101 | KT8: 101 | KU8: 102 | KV8: 102 | KW8: 102 | KX8: 103 | KY8: 103 | KZ8: 103 | LA8: 104 | LB8: 104 | LC8: 104 | LD8: 105 | LE8: 105 | LF8: 105 | LG8: 106 | LH8: 106 | LI8: 106
B9: Produccion efectiva, kg DBO5 | D9: 0 | E9: 0 | F9: 0 | G9: 0 | H9: 0 | I9: 0 | J9: 0 | K9: 0 | L9: 0 | M9: 0 | N9: 0 | O9: 0 | P9: 0 | Q9: 0 | R9: 0 | S9: 0 | T9: 0 | U9: 0 | V9: 0 | W9: 0 | X9: 0 | Y9: 0 | Z9: 0 | AA9: 0 | AB9: 0 | AC9: 0 | AD9: 0 | AE9: 0 | AF9: 0 | AG9: 0 | AH9: 0 | AI9: 0 | AJ9: 0 | AK9: 0 | AL9: 0 | AM9: 0 | AN9: 0 | AO9: 0 | AP9: 0 | AQ9: 0 | AR9: 0 | AS9: 0 | AT9: 0 | AU9: 0 | AV9: 0 | AW9: 0 | AX9: 0 | AY9: 0 | AZ9: 558467.34 | BA9: 558467.34 | BB9: 558467.34 | BC9: 565769.15 | BD9: 565769.15 | BE9: 565769.15 | BF9: 565769.15 | BG9: 565769.15 | BH9: 565769.15 | BI9: 565769.15 | BJ9: 565769.15 | BK9: 565769.15 | BL9: 565769.15 | BM9: 565769.15 | BN9: 565769.15 | BO9: 571854 | BP9: 571854 | BQ9: 571854 | BR9: 571854 | BS9: 571854 | BT9: 571854 | BU9: 571854 | BV9: 571854 | BW9: 571854 | BX9: 571854 | BY9: 571854 | BZ9: 571854 | CA9: 576721.88 | CB9: 576721.88 | CC9: 576721.88 | CD9: 576721.88 | CE9: 576721.88 | CF9: 576721.88 | CG9: 576721.88 | CH9: 576721.88 | CI9: 576721.88 | CJ9: 576721.88 | CK9: 576721.88 | CL9: 576721.88 | CM9: 581589.76 | CN9: 581589.76 | CO9: 581589.76 | CP9: 581589.76 | CQ9: 581589.76 | CR9: 581589.76 | CS9: 581589.76 | CT9: 581589.76 | CU9: 581589.76 | CV9: 581589.76 | CW9: 581589.76 | CX9: 581589.76 | CY9: 586457.64 | CZ9: 586457.64 | DA9: 586457.64 | DB9: 586457.64 | DC9: 586457.64 | DD9: 586457.64 | DE9: 586457.64 | DF9: 586457.64 | DG9: 586457.64 | DH9: 586457.64 | DI9: 586457.64 | DJ9: 586457.64 | DK9: 591325.51 | DL9: 591325.51 | DM9: 591325.51 | DN9: 591325.51 | DO9: 591325.51 | DP9: 591325.51 | DQ9: 591325.51 | DR9: 591325.51 | DS9: 591325.51 | DT9: 591325.51 | DU9: 591325.51 | DV9: 591325.51 | DW9: 620532.78 | DX9: 620532.78 | DY9: 620532.78 | DZ9: 620532.78 | EA9: 620532.78 | EB9: 620532.78 | EC9: 620532.78 | ED9: 620532.78 | EE9: 620532.78 | EF9: 620532.78 | EG9: 620532.78 | EH9: 620532.78 | EI9: 626617.63 | EJ9: 626617.63 | EK9: 626617.63 | EL9: 626617.63 | EM9: 626617.63 | EN9: 626617.63 | EO9: 626617.63 | EP9: 626617.63 | EQ9: 626617.63 | ER9: 626617.63 | ES9: 626617.63 | ET9: 626617.63 | EU9: 632702.48 | EV9: 632702.48 | EW9: 632702.48 | EX9: 632702.48 | EY9: 632702.48 | EZ9: 632702.48 | FA9: 632702.48 | FB9: 632702.48 | FC9: 632702.48 | FD9: 632702.48 | FE9: 632702.48 | FF9: 632702.48 | FG9: 640004.3 | FH9: 640004.3 | FI9: 640004.3 | FJ9: 640004.3 | FK9: 640004.3 | FL9: 640004.3 | FM9: 640004.3 | FN9: 640004.3 | FO9: 640004.3 | FP9: 640004.3 | FQ9: 640004.3 | FR9: 640004.3 | FS9: 646089.14 | FT9: 646089.14 | FU9: 646089.14 | FV9: 646089.14 | FW9: 646089.14 | FX9: 646089.14 | FY9: 646089.14 | FZ9: 646089.14 | GA9: 646089.14 | GB9: 646089.14 | GC9: 646089.14 | GD9: 646089.14 | GE9: 653390.96 | GF9: 653390.96 | GG9: 653390.96 | GH9: 653390.96 | GI9: 653390.96 | GJ9: 653390.96 | GK9: 653390.96 | GL9: 653390.96 | GM9: 653390.96 | GN9: 653390.96 | GO9: 653390.96 | GP9: 653390.96 | GQ9: 659475.81 | GR9: 659475.81 | GS9: 659475.81 | GT9: 659475.81 | GU9: 659475.81 | GV9: 659475.81 | GW9: 659475.81 | GX9: 659475.81 | GY9: 659475.81 | GZ9: 659475.81 | HA9: 659475.81 | HB9: 659475.81 | HC9: 666777.63 | HD9: 666777.63 | HE9: 666777.63 | HF9: 666777.63 | HG9: 666777.63 | HH9: 666777.63 | HI9: 666777.63 | HJ9: 666777.63 | HK9: 666777.63 | HL9: 666777.63 | HM9: 666777.63 | HN9: 666777.63 | HO9: 674079.44 | HP9: 674079.44 | HQ9: 674079.44 | HR9: 674079.44 | HS9: 674079.44 | HT9: 674079.44 | HU9: 674079.44 | HV9: 674079.44 | HW9: 674079.44 | HX9: 674079.44 | HY9: 674079.44 | HZ9: 674079.44 | IA9: 681381.26 | IB9: 681381.26 | IC9: 681381.26 | ID9: 681381.26 | IE9: 681381.26 | IF9: 681381.26 | IG9: 681381.26 | IH9: 681381.26 | II9: 681381.26 | IJ9: 681381.26 | IK9: 681381.26 | IL9: 681381.26 | IM9: 688683.08 | IN9: 688683.08 | IO9: 688683.08 | IP9: 688683.08 | IQ9: 688683.08 | IR9: 688683.08 | IS9: 688683.08 | IT9: 688683.08 | IU9: 688683.08 | IV9: 688683.08 | IW9: 688683.08 | IX9: 688683.08 | IY9: 695984.9 | IZ9: 695984.9 | JA9: 695984.9 | JB9: 695984.9 | JC9: 695984.9 | JD9: 695984.9 | JE9: 695984.9 | JF9: 695984.9 | JG9: 695984.9 | JH9: 695984.9 | JI9: 695984.9 | JJ9: 695984.9 | JK9: 703286.71 | JL9: 703286.71 | JM9: 703286.71 | JN9: 703286.71 | JO9: 703286.71 | JP9: 703286.71 | JQ9: 703286.71 | JR9: 703286.71 | JS9: 703286.71 | JT9: 703286.71 | JU9: 703286.71 | JV9: 703286.71 | JW9: 711805.5 | JX9: 711805.5 | JY9: 711805.5 | JZ9: 711805.5 | KA9: 711805.5 | KB9: 711805.5 | KC9: 711805.5 | KD9: 711805.5 | KE9: 711805.5 | KF9: 711805.5 | KG9: 711805.5 | KH9: 711805.5 | KI9: 720324.29 | KJ9: 720324.29 | KK9: 720324.29 | KL9: 720324.29 | KM9: 720324.29 | KN9: 720324.29 | KO9: 720324.29 | KP9: 720324.29 | KQ9: 720324.29 | KR9: 720324.29 | KS9: 720324.29 | KT9: 720324.29 | KU9: 720324.29 | KV9: 720324.29 | KW9: 720324.29 | KX9: 720324.29 | KY9: 720324.29 | KZ9: 720324.29 | LA9: 720324.29 | LB9: 720324.29 | LC9: 720324.29 | LD9: 0 | LE9: 0 | LF9: 0 | LG9: 0 | LH9: 0 | LI9: 0
B10: IPM mensual | D10: =((1+p_ipm)^(1/12)-1)*D7 | E10: =((1+p_ipm)^(1/12)-1)*E7 | F10: =((1+p_ipm)^(1/12)-1)*F7 | G10: =((1+p_ipm)^(1/12)-1)*G7 | H10: =((1+p_ipm)^(1/12)-1)*H7 | I10: =((1+p_ipm)^(1/12)-1)*I7 | J10: =((1+p_ipm)^(1/12)-1)*J7 | K10: =((1+p_ipm)^(1/12)-1)*K7 | ... LI10: =((1+p_ipm)^(1/12)-1)*LI7
B11: Acumulado pendiente | D11: =IF($D10=0,0,$D10) | E11: =IF(E10=0,0,SUM($D10:E10)-SUM($D12:D12)) | F11: =IF(F10=0,0,SUM($D10:F10)-SUM($D12:E12)) | G11: =IF(G10=0,0,SUM($D10:G10)-SUM($D12:F12)) | H11: =IF(H10=0,0,SUM($D10:H10)-SUM($D12:G12)) | I11: =IF(I10=0,0,SUM($D10:I10)-SUM($D12:H12)) | J11: =IF(J10=0,0,SUM($D10:J10)-SUM($D12:I12)) | K11: =IF(K10=0,0,SUM($D10:K10)-SUM($D12:J12)) | L11: =IF(L10=0,0,SUM($D10:L10)-SUM($D12:K12)) | ... LI11: =IF(LI10=0,0,SUM($D10:LI10)-SUM($D12:LH12))
B12: Ajuste liberado | D12: =IF(D11>=p_gatillo,D11,0) | E12: =IF(E11>=p_gatillo,E11,0) | F12: =IF(F11>=p_gatillo,F11,0) | G12: =IF(G11>=p_gatillo,G11,0) | H12: =IF(H11>=p_gatillo,H11,0) | I12: =IF(I11>=p_gatillo,I11,0) | J12: =IF(J11>=p_gatillo,J11,0) | K12: =IF(K11>=p_gatillo,K11,0) | ... LI12: =IF(LI11>=p_gatillo,LI11,0)
B13: Factor de reajuste | D13: =TRUNC(IF(D7=0,1,1*(1+D12)*D7),5) | E13: =TRUNC(IF(E7=0,1,D13*(1+E12)*E7),5) | F13: =TRUNC(IF(F7=0,1,E13*(1+F12)*F7),5) | G13: =TRUNC(IF(G7=0,1,F13*(1+G12)*G7),5) | H13: =TRUNC(IF(H7=0,1,G13*(1+H12)*H7),5) | I13: =TRUNC(IF(I7=0,1,H13*(1+I12)*I7),5) | J13: =TRUNC(IF(J7=0,1,I13*(1+J12)*J7),5) | K13: =TRUNC(IF(K7=0,1,J13*(1+K12)*K7),5) | L13: =TRUNC(IF(L7=0,1,K13*(1+L12)*L7),5) | ... LI13: =TRUNC(IF(LI7=0,1,LH13*(1+LI12)*LI7),5)
B14: Ingreso tarifario mensual | D14: =IF(D7=0,0,p_tarifa_usuario*D9*D13)/1000 | E14: =IF(E7=0,0,p_tarifa_usuario*E9*E13)/1000 | F14: =IF(F7=0,0,p_tarifa_usuario*F9*F13)/1000 | G14: =IF(G7=0,0,p_tarifa_usuario*G9*G13)/1000 | H14: =IF(H7=0,0,p_tarifa_usuario*H9*H13)/1000 | I14: =IF(I7=0,0,p_tarifa_usuario*I9*I13)/1000 | J14: =IF(J7=0,0,p_tarifa_usuario*J9*J13)/1000 | K14: =IF(K7=0,0,p_tarifa_usuario*K9*K13)/1000 | ... LI14: =IF(LI7=0,0,p_tarifa_usuario*LI9*LI13)/1000
B15: Primer mes de operacion | D15: =IF(AND(D7=1,0=0),1,0) | E15: =IF(AND(E7=1,SUM($D7:D7)=0),1,0) | F15: =IF(AND(F7=1,SUM($D7:E7)=0),1,0) | G15: =IF(AND(G7=1,SUM($D7:F7)=0),1,0) | H15: =IF(AND(H7=1,SUM($D7:G7)=0),1,0) | I15: =IF(AND(I7=1,SUM($D7:H7)=0),1,0) | J15: =IF(AND(J7=1,SUM($D7:I7)=0),1,0) | K15: =IF(AND(K7=1,SUM($D7:J7)=0),1,0) | L15: =IF(AND(L7=1,SUM($D7:K7)=0),1,0) | ... LI15: =IF(AND(LI7=1,SUM($D7:LH7)=0),1,0)

Sheet Activo intangible
B2: Activo intangible de la concesion
B3: CINIIF 12 p.17: derecho a cobrar al usuario, no importe determinable del concedente. p.22: intereses de obra capitalizados.
B6: Mes | D6: 2026-10-31 | E6: 2026-11-30 | F6: 2026-12-31 | G6: 2027-01-31 | H6: 2027-02-28 | I6: 2027-03-31 | J6: 2027-04-30 | K6: 2027-05-31 | L6: 2027-06-30 | M6: 2027-07-31 | N6: 2027-08-31 | O6: 2027-09-30 | P6: 2027-10-31 | Q6: 2027-11-30 | R6: 2027-12-31 | S6: 2028-01-31 | T6: 2028-02-29 | U6: 2028-03-31 | V6: 2028-04-30 | W6: 2028-05-31 | X6: 2028-06-30 | Y6: 2028-07-31 | Z6: 2028-08-31 | AA6: 2028-09-30 | AB6: 2028-10-31 | AC6: 2028-11-30 | AD6: 2028-12-31 | AE6: 2029-01-31 | AF6: 2029-02-28 | AG6: 2029-03-31 | AH6: 2029-04-30 | AI6: 2029-05-31 | AJ6: 2029-06-30 | AK6: 2029-07-31 | AL6: 2029-08-31 | AM6: 2029-09-30 | AN6: 2029-10-31 | AO6: 2029-11-30 | AP6: 2029-12-31 | AQ6: 2030-01-31 | AR6: 2030-02-28 | AS6: 2030-03-31 | AT6: 2030-04-30 | AU6: 2030-05-31 | AV6: 2030-06-30 | AW6: 2030-07-31 | AX6: 2030-08-31 | AY6: 2030-09-30 | AZ6: 2030-10-31 | BA6: 2030-11-30 | BB6: 2030-12-31 | BC6: 2031-01-31 | BD6: 2031-02-28 | BE6: 2031-03-31 | BF6: 2031-04-30 | BG6: 2031-05-31 | BH6: 2031-06-30 | BI6: 2031-07-31 | BJ6: 2031-08-31 | BK6: 2031-09-30 | BL6: 2031-10-31 | BM6: 2031-11-30 | BN6: 2031-12-31 | BO6: 2032-01-31 | BP6: 2032-02-29 | BQ6: 2032-03-31 | BR6: 2032-04-30 | BS6: 2032-05-31 | BT6: 2032-06-30 | BU6: 2032-07-31 | BV6: 2032-08-31 | BW6: 2032-09-30 | BX6: 2032-10-31 | BY6: 2032-11-30 | BZ6: 2032-12-31 | CA6: 2033-01-31 | CB6: 2033-02-28 | CC6: 2033-03-31 | CD6: 2033-04-30 | CE6: 2033-05-31 | CF6: 2033-06-30 | CG6: 2033-07-31 | CH6: 2033-08-31 | CI6: 2033-09-30 | CJ6: 2033-10-31 | CK6: 2033-11-30 | CL6: 2033-12-31 | CM6: 2034-01-31 | CN6: 2034-02-28 | CO6: 2034-03-31 | CP6: 2034-04-30 | CQ6: 2034-05-31 | CR6: 2034-06-30 | CS6: 2034-07-31 | CT6: 2034-08-31 | CU6: 2034-09-30 | CV6: 2034-10-31 | CW6: 2034-11-30 | CX6: 2034-12-31 | CY6: 2035-01-31 | CZ6: 2035-02-28 | DA6: 2035-03-31 | DB6: 2035-04-30 | DC6: 2035-05-31 | DD6: 2035-06-30 | DE6: 2035-07-31 | DF6: 2035-08-31 | DG6: 2035-09-30 | DH6: 2035-10-31 | DI6: 2035-11-30 | DJ6: 2035-12-31 | DK6: 2036-01-31 | DL6: 2036-02-29 | DM6: 2036-03-31 | DN6: 2036-04-30 | DO6: 2036-05-31 | DP6: 2036-06-30 | DQ6: 2036-07-31 | DR6: 2036-08-31 | DS6: 2036-09-30 | DT6: 2036-10-31 | DU6: 2036-11-30 | DV6: 2036-12-31 | DW6: 2037-01-31 | DX6: 2037-02-28 | DY6: 2037-03-31 | DZ6: 2037-04-30 | EA6: 2037-05-31 | EB6: 2037-06-30 | EC6: 2037-07-31 | ED6: 2037-08-31 | EE6: 2037-09-30 | EF6: 2037-10-31 | EG6: 2037-11-30 | EH6: 2037-12-31 | EI6: 2038-01-31 | EJ6: 2038-02-28 | EK6: 2038-03-31 | EL6: 2038-04-30 | EM6: 2038-05-31 | EN6: 2038-06-30 | EO6: 2038-07-31 | EP6: 2038-08-31 | EQ6: 2038-09-30 | ER6: 2038-10-31 | ES6: 2038-11-30 | ET6: 2038-12-31 | EU6: 2039-01-31 | EV6: 2039-02-28 | EW6: 2039-03-31 | EX6: 2039-04-30 | EY6: 2039-05-31 | EZ6: 2039-06-30 | FA6: 2039-07-31 | FB6: 2039-08-31 | FC6: 2039-09-30 | FD6: 2039-10-31 | FE6: 2039-11-30 | FF6: 2039-12-31 | FG6: 2040-01-31 | FH6: 2040-02-29 | FI6: 2040-03-31 | FJ6: 2040-04-30 | FK6: 2040-05-31 | FL6: 2040-06-30 | FM6: 2040-07-31 | FN6: 2040-08-31 | FO6: 2040-09-30 | FP6: 2040-10-31 | FQ6: 2040-11-30 | FR6: 2040-12-31 | FS6: 2041-01-31 | FT6: 2041-02-28 | FU6: 2041-03-31 | FV6: 2041-04-30 | FW6: 2041-05-31 | FX6: 2041-06-30 | FY6: 2041-07-31 | FZ6: 2041-08-31 | GA6: 2041-09-30 | GB6: 2041-10-31 | GC6: 2041-11-30 | GD6: 2041-12-31 | GE6: 2042-01-31 | GF6: 2042-02-28 | GG6: 2042-03-31 | GH6: 2042-04-30 | GI6: 2042-05-31 | GJ6: 2042-06-30 | GK6: 2042-07-31 | GL6: 2042-08-31 | GM6: 2042-09-30 | GN6: 2042-10-31 | GO6: 2042-11-30 | GP6: 2042-12-31 | GQ6: 2043-01-31 | GR6: 2043-02-28 | GS6: 2043-03-31 | GT6: 2043-04-30 | GU6: 2043-05-31 | GV6: 2043-06-30 | GW6: 2043-07-31 | GX6: 2043-08-31 | GY6: 2043-09-30 | GZ6: 2043-10-31 | HA6: 2043-11-30 | HB6: 2043-12-31 | HC6: 2044-01-31 | HD6: 2044-02-29 | HE6: 2044-03-31 | HF6: 2044-04-30 | HG6: 2044-05-31 | HH6: 2044-06-30 | HI6: 2044-07-31 | HJ6: 2044-08-31 | HK6: 2044-09-30 | HL6: 2044-10-31 | HM6: 2044-11-30 | HN6: 2044-12-31 | HO6: 2045-01-31 | HP6: 2045-02-28 | HQ6: 2045-03-31 | HR6: 2045-04-30 | HS6: 2045-05-31 | HT6: 2045-06-30 | HU6: 2045-07-31 | HV6: 2045-08-31 | HW6: 2045-09-30 | HX6: 2045-10-31 | HY6: 2045-11-30 | HZ6: 2045-12-31 | IA6: 2046-01-31 | IB6: 2046-02-28 | IC6: 2046-03-31 | ID6: 2046-04-30 | IE6: 2046-05-31 | IF6: 2046-06-30 | IG6: 2046-07-31 | IH6: 2046-08-31 | II6: 2046-09-30 | IJ6: 2046-10-31 | IK6: 2046-11-30 | IL6: 2046-12-31 | IM6: 2047-01-31 | IN6: 2047-02-28 | IO6: 2047-03-31 | IP6: 2047-04-30 | IQ6: 2047-05-31 | IR6: 2047-06-30 | IS6: 2047-07-31 | IT6: 2047-08-31 | IU6: 2047-09-30 | IV6: 2047-10-31 | IW6: 2047-11-30 | IX6: 2047-12-31 | IY6: 2048-01-31 | IZ6: 2048-02-29 | JA6: 2048-03-31 | JB6: 2048-04-30 | JC6: 2048-05-31 | JD6: 2048-06-30 | JE6: 2048-07-31 | JF6: 2048-08-31 | JG6: 2048-09-30 | JH6: 2048-10-31 | JI6: 2048-11-30 | JJ6: 2048-12-31 | JK6: 2049-01-31 | JL6: 2049-02-28 | JM6: 2049-03-31 | JN6: 2049-04-30 | JO6: 2049-05-31 | JP6: 2049-06-30 | JQ6: 2049-07-31 | JR6: 2049-08-31 | JS6: 2049-09-30 | JT6: 2049-10-31 | JU6: 2049-11-30 | JV6: 2049-12-31 | JW6: 2050-01-31 | JX6: 2050-02-28 | JY6: 2050-03-31 | JZ6: 2050-04-30 | KA6: 2050-05-31 | KB6: 2050-06-30 | KC6: 2050-07-31 | KD6: 2050-08-31 | KE6: 2050-09-30 | KF6: 2050-10-31 | KG6: 2050-11-30 | KH6: 2050-12-31 | KI6: 2051-01-31 | KJ6: 2051-02-28 | KK6: 2051-03-31 | KL6: 2051-04-30 | KM6: 2051-05-31 | KN6: 2051-06-30 | KO6: 2051-07-31 | KP6: 2051-08-31 | KQ6: 2051-09-30 | KR6: 2051-10-31 | KS6: 2051-11-30 | KT6: 2051-12-31 | KU6: 2052-01-31 | KV6: 2052-02-29 | KW6: 2052-03-31 | KX6: 2052-04-30 | KY6: 2052-05-31 | KZ6: 2052-06-30 | LA6: 2052-07-31 | LB6: 2052-08-31 | LC6: 2052-09-30 | LD6: 2052-10-31 | LE6: 2052-11-30 | LF6: 2052-12-31 | LG6: 2053-01-31 | LH6: 2053-02-28 | LI6: 2053-03-31
B7: Meses de operacion | D7: =SUM($D$12:$LI$12)
B8: Base del intangible al termino de obra | D8: =SUM($D$16:$LI$16)
B9: Amortizacion lineal mensual | D9: =$D$8/$D$7
B10: Trimestre del mes | D10: 1 | E10: 1 | F10: 1 | G10: 2 | H10: 2 | I10: 2 | J10: 3 | K10: 3 | L10: 3 | M10: 4 | N10: 4 | O10: 4 | P10: 5 | Q10: 5 | R10: 5 | S10: 6 | T10: 6 | U10: 6 | V10: 7 | W10: 7 | X10: 7 | Y10: 8 | Z10: 8 | AA10: 8 | AB10: 9 | AC10: 9 | AD10: 9 | AE10: 10 | AF10: 10 | AG10: 10 | AH10: 11 | AI10: 11 | AJ10: 11 | AK10: 12 | AL10: 12 | AM10: 12 | AN10: 13 | AO10: 13 | AP10: 13 | AQ10: 14 | AR10: 14 | AS10: 14 | AT10: 15 | AU10: 15 | AV10: 15 | AW10: 16 | AX10: 16 | AY10: 16 | AZ10: 17 | BA10: 17 | BB10: 17 | BC10: 18 | BD10: 18 | BE10: 18 | BF10: 19 | BG10: 19 | BH10: 19 | BI10: 20 | BJ10: 20 | BK10: 20 | BL10: 21 | BM10: 21 | BN10: 21 | BO10: 22 | BP10: 22 | BQ10: 22 | BR10: 23 | BS10: 23 | BT10: 23 | BU10: 24 | BV10: 24 | BW10: 24 | BX10: 25 | BY10: 25 | BZ10: 25 | CA10: 26 | CB10: 26 | CC10: 26 | CD10: 27 | CE10: 27 | CF10: 27 | CG10: 28 | CH10: 28 | CI10: 28 | CJ10: 29 | CK10: 29 | CL10: 29 | CM10: 30 | CN10: 30 | CO10: 30 | CP10: 31 | CQ10: 31 | CR10: 31 | CS10: 32 | CT10: 32 | CU10: 32 | CV10: 33 | CW10: 33 | CX10: 33 | CY10: 34 | CZ10: 34 | DA10: 34 | DB10: 35 | DC10: 35 | DD10: 35 | DE10: 36 | DF10: 36 | DG10: 36 | DH10: 37 | DI10: 37 | DJ10: 37 | DK10: 38 | DL10: 38 | DM10: 38 | DN10: 39 | DO10: 39 | DP10: 39 | DQ10: 40 | DR10: 40 | DS10: 40 | DT10: 41 | DU10: 41 | DV10: 41 | DW10: 42 | DX10: 42 | DY10: 42 | DZ10: 43 | EA10: 43 | EB10: 43 | EC10: 44 | ED10: 44 | EE10: 44 | EF10: 45 | EG10: 45 | EH10: 45 | EI10: 46 | EJ10: 46 | EK10: 46 | EL10: 47 | EM10: 47 | EN10: 47 | EO10: 48 | EP10: 48 | EQ10: 48 | ER10: 49 | ES10: 49 | ET10: 49 | EU10: 50 | EV10: 50 | EW10: 50 | EX10: 51 | EY10: 51 | EZ10: 51 | FA10: 52 | FB10: 52 | FC10: 52 | FD10: 53 | FE10: 53 | FF10: 53 | FG10: 54 | FH10: 54 | FI10: 54 | FJ10: 55 | FK10: 55 | FL10: 55 | FM10: 56 | FN10: 56 | FO10: 56 | FP10: 57 | FQ10: 57 | FR10: 57 | FS10: 58 | FT10: 58 | FU10: 58 | FV10: 59 | FW10: 59 | FX10: 59 | FY10: 60 | FZ10: 60 | GA10: 60 | GB10: 61 | GC10: 61 | GD10: 61 | GE10: 62 | GF10: 62 | GG10: 62 | GH10: 63 | GI10: 63 | GJ10: 63 | GK10: 64 | GL10: 64 | GM10: 64 | GN10: 65 | GO10: 65 | GP10: 65 | GQ10: 66 | GR10: 66 | GS10: 66 | GT10: 67 | GU10: 67 | GV10: 67 | GW10: 68 | GX10: 68 | GY10: 68 | GZ10: 69 | HA10: 69 | HB10: 69 | HC10: 70 | HD10: 70 | HE10: 70 | HF10: 71 | HG10: 71 | HH10: 71 | HI10: 72 | HJ10: 72 | HK10: 72 | HL10: 73 | HM10: 73 | HN10: 73 | HO10: 74 | HP10: 74 | HQ10: 74 | HR10: 75 | HS10: 75 | HT10: 75 | HU10: 76 | HV10: 76 | HW10: 76 | HX10: 77 | HY10: 77 | HZ10: 77 | IA10: 78 | IB10: 78 | IC10: 78 | ID10: 79 | IE10: 79 | IF10: 79 | IG10: 80 | IH10: 80 | II10: 80 | IJ10: 81 | IK10: 81 | IL10: 81 | IM10: 82 | IN10: 82 | IO10: 82 | IP10: 83 | IQ10: 83 | IR10: 83 | IS10: 84 | IT10: 84 | IU10: 84 | IV10: 85 | IW10: 85 | IX10: 85 | IY10: 86 | IZ10: 86 | JA10: 86 | JB10: 87 | JC10: 87 | JD10: 87 | JE10: 88 | JF10: 88 | JG10: 88 | JH10: 89 | JI10: 89 | JJ10: 89 | JK10: 90 | JL10: 90 | JM10: 90 | JN10: 91 | JO10: 91 | JP10: 91 | JQ10: 92 | JR10: 92 | JS10: 92 | JT10: 93 | JU10: 93 | JV10: 93 | JW10: 94 | JX10: 94 | JY10: 94 | JZ10: 95 | KA10: 95 | KB10: 95 | KC10: 96 | KD10: 96 | KE10: 96 | KF10: 97 | KG10: 97 | KH10: 97 | KI10: 98 | KJ10: 98 | KK10: 98 | KL10: 99 | KM10: 99 | KN10: 99 | KO10: 100 | KP10: 100 | KQ10: 100 | KR10: 101 | KS10: 101 | KT10: 101 | KU10: 102 | KV10: 102 | KW10: 102 | KX10: 103 | KY10: 103 | KZ10: 103 | LA10: 104 | LB10: 104 | LC10: 104 | LD10: 105 | LE10: 105 | LF10: 105 | LG10: 106 | LH10: 106 | LI10: 106
B11: Flag anterior a la operacion | D11: 1 | E11: 1 | F11: 1 | G11: 1 | H11: 1 | I11: 1 | J11: 1 | K11: 1 | L11: 1 | M11: 1 | N11: 1 | O11: 1 | P11: 1 | Q11: 1 | R11: 1 | S11: 1 | T11: 1 | U11: 1 | V11: 1 | W11: 1 | X11: 1 | Y11: 1 | Z11: 1 | AA11: 1 | AB11: 1 | AC11: 1 | AD11: 1 | AE11: 1 | AF11: 1 | AG11: 1 | AH11: 1 | AI11: 1 | AJ11: 1 | AK11: 1 | AL11: 1 | AM11: 1 | AN11: 1 | AO11: 1 | AP11: 1 | AQ11: 1 | AR11: 1 | AS11: 1 | AT11: 1 | AU11: 1 | AV11: 1 | AW11: 1 | AX11: 1 | AY11: 1 | AZ11: 0 | BA11: 0 | BB11: 0 | BC11: 0 | BD11: 0 | BE11: 0 | BF11: 0 | BG11: 0 | BH11: 0 | BI11: 0 | BJ11: 0 | BK11: 0 | BL11: 0 | BM11: 0 | BN11: 0 | BO11: 0 | BP11: 0 | BQ11: 0 | BR11: 0 | BS11: 0 | BT11: 0 | BU11: 0 | BV11: 0 | BW11: 0 | BX11: 0 | BY11: 0 | BZ11: 0 | CA11: 0 | CB11: 0 | CC11: 0 | CD11: 0 | CE11: 0 | CF11: 0 | CG11: 0 | CH11: 0 | CI11: 0 | CJ11: 0 | CK11: 0 | CL11: 0 | CM11: 0 | CN11: 0 | CO11: 0 | CP11: 0 | CQ11: 0 | CR11: 0 | CS11: 0 | CT11: 0 | CU11: 0 | CV11: 0 | CW11: 0 | CX11: 0 | CY11: 0 | CZ11: 0 | DA11: 0 | DB11: 0 | DC11: 0 | DD11: 0 | DE11: 0 | DF11: 0 | DG11: 0 | DH11: 0 | DI11: 0 | DJ11: 0 | DK11: 0 | DL11: 0 | DM11: 0 | DN11: 0 | DO11: 0 | DP11: 0 | DQ11: 0 | DR11: 0 | DS11: 0 | DT11: 0 | DU11: 0 | DV11: 0 | DW11: 0 | DX11: 0 | DY11: 0 | DZ11: 0 | EA11: 0 | EB11: 0 | EC11: 0 | ED11: 0 | EE11: 0 | EF11: 0 | EG11: 0 | EH11: 0 | EI11: 0 | EJ11: 0 | EK11: 0 | EL11: 0 | EM11: 0 | EN11: 0 | EO11: 0 | EP11: 0 | EQ11: 0 | ER11: 0 | ES11: 0 | ET11: 0 | EU11: 0 | EV11: 0 | EW11: 0 | EX11: 0 | EY11: 0 | EZ11: 0 | FA11: 0 | FB11: 0 | FC11: 0 | FD11: 0 | FE11: 0 | FF11: 0 | FG11: 0 | FH11: 0 | FI11: 0 | FJ11: 0 | FK11: 0 | FL11: 0 | FM11: 0 | FN11: 0 | FO11: 0 | FP11: 0 | FQ11: 0 | FR11: 0 | FS11: 0 | FT11: 0 | FU11: 0 | FV11: 0 | FW11: 0 | FX11: 0 | FY11: 0 | FZ11: 0 | GA11: 0 | GB11: 0 | GC11: 0 | GD11: 0 | GE11: 0 | GF11: 0 | GG11: 0 | GH11: 0 | GI11: 0 | GJ11: 0 | GK11: 0 | GL11: 0 | GM11: 0 | GN11: 0 | GO11: 0 | GP11: 0 | GQ11: 0 | GR11: 0 | GS11: 0 | GT11: 0 | GU11: 0 | GV11: 0 | GW11: 0 | GX11: 0 | GY11: 0 | GZ11: 0 | HA11: 0 | HB11: 0 | HC11: 0 | HD11: 0 | HE11: 0 | HF11: 0 | HG11: 0 | HH11: 0 | HI11: 0 | HJ11: 0 | HK11: 0 | HL11: 0 | HM11: 0 | HN11: 0 | HO11: 0 | HP11: 0 | HQ11: 0 | HR11: 0 | HS11: 0 | HT11: 0 | HU11: 0 | HV11: 0 | HW11: 0 | HX11: 0 | HY11: 0 | HZ11: 0 | IA11: 0 | IB11: 0 | IC11: 0 | ID11: 0 | IE11: 0 | IF11: 0 | IG11: 0 | IH11: 0 | II11: 0 | IJ11: 0 | IK11: 0 | IL11: 0 | IM11: 0 | IN11: 0 | IO11: 0 | IP11: 0 | IQ11: 0 | IR11: 0 | IS11: 0 | IT11: 0 | IU11: 0 | IV11: 0 | IW11: 0 | IX11: 0 | IY11: 0 | IZ11: 0 | JA11: 0 | JB11: 0 | JC11: 0 | JD11: 0 | JE11: 0 | JF11: 0 | JG11: 0 | JH11: 0 | JI11: 0 | JJ11: 0 | JK11: 0 | JL11: 0 | JM11: 0 | JN11: 0 | JO11: 0 | JP11: 0 | JQ11: 0 | JR11: 0 | JS11: 0 | JT11: 0 | JU11: 0 | JV11: 0 | JW11: 0 | JX11: 0 | JY11: 0 | JZ11: 0 | KA11: 0 | KB11: 0 | KC11: 0 | KD11: 0 | KE11: 0 | KF11: 0 | KG11: 0 | KH11: 0 | KI11: 0 | KJ11: 0 | KK11: 0 | KL11: 0 | KM11: 0 | KN11: 0 | KO11: 0 | KP11: 0 | KQ11: 0 | KR11: 0 | KS11: 0 | KT11: 0 | KU11: 0 | KV11: 0 | KW11: 0 | KX11: 0 | KY11: 0 | KZ11: 0 | LA11: 0 | LB11: 0 | LC11: 0 | LD11: 0 | LE11: 0 | LF11: 0 | LG11: 0 | LH11: 0 | LI11: 0
B12: Flag de operacion | D12: 0 | E12: 0 | F12: 0 | G12: 0 | H12: 0 | I12: 0 | J12: 0 | K12: 0 | L12: 0 | M12: 0 | N12: 0 | O12: 0 | P12: 0 | Q12: 0 | R12: 0 | S12: 0 | T12: 0 | U12: 0 | V12: 0 | W12: 0 | X12: 0 | Y12: 0 | Z12: 0 | AA12: 0 | AB12: 0 | AC12: 0 | AD12: 0 | AE12: 0 | AF12: 0 | AG12: 0 | AH12: 0 | AI12: 0 | AJ12: 0 | AK12: 0 | AL12: 0 | AM12: 0 | AN12: 0 | AO12: 0 | AP12: 0 | AQ12: 0 | AR12: 0 | AS12: 0 | AT12: 0 | AU12: 0 | AV12: 0 | AW12: 0 | AX12: 0 | AY12: 0 | AZ12: 1 | BA12: 1 | BB12: 1 | BC12: 1 | BD12: 1 | BE12: 1 | BF12: 1 | BG12: 1 | BH12: 1 | BI12: 1 | BJ12: 1 | BK12: 1 | BL12: 1 | BM12: 1 | BN12: 1 | BO12: 1 | BP12: 1 | BQ12: 1 | BR12: 1 | BS12: 1 | BT12: 1 | BU12: 1 | BV12: 1 | BW12: 1 | BX12: 1 | BY12: 1 | BZ12: 1 | CA12: 1 | CB12: 1 | CC12: 1 | CD12: 1 | CE12: 1 | CF12: 1 | CG12: 1 | CH12: 1 | CI12: 1 | CJ12: 1 | CK12: 1 | CL12: 1 | CM12: 1 | CN12: 1 | CO12: 1 | CP12: 1 | CQ12: 1 | CR12: 1 | CS12: 1 | CT12: 1 | CU12: 1 | CV12: 1 | CW12: 1 | CX12: 1 | CY12: 1 | CZ12: 1 | DA12: 1 | DB12: 1 | DC12: 1 | DD12: 1 | DE12: 1 | DF12: 1 | DG12: 1 | DH12: 1 | DI12: 1 | DJ12: 1 | DK12: 1 | DL12: 1 | DM12: 1 | DN12: 1 | DO12: 1 | DP12: 1 | DQ12: 1 | DR12: 1 | DS12: 1 | DT12: 1 | DU12: 1 | DV12: 1 | DW12: 1 | DX12: 1 | DY12: 1 | DZ12: 1 | EA12: 1 | EB12: 1 | EC12: 1 | ED12: 1 | EE12: 1 | EF12: 1 | EG12: 1 | EH12: 1 | EI12: 1 | EJ12: 1 | EK12: 1 | EL12: 1 | EM12: 1 | EN12: 1 | EO12: 1 | EP12: 1 | EQ12: 1 | ER12: 1 | ES12: 1 | ET12: 1 | EU12: 1 | EV12: 1 | EW12: 1 | EX12: 1 | EY12: 1 | EZ12: 1 | FA12: 1 | FB12: 1 | FC12: 1 | FD12: 1 | FE12: 1 | FF12: 1 | FG12: 1 | FH12: 1 | FI12: 1 | FJ12: 1 | FK12: 1 | FL12: 1 | FM12: 1 | FN12: 1 | FO12: 1 | FP12: 1 | FQ12: 1 | FR12: 1 | FS12: 1 | FT12: 1 | FU12: 1 | FV12: 1 | FW12: 1 | FX12: 1 | FY12: 1 | FZ12: 1 | GA12: 1 | GB12: 1 | GC12: 1 | GD12: 1 | GE12: 1 | GF12: 1 | GG12: 1 | GH12: 1 | GI12: 1 | GJ12: 1 | GK12: 1 | GL12: 1 | GM12: 1 | GN12: 1 | GO12: 1 | GP12: 1 | GQ12: 1 | GR12: 1 | GS12: 1 | GT12: 1 | GU12: 1 | GV12: 1 | GW12: 1 | GX12: 1 | GY12: 1 | GZ12: 1 | HA12: 1 | HB12: 1 | HC12: 1 | HD12: 1 | HE12: 1 | HF12: 1 | HG12: 1 | HH12: 1 | HI12: 1 | HJ12: 1 | HK12: 1 | HL12: 1 | HM12: 1 | HN12: 1 | HO12: 1 | HP12: 1 | HQ12: 1 | HR12: 1 | HS12: 1 | HT12: 1 | HU12: 1 | HV12: 1 | HW12: 1 | HX12: 1 | HY12: 1 | HZ12: 1 | IA12: 1 | IB12: 1 | IC12: 1 | ID12: 1 | IE12: 1 | IF12: 1 | IG12: 1 | IH12: 1 | II12: 1 | IJ12: 1 | IK12: 1 | IL12: 1 | IM12: 1 | IN12: 1 | IO12: 1 | IP12: 1 | IQ12: 1 | IR12: 1 | IS12: 1 | IT12: 1 | IU12: 1 | IV12: 1 | IW12: 1 | IX12: 1 | IY12: 1 | IZ12: 1 | JA12: 1 | JB12: 1 | JC12: 1 | JD12: 1 | JE12: 1 | JF12: 1 | JG12: 1 | JH12: 1 | JI12: 1 | JJ12: 1 | JK12: 1 | JL12: 1 | JM12: 1 | JN12: 1 | JO12: 1 | JP12: 1 | JQ12: 1 | JR12: 1 | JS12: 1 | JT12: 1 | JU12: 1 | JV12: 1 | JW12: 1 | JX12: 1 | JY12: 1 | JZ12: 1 | KA12: 1 | KB12: 1 | KC12: 1 | KD12: 1 | KE12: 1 | KF12: 1 | KG12: 1 | KH12: 1 | KI12: 1 | KJ12: 1 | KK12: 1 | KL12: 1 | KM12: 1 | KN12: 1 | KO12: 1 | KP12: 1 | KQ12: 1 | KR12: 1 | KS12: 1 | KT12: 1 | KU12: 1 | KV12: 1 | KW12: 1 | KX12: 1 | KY12: 1 | KZ12: 1 | LA12: 1 | LB12: 1 | LC12: 1 | LD12: 0 | LE12: 0 | LF12: 0 | LG12: 0 | LH12: 0 | LI12: 0
