Workbook
Name p_costo_obra: Inputs!$D$6
Name p_tamano_deuda: Inputs!$D$7
Name p_kd: Inputs!$D$8
Name p_spread: Inputs!$D$9
Name p_ke: Inputs!$D$10
Name p_wacc: Inputs!$D$11
Name p_pagos: Inputs!$D$12
Name p_ipm: Inputs!$D$13
Name p_gatillo: Inputs!$D$14
Name p_ipc: Inputs!$D$15
Name p_ir: Inputs!$D$16
Name p_part: Inputs!$D$17
Name p_superv: Inputs!$D$18
Name p_margen_cf: Inputs!$D$19
Name p_fijo_base: Inputs!$D$20
Name p_tarifa: Inputs!$D$21
Name p_ppdi_anual: Inputs!$D$22

Sheet Resumen
B2: Resumen del modelo
B3: S/ miles sin IGV, primer mes de operacion anualizado.
B6: PPD Inversiones, anual | D6: =p_ppdi_anual
B7: PPD MO fijo, anual | D7: =SUMPRODUCT(PPDMO!$D$21:$LI$21,PPDMO!$D$15:$LI$15)*12
B8: PPD MO variable, anual | D8: =SUMPRODUCT(PPDMO!$D$21:$LI$21,PPDMO!$D$16:$LI$16)*12
B9: PPD MO total, anual | D9: =D7+D8
B10: PPD total, anual | D10: =D6+D9
B11: Tarifa unitaria, S/ por kg DBO5 | D11: =p_tarifa
B12: VAN financiero, debe ser cero | D12: =Flujo!$D$34
B13: WACC | D13: =p_wacc
B14: Kd | D14: =p_kd
B15: Ke | D15: =p_ke
B16: Activo financiero, saldo maximo | D16: =MAX('Activo financiero'!$D$17:$LC$17)
B17: Activo financiero, amortizacion acumulada | D17: =SUM('Activo financiero'!$D$16:$LC$16)
B18: Activo financiero, saldo final | D18: ='Activo financiero'!$LC$17
B19: Tasa implicita del activo, anual | D19: =(1+'Activo financiero'!$D$7)^12-1

Sheet Inputs
B2: Parametros del modelo
B3: Las celdas en ambar son de entrada. Las dos ultimas las resuelve el cierre.
B6: Costo de obra a financiar | D6: 261144.81 | E6: S/ miles
B7: Tamano de deuda | D7: 0.8 | E7: % del costo de obra
B8: Kd, costo de la deuda | D8: 0.10092957 | E8: soberano a vida media + spread
B9: Spread de deuda | D9: 0.035 | E9: sondeo de mercado
B10: Ke, costo del patrimonio | D10: 0.12622649 | E10: CAPM en USD + riesgo pais + devaluacion
B11: WACC | D11: 0.097303479 | E11: despues de impuestos
B12: Numero de pagos de la deuda | D12: 144 | E12: meses
B13: IPM, reajuste de ingresos | D13: 0.0267 | E13: anual
B14: Gatillo del reajuste | D14: 0.03 | E14: acumulado que dispara el ajuste
B15: IPC, reajuste de costos | D15: 0.02 | E15: anual, sin gatillo
B16: Tasa de Impuesto a la Renta | D16: 0.295
B17: Participacion de trabajadores | D17: 0.05
B18: Supervision SUNASS | D18: 0.01 | E18: % del PPD
B19: Margen del costo fijo | D19: 0.15 | E19: pass-through de costos
B20: PPDMO fijo base mensual | D20: 556.65918 | E20: S/ miles, calculado de costos
B21: Tarifa variable | D21: 3.8583316 | E21: S/ por kg DBO5 - LA CIERRA Buscar Objetivo
B22: PPDI anual | D22: 46362.146 | E22: S/ miles - LA CIERRA Buscar Objetivo

Sheet Deuda
B2: Deuda financiera
B3: Cuota constante: el servicio sale de PMT y la amortizacion es el residuo.
B6: Mes | D6: 2026-10-31 | E6: 2026-11-30 | F6: 2026-12-31 | G6: 2027-01-31 | H6: 2027-02-28 | I6: 2027-03-31 | J6: 2027-04-30 | K6: 2027-05-31 | L6: 2027-06-30 | M6: 2027-07-31 | N6: 2027-08-31 | O6: 2027-09-30 | P6: 2027-10-31 | Q6: 2027-11-30 | R6: 2027-12-31 | S6: 2028-01-31 | T6: 2028-02-29 | U6: 2028-03-31 | V6: 2028-04-30 | W6: 2028-05-31 | X6: 2028-06-30 | Y6: 2028-07-31 | Z6: 2028-08-31 | AA6: 2028-09-30 | AB6: 2028-10-31 | AC6: 2028-11-30 | AD6: 2028-12-31 | AE6: 2029-01-31 | AF6: 2029-02-28 | AG6: 2029-03-31 | AH6: 2029-04-30 | AI6: 2029-05-31 | AJ6: 2029-06-30 | AK6: 2029-07-31 | AL6: 2029-08-31 | AM6: 2029-09-30 | AN6: 2029-10-31 | AO6: 2029-11-30 | AP6: 2029-12-31 | AQ6: 2030-01-31 | AR6: 2030-02-28 | AS6: 2030-03-31 | AT6: 2030-04-30 | AU6: 2030-05-31 | AV6: 2030-06-30 | AW6: 2030-07-31 | AX6: 2030-08-31 | AY6: 2030-09-30 | AZ6: 2030-10-31 | BA6: 2030-11-30 | BB6: 2030-12-31 | BC6: 2031-01-31 | BD6: 2031-02-28 | BE6: 2031-03-31 | BF6: 2031-04-30 | BG6: 2031-05-31 | BH6: 2031-06-30 | BI6: 2031-07-31 | BJ6: 2031-08-31 | BK6: 2031-09-30 | BL6: 2031-10-31 | BM6: 2031-11-30 | BN6: 2031-12-31 | BO6: 2032-01-31 | BP6: 2032-02-29 | BQ6: 2032-03-31 | BR6: 2032-04-30 | BS6: 2032-05-31 | BT6: 2032-06-30 | BU6: 2032-07-31 | BV6: 2032-08-31 | BW6: 2032-09-30 | BX6: 2032-10-31 | BY6: 2032-11-30 | BZ6: 2032-12-31 | CA6: 2033-01-31 | CB6: 2033-02-28 | CC6: 2033-03-31 | CD6: 2033-04-30 | CE6: 2033-05-31 | CF6: 2033-06-30 | CG6: 2033-07-31 | CH6: 2033-08-31 | CI6: 2033-09-30 | CJ6: 2033-10-31 | CK6: 2033-11-30 | CL6: 2033-12-31 | CM6: 2034-01-31 | CN6: 2034-02-28 | CO6: 2034-03-31 | CP6: 2034-04-30 | CQ6: 2034-05-31 | CR6: 2034-06-30 | CS6: 2034-07-31 | CT6: 2034-08-31 | CU6: 2034-09-30 | CV6: 2034-10-31 | CW6: 2034-11-30 | CX6: 2034-12-31 | CY6: 2035-01-31 | CZ6: 2035-02-28 | DA6: 2035-03-31 | DB6: 2035-04-30 | DC6: 2035-05-31 | DD6: 2035-06-30 | DE6: 2035-07-31 | DF6: 2035-08-31 | DG6: 2035-09-30 | DH6: 2035-10-31 | DI6: 2035-11-30 | DJ6: 2035-12-31 | DK6: 2036-01-31 | DL6: 2036-02-29 | DM6: 2036-03-31 | DN6: 2036-04-30 | DO6: 2036-05-31 | DP6: 2036-06-30 | DQ6: 2036-07-31 | DR6: 2036-08-31 | DS6: 2036-09-30 | DT6: 2036-10-31 | DU6: 2036-11-30 | DV6: 2036-12-31 | DW6: 2037-01-31 | DX6: 2037-02-28 | DY6: 2037-03-31 | DZ6: 2037-04-30 | EA6: 2037-05-31 | EB6: 2037-06-30 | EC6: 2037-07-31 | ED6: 2037-08-31 | EE6: 2037-09-30 | EF6: 2037-10-31 | EG6: 2037-11-30 | EH6: 2037-12-31 | EI6: 2038-01-31 | EJ6: 2038-02-28 | EK6: 2038-03-31 | EL6: 2038-04-30 | EM6: 2038-05-31 | EN6: 2038-06-30 | EO6: 2038-07-31 | EP6: 2038-08-31 | EQ6: 2038-09-30 | ER6: 2038-10-31 | ES6: 2038-11-30 | ET6: 2038-12-31 | EU6: 2039-01-31 | EV6: 2039-02-28 | EW6: 2039-03-31 | EX6: 2039-04-30 | EY6: 2039-05-31 | EZ6: 2039-06-30 | FA6: 2039-07-31 | FB6: 2039-08-31 | FC6: 2039-09-30 | FD6: 2039-10-31 | FE6: 2039-11-30 | FF6: 2039-12-31 | FG6: 2040-01-31 | FH6: 2040-02-29 | FI6: 2040-03-31 | FJ6: 2040-04-30 | FK6: 2040-05-31 | FL6: 2040-06-30 | FM6: 2040-07-31 | FN6: 2040-08-31 | FO6: 2040-09-30 | FP6: 2040-10-31 | FQ6: 2040-11-30 | FR6: 2040-12-31 | FS6: 2041-01-31 | FT6: 2041-02-28 | FU6: 2041-03-31 | FV6: 2041-04-30 | FW6: 2041-05-31 | FX6: 2041-06-30 | FY6: 2041-07-31 | FZ6: 2041-08-31 | GA6: 2041-09-30 | GB6: 2041-10-31 | GC6: 2041-11-30 | GD6: 2041-12-31 | GE6: 2042-01-31 | GF6: 2042-02-28 | GG6: 2042-03-31 | GH6: 2042-04-30 | GI6: 2042-05-31 | GJ6: 2042-06-30 | GK6: 2042-07-31 | GL6: 2042-08-31 | GM6: 2042-09-30 | GN6: 2042-10-31 | GO6: 2042-11-30 | GP6: 2042-12-31 | GQ6: 2043-01-31 | GR6: 2043-02-28 | GS6: 2043-03-31 | GT6: 2043-04-30 | GU6: 2043-05-31 | GV6: 2043-06-30 | GW6: 2043-07-31 | GX6: 2043-08-31 | GY6: 2043-09-30 | GZ6: 2043-10-31 | HA6: 2043-11-30 | HB6: 2043-12-31 | HC6: 2044-01-31 | HD6: 2044-02-29 | HE6: 2044-03-31 | HF6: 2044-04-30 | HG6: 2044-05-31 | HH6: 2044-06-30 | HI6: 2044-07-31 | HJ6: 2044-08-31 | HK6: 2044-09-30 | HL6: 2044-10-31 | HM6: 2044-11-30 | HN6: 2044-12-31 | HO6: 2045-01-31 | HP6: 2045-02-28 | HQ6: 2045-03-31 | HR6: 2045-04-30 | HS6: 2045-05-31 | HT6: 2045-06-30 | HU6: 2045-07-31 | HV6: 2045-08-31 | HW6: 2045-09-30 | HX6: 2045-10-31 | HY6: 2045-11-30 | HZ6: 2045-12-31 | IA6: 2046-01-31 | IB6: 2046-02-28 | IC6: 2046-03-31 | ID6: 2046-04-30 | IE6: 2046-05-31 | IF6: 2046-06-30 | IG6: 2046-07-31 | IH6: 2046-08-31 | II6: 2046-09-30 | IJ6: 2046-10-31 | IK6: 2046-11-30 | IL6: 2046-12-31 | IM6: 2047-01-31 | IN6: 2047-02-28 | IO6: 2047-03-31 | IP6: 2047-04-30 | IQ6: 2047-05-31 | IR6: 2047-06-30 | IS6: 2047-07-31 | IT6: 2047-08-31 | IU6: 2047-09-30 | IV6: 2047-10-31 | IW6: 2047-11-30 | IX6: 2047-12-31 | IY6: 2048-01-31 | IZ6: 2048-02-29 | JA6: 2048-03-31 | JB6: 2048-04-30 | JC6: 2048-05-31 | JD6: 2048-06-30 | JE6: 2048-07-31 | JF6: 2048-08-31 | JG6: 2048-09-30 | JH6: 2048-10-31 | JI6: 2048-11-30 | JJ6: 2048-12-31 | JK6: 2049-01-31 | JL6: 2049-02-28 | JM6: 2049-03-31 | JN6: 2049-04-30 | JO6: 2049-05-31 | JP6: 2049-06-30 | JQ6: 2049-07-31 | JR6: 2049-08-31 | JS6: 2049-09-30 | JT6: 2049-10-31 | JU6: 2049-11-30 | JV6: 2049-12-31 | JW6: 2050-01-31 | JX6: 2050-02-28 | JY6: 2050-03-31 | JZ6: 2050-04-30 | KA6: 2050-05-31 | KB6: 2050-06-30 | KC6: 2050-07-31 | KD6: 2050-08-31 | KE6: 2050-09-30 | KF6: 2050-10-31 | KG6: 2050-11-30 | KH6: 2050-12-31 | KI6: 2051-01-31 | KJ6: 2051-02-28 | KK6: 2051-03-31 | KL6: 2051-04-30 | KM6: 2051-05-31 | KN6: 2051-06-30 | KO6: 2051-07-31 | KP6: 2051-08-31 | KQ6: 2051-09-30 | KR6: 2051-10-31 | KS6: 2051-11-30 | KT6: 2051-12-31 | KU6: 2052-01-31 | KV6: 2052-02-29 | KW6: 2052-03-31 | KX6: 2052-04-30 | KY6: 2052-05-31 | KZ6: 2052-06-30 | LA6: 2052-07-31 | LB6: 2052-08-31 | LC6: 2052-09-30 | LD6: 2052-10-31 | LE6: 2052-11-30 | LF6: 2052-12-31 | LG6: 2053-01-31 | LH6: 2053-02-28 | LI6: 2053-03-31
B7: Flag obra y puesta en marcha | D7: 0 | E7: 0 | F7: 0 | G7: 0 | H7: 0 | I7: 0 | J7: 0 | K7: 0 | L7: 0 | M7: 0 | N7: 0 | O7: 0 | P7: 0 | Q7: 0 | R7: 0 | S7: 0 | T7: 0 | U7: 0 | V7: 0 | W7: 0 | X7: 0 | Y7: 1 | Z7: 1 | AA7: 1 | AB7: 1 | AC7: 1 | AD7: 1 | AE7: 1 | AF7: 1 | AG7: 1 | AH7: 1 | AI7: 1 | AJ7: 1 | AK7: 1 | AL7: 1 | AM7: 1 | AN7: 1 | AO7: 1 | AP7: 1 | AQ7: 1 | AR7: 1 | AS7: 1 | AT7: 1 | AU7: 1 | AV7: 1 | AW7: 1 | AX7: 1 | AY7: 1 | AZ7: 0 | BA7: 0 | BB7: 0 | BC7: 0 | BD7: 0 | BE7: 0 | BF7: 0 | BG7: 0 | BH7: 0 | BI7: 0 | BJ7: 0 | BK7: 0 | BL7: 0 | BM7: 0 | BN7: 0 | BO7: 0 | BP7: 0 | BQ7: 0 | BR7: 0 | BS7: 0 | BT7: 0 | BU7: 0 | BV7: 0 | BW7: 0 | BX7: 0 | BY7: 0 | BZ7: 0 | CA7: 0 | CB7: 0 | CC7: 0 | CD7: 0 | CE7: 0 | CF7: 0 | CG7: 0 | CH7: 0 | CI7: 0 | CJ7: 0 | CK7: 0 | CL7: 0 | CM7: 0 | CN7: 0 | CO7: 0 | CP7: 0 | CQ7: 0 | CR7: 0 | CS7: 0 | CT7: 0 | CU7: 0 | CV7: 0 | CW7: 0 | CX7: 0 | CY7: 0 | CZ7: 0 | DA7: 0 | DB7: 0 | DC7: 0 | DD7: 0 | DE7: 0 | DF7: 0 | DG7: 0 | DH7: 0 | DI7: 0 | DJ7: 0 | DK7: 0 | DL7: 0 | DM7: 0 | DN7: 0 | DO7: 0 | DP7: 0 | DQ7: 0 | DR7: 0 | DS7: 0 | DT7: 0 | DU7: 0 | DV7: 0 | DW7: 0 | DX7: 0 | DY7: 0 | DZ7: 0 | EA7: 0 | EB7: 0 | EC7: 0 | ED7: 0 | EE7: 0 | EF7: 0 | EG7: 0 | EH7: 0 | EI7: 0 | EJ7: 0 | EK7: 0 | EL7: 0 | EM7: 0 | EN7: 0 | EO7: 0 | EP7: 0 | EQ7: 0 | ER7: 0 | ES7: 0 | ET7: 0 | EU7: 0 | EV7: 0 | EW7: 0 | EX7: 0 | EY7: 0 | EZ7: 0 | FA7: 0 | FB7: 0 | FC7: 0 | FD7: 0 | FE7: 0 | FF7: 0 | FG7: 0 | FH7: 0 | FI7: 0 | FJ7: 0 | FK7: 0 | FL7: 0 | FM7: 0 | FN7: 0 | FO7: 0 | FP7: 0 | FQ7: 0 | FR7: 0 | FS7: 0 | FT7: 0 | FU7: 0 | FV7: 0 | FW7: 0 | FX7: 0 | FY7: 0 | FZ7: 0 | GA7: 0 | GB7: 0 | GC7: 0 | GD7: 0 | GE7: 0 | GF7: 0 | GG7: 0 | GH7: 0 | GI7: 0 | GJ7: 0 | GK7: 0 | GL7: 0 | GM7: 0 | GN7: 0 | GO7: 0 | GP7: 0 | GQ7: 0 | GR7: 0 | GS7: 0 | GT7: 0 | GU7: 0 | GV7: 0 | GW7: 0 | GX7: 0 | GY7: 0 | GZ7: 0 | HA7: 0 | HB7: 0 | HC7: 0 | HD7: 0 | HE7: 0 | HF7: 0 | HG7: 0 | HH7: 0 | HI7: 0 | HJ7: 0 | HK7: 0 | HL7: 0 | HM7: 0 | HN7: 0 | HO7: 0 | HP7: 0 | HQ7: 0 | HR7: 0 | HS7: 0 | HT7: 0 | HU7: 0 | HV7: 0 | HW7: 0 | HX7: 0 | HY7: 0 | HZ7: 0 | IA7: 0 | IB7: 0 | IC7: 0 | ID7: 0 | IE7: 0 | IF7: 0 | IG7: 0 | IH7: 0 | II7: 0 | IJ7: 0 | IK7: 0 | IL7: 0 | IM7: 0 | IN7: 0 | IO7: 0 | IP7: 0 | IQ7: 0 | IR7: 0 | IS7: 0 | IT7: 0 | IU7: 0 | IV7: 0 | IW7: 0 | IX7: 0 | IY7: 0 | IZ7: 0 | JA7: 0 | JB7: 0 | JC7: 0 | JD7: 0 | JE7: 0 | JF7: 0 | JG7: 0 | JH7: 0 | JI7: 0 | JJ7: 0 | JK7: 0 | JL7: 0 | JM7: 0 | JN7: 0 | JO7: 0 | JP7: 0 | JQ7: 0 | JR7: 0 | JS7: 0 | JT7: 0 | JU7: 0 | JV7: 0 | JW7: 0 | JX7: 0 | JY7: 0 | JZ7: 0 | KA7: 0 | KB7: 0 | KC7: 0 | KD7: 0 | KE7: 0 | KF7: 0 | KG7: 0 | KH7: 0 | KI7: 0 | KJ7: 0 | KK7: 0 | KL7: 0 | KM7: 0 | KN7: 0 | KO7: 0 | KP7: 0 | KQ7: 0 | KR7: 0 | KS7: 0 | KT7: 0 | KU7: 0 | KV7: 0 | KW7: 0 | KX7: 0 | KY7: 0 | KZ7: 0 | LA7: 0 | LB7: 0 | LC7: 0 | LD7: 0 | LE7: 0 | LF7: 0 | LG7: 0 | LH7: 0 | LI7: 0
B8: Flag de pago de deuda | D8: 0 | E8: 0 | F8: 0 | G8: 0 | H8: 0 | I8: 0 | J8: 0 | K8: 0 | L8: 0 | M8: 0 | N8: 0 | O8: 0 | P8: 0 | Q8: 0 | R8: 0 | S8: 0 | T8: 0 | U8: 0 | V8: 0 | W8: 0 | X8: 0 | Y8: 0 | Z8: 0 | AA8: 0 | AB8: 0 | AC8: 0 | AD8: 0 | AE8: 0 | AF8: 0 | AG8: 0 | AH8: 0 | AI8: 0 | AJ8: 0 | AK8: 0 | AL8: 0 | AM8: 0 | AN8: 0 | AO8: 0 | AP8: 0 | AQ8: 0 | AR8: 0 | AS8: 0 | AT8: 0 | AU8: 0 | AV8: 0 | AW8: 0 | AX8: 0 | AY8: 0 | AZ8: 1 | BA8: 1 | BB8: 1 | BC8: 1 | BD8: 1 | BE8: 1 | BF8: 1 | BG8: 1 | BH8: 1 | BI8: 1 | BJ8: 1 | BK8: 1 | BL8: 1 | BM8: 1 | BN8: 1 | BO8: 1 | BP8: 1 | BQ8: 1 | BR8: 1 | BS8: 1 | BT8: 1 | BU8: 1 | BV8: 1 | BW8: 1 | BX8: 1 | BY8: 1 | BZ8: 1 | CA8: 1 | CB8: 1 | CC8: 1 | CD8: 1 | CE8: 1 | CF8: 1 | CG8: 1 | CH8: 1 | CI8: 1 | CJ8: 1 | CK8: 1 | CL8: 1 | CM8: 1 | CN8: 1 | CO8: 1 | CP8: 1 | CQ8: 1 | CR8: 1 | CS8: 1 | CT8: 1 | CU8: 1 | CV8: 1 | CW8: 1 | CX8: 1 | CY8: 1 | CZ8: 1 | DA8: 1 | DB8: 1 | DC8: 1 | DD8: 1 | DE8: 1 | DF8: 1 | DG8: 1 | DH8: 1 | DI8: 1 | DJ8: 1 | DK8: 1 | DL8: 1 | DM8: 1 | DN8: 1 | DO8: 1 | DP8: 1 | DQ8: 1 | DR8: 1 | DS8: 1 | DT8: 1 | DU8: 1 | DV8: 1 | DW8: 1 | DX8: 1 | DY8: 1 | DZ8: 1 | EA8: 1 | EB8: 1 | EC8: 1 | ED8: 1 | EE8: 1 | EF8: 1 | EG8: 1 | EH8: 1 | EI8: 1 | EJ8: 1 | EK8: 1 | EL8: 1 | EM8: 1 | EN8: 1 | EO8: 1 | EP8: 1 | EQ8: 1 | ER8: 1 | ES8: 1 | ET8: 1 | EU8: 1 | EV8: 1 | EW8: 1 | EX8: 1 | EY8: 1 | EZ8: 1 | FA8: 1 | FB8: 1 | FC8: 1 | FD8: 1 | FE8: 1 | FF8: 1 | FG8: 1 | FH8: 1 | FI8: 1 | FJ8: 1 | FK8: 1 | FL8: 1 | FM8: 1 | FN8: 1 | FO8: 1 | FP8: 1 | FQ8: 1 | FR8: 1 | FS8: 1 | FT8: 1 | FU8: 1 | FV8: 1 | FW8: 1 | FX8: 1 | FY8: 1 | FZ8: 1 | GA8: 1 | GB8: 1 | GC8: 1 | GD8: 1 | GE8: 1 | GF8: 1 | GG8: 1 | GH8: 1 | GI8: 1 | GJ8: 1 | GK8: 1 | GL8: 1 | GM8: 1 | GN8: 0 | GO8: 0 | GP8: 0 | GQ8: 0 | GR8: 0 | GS8: 0 | GT8: 0 | GU8: 0 | GV8: 0 | GW8: 0 | GX8: 0 | GY8: 0 | GZ8: 0 | HA8: 0 | HB8: 0 | HC8: 0 | HD8: 0 | HE8: 0 | HF8: 0 | HG8: 0 | HH8: 0 | HI8: 0 | HJ8: 0 | HK8: 0 | HL8: 0 | HM8: 0 | HN8: 0 | HO8: 0 | HP8: 0 | HQ8: 0 | HR8: 0 | HS8: 0 | HT8: 0 | HU8: 0 | HV8: 0 | HW8: 0 | HX8: 0 | HY8: 0 | HZ8: 0 | IA8: 0 | IB8: 0 | IC8: 0 | ID8: 0 | IE8: 0 | IF8: 0 | IG8: 0 | IH8: 0 | II8: 0 | IJ8: 0 | IK8: 0 | IL8: 0 | IM8: 0 | IN8: 0 | IO8: 0 | IP8: 0 | IQ8: 0 | IR8: 0 | IS8: 0 | IT8: 0 | IU8: 0 | IV8: 0 | IW8: 0 | IX8: 0 | IY8: 0 | IZ8: 0 | JA8: 0 | JB8: 0 | JC8: 0 | JD8: 0 | JE8: 0 | JF8: 0 | JG8: 0 | JH8: 0 | JI8: 0 | JJ8: 0 | JK8: 0 | JL8: 0 | JM8: 0 | JN8: 0 | JO8: 0 | JP8: 0 | JQ8: 0 | JR8: 0 | JS8: 0 | JT8: 0 | JU8: 0 | JV8: 0 | JW8: 0 | JX8: 0 | JY8: 0 | JZ8: 0 | KA8: 0 | KB8: 0 | KC8: 0 | KD8: 0 | KE8: 0 | KF8: 0 | KG8: 0 | KH8: 0 | KI8: 0 | KJ8: 0 | KK8: 0 | KL8: 0 | KM8: 0 | KN8: 0 | KO8: 0 | KP8: 0 | KQ8: 0 | KR8: 0 | KS8: 0 | KT8: 0 | KU8: 0 | KV8: 0 | KW8: 0 | KX8: 0 | KY8: 0 | KZ8: 0 | LA8: 0 | LB8: 0 | LC8: 0 | LD8: 0 | LE8: 0 | LF8: 0 | LG8: 0 | LH8: 0 | LI8: 0
B9: Inversion a financiarse | D9: 0 | E9: 0 | F9: 0 | G9: 0 | H9: 0 | I9: 0 | J9: 0 | K9: 0 | L9: 0 | M9: 0 | N9: 0 | O9: 0 | P9: 0 | Q9: 0 | R9: 0 | S9: 0 | T9: 0 | U9: 0 | V9: 0 | W9: 0 | X9: 0 | Y9: 42887.065 | Z9: 6255.7562 | AA9: 6266.0881 | AB9: 6276.4371 | AC9: 6286.8031 | AD9: 6297.1863 | AE9: 15790.504 | AF9: 15816.583 | AG9: 15842.705 | AH9: 15868.871 | AI9: 15642.805 | AJ9: 15633.192 | AK9: 13673.055 | AL9: 13671.281 | AM9: 13091.902 | AN9: 13113.525 | AO9: 14842.491 | AP9: 14831.203 | AQ9: 2451.2709 | AR9: 2455.3194 | AS9: 1600.067 | AT9: 1602.7096 | AU9: 188.97311 | AV9: 189.28521 | AW9: 189.59783 | AX9: 189.91097 | AY9: 190.22462 | AZ9: 0 | BA9: 0 | BB9: 0 | BC9: 0 | BD9: 0 | BE9: 0 | BF9: 0 | BG9: 0 | BH9: 0 | BI9: 0 | BJ9: 0 | BK9: 0 | BL9: 0 | BM9: 0 | BN9: 0 | BO9: 0 | BP9: 0 | BQ9: 0 | BR9: 0 | BS9: 0 | BT9: 0 | BU9: 0 | BV9: 0 | BW9: 0 | BX9: 0 | BY9: 0 | BZ9: 0 | CA9: 0 | CB9: 0 | CC9: 0 | CD9: 0 | CE9: 0 | CF9: 0 | CG9: 0 | CH9: 0 | CI9: 0 | CJ9: 0 | CK9: 0 | CL9: 0 | CM9: 0 | CN9: 0 | CO9: 0 | CP9: 0 | CQ9: 0 | CR9: 0 | CS9: 0 | CT9: 0 | CU9: 0 | CV9: 0 | CW9: 0 | CX9: 0 | CY9: 0 | CZ9: 0 | DA9: 0 | DB9: 0 | DC9: 0 | DD9: 0 | DE9: 0 | DF9: 0 | DG9: 0 | DH9: 0 | DI9: 0 | DJ9: 0 | DK9: 0 | DL9: 0 | DM9: 0 | DN9: 0 | DO9: 0 | DP9: 0 | DQ9: 0 | DR9: 0 | DS9: 0 | DT9: 0 | DU9: 0 | DV9: 0 | DW9: 0 | DX9: 0 | DY9: 0 | DZ9: 0 | EA9: 0 | EB9: 0 | EC9: 0 | ED9: 0 | EE9: 0 | EF9: 0 | EG9: 0 | EH9: 0 | EI9: 0 | EJ9: 0 | EK9: 0 | EL9: 0 | EM9: 0 | EN9: 0 | EO9: 0 | EP9: 0 | EQ9: 0 | ER9: 0 | ES9: 0 | ET9: 0 | EU9: 0 | EV9: 0 | EW9: 0 | EX9: 0 | EY9: 0 | EZ9: 0 | FA9: 0 | FB9: 0 | FC9: 0 | FD9: 0 | FE9: 0 | FF9: 0 | FG9: 0 | FH9: 0 | FI9: 0 | FJ9: 0 | FK9: 0 | FL9: 0 | FM9: 0 | FN9: 0 | FO9: 0 | FP9: 0 | FQ9: 0 | FR9: 0 | FS9: 0 | FT9: 0 | FU9: 0 | FV9: 0 | FW9: 0 | FX9: 0 | FY9: 0 | FZ9: 0 | GA9: 0 | GB9: 0 | GC9: 0 | GD9: 0 | GE9: 0 | GF9: 0 | GG9: 0 | GH9: 0 | GI9: 0 | GJ9: 0 | GK9: 0 | GL9: 0 | GM9: 0 | GN9: 0 | GO9: 0 | GP9: 0 | GQ9: 0 | GR9: 0 | GS9: 0 | GT9: 0 | GU9: 0 | GV9: 0 | GW9: 0 | GX9: 0 | GY9: 0 | GZ9: 0 | HA9: 0 | HB9: 0 | HC9: 0 | HD9: 0 | HE9: 0 | HF9: 0 | HG9: 0 | HH9: 0 | HI9: 0 | HJ9: 0 | HK9: 0 | HL9: 0 | HM9: 0 | HN9: 0 | HO9: 0 | HP9: 0 | HQ9: 0 | HR9: 0 | HS9: 0 | HT9: 0 | HU9: 0 | HV9: 0 | HW9: 0 | HX9: 0 | HY9: 0 | HZ9: 0 | IA9: 0 | IB9: 0 | IC9: 0 | ID9: 0 | IE9: 0 | IF9: 0 | IG9: 0 | IH9: 0 | II9: 0 | IJ9: 0 | IK9: 0 | IL9: 0 | IM9: 0 | IN9: 0 | IO9: 0 | IP9: 0 | IQ9: 0 | IR9: 0 | IS9: 0 | IT9: 0 | IU9: 0 | IV9: 0 | IW9: 0 | IX9: 0 | IY9: 0 | IZ9: 0 | JA9: 0 | JB9: 0 | JC9: 0 | JD9: 0 | JE9: 0 | JF9: 0 | JG9: 0 | JH9: 0 | JI9: 0 | JJ9: 0 | JK9: 0 | JL9: 0 | JM9: 0 | JN9: 0 | JO9: 0 | JP9: 0 | JQ9: 0 | JR9: 0 | JS9: 0 | JT9: 0 | JU9: 0 | JV9: 0 | JW9: 0 | JX9: 0 | JY9: 0 | JZ9: 0 | KA9: 0 | KB9: 0 | KC9: 0 | KD9: 0 | KE9: 0 | KF9: 0 | KG9: 0 | KH9: 0 | KI9: 0 | KJ9: 0 | KK9: 0 | KL9: 0 | KM9: 0 | KN9: 0 | KO9: 0 | KP9: 0 | KQ9: 0 | KR9: 0 | KS9: 0 | KT9: 0 | KU9: 0 | KV9: 0 | KW9: 0 | KX9: 0 | KY9: 0 | KZ9: 0 | LA9: 0 | LB9: 0 | LC9: 0 | LD9: 0 | LE9: 0 | LF9: 0 | LG9: 0 | LH9: 0 | LI9: 0
B10: Desembolsos | D10: =D7*D9*p_tamano_deuda | E10: =E7*E9*p_tamano_deuda | F10: =F7*F9*p_tamano_deuda | G10: =G7*G9*p_tamano_deuda | H10: =H7*H9*p_tamano_deuda | I10: =I7*I9*p_tamano_deuda | J10: =J7*J9*p_tamano_deuda | K10: =K7*K9*p_tamano_deuda | ... LI10: =LI7*LI9*p_tamano_deuda
B11: Tasa mensual | D11: =(1+p_kd)^(1/12)-1
B12: Saldo de obra capitalizado (base de la cuota) | D12: =0*(1+$D$11)+D10 | E12: =D12*(1+$D$11)+E10 | F12: =E12*(1+$D$11)+F10 | G12: =F12*(1+$D$11)+G10 | H12: =G12*(1+$D$11)+H10 | I12: =H12*(1+$D$11)+I10 | J12: =I12*(1+$D$11)+J10 | K12: =J12*(1+$D$11)+K10 | L12: =K12*(1+$D$11)+L10 | ... AY12: =AX12*(1+$D$11)+AY10 | AZ12: 0 | BA12: 0 | BB12: 0 | BC12: 0 | BD12: 0 | BE12: 0 | BF12: 0 | BG12: 0 | BH12: 0 | BI12: 0 | BJ12: 0 | BK12: 0 | BL12: 0 | BM12: 0 | BN12: 0 | BO12: 0 | BP12: 0 | BQ12: 0 | BR12: 0 | BS12: 0 | BT12: 0 | BU12: 0 | BV12: 0 | BW12: 0 | BX12: 0 | BY12: 0 | BZ12: 0 | CA12: 0 | CB12: 0 | CC12: 0 | CD12: 0 | CE12: 0 | CF12: 0 | CG12: 0 | CH12: 0 | CI12: 0 | CJ12: 0 | CK12: 0 | CL12: 0 | CM12: 0 | CN12: 0 | CO12: 0 | CP12: 0 | CQ12: 0 | CR12: 0 | CS12: 0 | CT12: 0 | CU12: 0 | CV12: 0 | CW12: 0 | CX12: 0 | CY12: 0 | CZ12: 0 | DA12: 0 | DB12: 0 | DC12: 0 | DD12: 0 | DE12: 0 | DF12: 0 | DG12: 0 | DH12: 0 | DI12: 0 | DJ12: 0 | DK12: 0 | DL12: 0 | DM12: 0 | DN12: 0 | DO12: 0 | DP12: 0 | DQ12: 0 | DR12: 0 | DS12: 0 | DT12: 0 | DU12: 0 | DV12: 0 | DW12: 0 | DX12: 0 | DY12: 0 | DZ12: 0 | EA12: 0 | EB12: 0 | EC12: 0 | ED12: 0 | EE12: 0 | EF12: 0 | EG12: 0 | EH12: 0 | EI12: 0 | EJ12: 0 | EK12: 0 | EL12: 0 | EM12: 0 | EN12: 0 | EO12: 0 | EP12: 0 | EQ12: 0 | ER12: 0 | ES12: 0 | ET12: 0 | EU12: 0 | EV12: 0 | EW12: 0 | EX12: 0 | EY12: 0 | EZ12: 0 | FA12: 0 | FB12: 0 | FC12: 0 | FD12: 0 | FE12: 0 | FF12: 0 | FG12: 0 | FH12: 0 | FI12: 0 | FJ12: 0 | FK12: 0 | FL12: 0 | FM12: 0 | FN12: 0 | FO12: 0 | FP12: 0 | FQ12: 0 | FR12: 0 | FS12: 0 | FT12: 0 | FU12: 0 | FV12: 0 | FW12: 0 | FX12: 0 | FY12: 0 | FZ12: 0 | GA12: 0 | GB12: 0 | GC12: 0 | GD12: 0 | GE12: 0 | GF12: 0 | GG12: 0 | GH12: 0 | GI12: 0 | GJ12: 0 | GK12: 0 | GL12: 0 | GM12: 0 | GN12: 0 | GO12: 0 | GP12: 0 | GQ12: 0 | GR12: 0 | GS12: 0 | GT12: 0 | GU12: 0 | GV12: 0 | GW12: 0 | GX12: 0 | GY12: 0 | GZ12: 0 | HA12: 0 | HB12: 0 | HC12: 0 | HD12: 0 | HE12: 0 | HF12: 0 | HG12: 0 | HH12: 0 | HI12: 0 | HJ12: 0 | HK12: 0 | HL12: 0 | HM12: 0 | HN12: 0 | HO12: 0 | HP12: 0 | HQ12: 0 | HR12: 0 | HS12: 0 | HT12: 0 | HU12: 0 | HV12: 0 | HW12: 0 | HX12: 0 | HY12: 0 | HZ12: 0 | IA12: 0 | IB12: 0 | IC12: 0 | ID12: 0 | IE12: 0 | IF12: 0 | IG12: 0 | IH12: 0 | II12: 0 | IJ12: 0 | IK12: 0 | IL12: 0 | IM12: 0 | IN12: 0 | IO12: 0 | IP12: 0 | IQ12: 0 | IR12: 0 | IS12: 0 | IT12: 0 | IU12: 0 | IV12: 0 | IW12: 0 | IX12: 0 | IY12: 0 | IZ12: 0 | JA12: 0 | JB12: 0 | JC12: 0 | JD12: 0 | JE12: 0 | JF12: 0 | JG12: 0 | JH12: 0 | JI12: 0 | JJ12: 0 | JK12: 0 | JL12: 0 | JM12: 0 | JN12: 0 | JO12: 0 | JP12: 0 | JQ12: 0 | JR12: 0 | JS12: 0 | JT12: 0 | JU12: 0 | JV12: 0 | JW12: 0 | JX12: 0 | JY12: 0 | JZ12: 0 | KA12: 0 | KB12: 0 | KC12: 0 | KD12: 0 | KE12: 0 | KF12: 0 | KG12: 0 | KH12: 0 | KI12: 0 | KJ12: 0 | KK12: 0 | KL12: 0 | KM12: 0 | KN12: 0 | KO12: 0 | KP12: 0 | KQ12: 0 | KR12: 0 | KS12: 0 | KT12: 0 | KU12: 0 | KV12: 0 | KW12: 0 | KX12: 0 | KY12: 0 | KZ12: 0 | LA12: 0 | LB12: 0 | LC12: 0 | LD12: 0 | LE12: 0 | LF12: 0 | LG12: 0 | LH12: 0 | LI12: 0
B13: Cuota constante | D13: =-PMT($D$11,p_pagos,AY12)
B14: Interes | D14: 0 | E14: =D17*$D$11 | F14: =E17*$D$11 | G14: =F17*$D$11 | H14: =G17*$D$11 | I14: =H17*$D$11 | J14: =I17*$D$11 | K14: =J17*$D$11 | L14: =K17*$D$11 | ... LI14: =LH17*$D$11
B15: Amortizacion | D15: =D16-D14 | E15: =E16-E14 | F15: =F16-F14 | G15: =G16-G14 | H15: =H16-H14 | I15: =I16-I14 | J15: =J16-J14 | K15: =K16-K14 | ... LI15: =LI16-LI14
B16: Servicio de deuda | D16: =D8*$D$13 | E16: =E8*$D$13 | F16: =F8*$D$13 | G16: =G8*$D$13 | H16: =H8*$D$13 | I16: =I8*$D$13 | J16: =J8*$D$13 | K16: =K8*$D$13 | ... LI16: =LI8*$D$13
B17: Saldo deudor | D17: =0+D10-D15 | E17: =D17+E10-E15 | F17: =E17+F10-F15 | G17: =F17+G10-G15 | H17: =G17+H10-H15 | I17: =H17+I10-I15 | J17: =I17+J10-J15 | K17: =J17+K10-K15 | L17: =K17+L10-L15 | ... LI17: =LH17+LI10-LI15

Sheet Activo financiero
B2: Activo financiero del PPDI
B3: CINIIF 12 p.16: derecho incondicional de cobro, no intangible. Amortizacion = cobro del mes menos ingreso financiero devengado.
B6: Mes | D6: 2026-10-31 | E6: 2026-11-30 | F6: 2026-12-31 | G6: 2027-01-31 | H6: 2027-02-28 | I6: 2027-03-31 | J6: 2027-04-30 | K6: 2027-05-31 | L6: 2027-06-30 | M6: 2027-07-31 | N6: 2027-08-31 | O6: 2027-09-30 | P6: 2027-10-31 | Q6: 2027-11-30 | R6: 2027-12-31 | S6: 2028-01-31 | T6: 2028-02-29 | U6: 2028-03-31 | V6: 2028-04-30 | W6: 2028-05-31 | X6: 2028-06-30 | Y6: 2028-07-31 | Z6: 2028-08-31 | AA6: 2028-09-30 | AB6: 2028-10-31 | AC6: 2028-11-30 | AD6: 2028-12-31 | AE6: 2029-01-31 | AF6: 2029-02-28 | AG6: 2029-03-31 | AH6: 2029-04-30 | AI6: 2029-05-31 | AJ6: 2029-06-30 | AK6: 2029-07-31 | AL6: 2029-08-31 | AM6: 2029-09-30 | AN6: 2029-10-31 | AO6: 2029-11-30 | AP6: 2029-12-31 | AQ6: 2030-01-31 | AR6: 2030-02-28 | AS6: 2030-03-31 | AT6: 2030-04-30 | AU6: 2030-05-31 | AV6: 2030-06-30 | AW6: 2030-07-31 | AX6: 2030-08-31 | AY6: 2030-09-30 | AZ6: 2030-10-31 | BA6: 2030-11-30 | BB6: 2030-12-31 | BC6: 2031-01-31 | BD6: 2031-02-28 | BE6: 2031-03-31 | BF6: 2031-04-30 | BG6: 2031-05-31 | BH6: 2031-06-30 | BI6: 2031-07-31 | BJ6: 2031-08-31 | BK6: 2031-09-30 | BL6: 2031-10-31 | BM6: 2031-11-30 | BN6: 2031-12-31 | BO6: 2032-01-31 | BP6: 2032-02-29 | BQ6: 2032-03-31 | BR6: 2032-04-30 | BS6: 2032-05-31 | BT6: 2032-06-30 | BU6: 2032-07-31 | BV6: 2032-08-31 | BW6: 2032-09-30 | BX6: 2032-10-31 | BY6: 2032-11-30 | BZ6: 2032-12-31 | CA6: 2033-01-31 | CB6: 2033-02-28 | CC6: 2033-03-31 | CD6: 2033-04-30 | CE6: 2033-05-31 | CF6: 2033-06-30 | CG6: 2033-07-31 | CH6: 2033-08-31 | CI6: 2033-09-30 | CJ6: 2033-10-31 | CK6: 2033-11-30 | CL6: 2033-12-31 | CM6: 2034-01-31 | CN6: 2034-02-28 | CO6: 2034-03-31 | CP6: 2034-04-30 | CQ6: 2034-05-31 | CR6: 2034-06-30 | CS6: 2034-07-31 | CT6: 2034-08-31 | CU6: 2034-09-30 | CV6: 2034-10-31 | CW6: 2034-11-30 | CX6: 2034-12-31 | CY6: 2035-01-31 | CZ6: 2035-02-28 | DA6: 2035-03-31 | DB6: 2035-04-30 | DC6: 2035-05-31 | DD6: 2035-06-30 | DE6: 2035-07-31 | DF6: 2035-08-31 | DG6: 2035-09-30 | DH6: 2035-10-31 | DI6: 2035-11-30 | DJ6: 2035-12-31 | DK6: 2036-01-31 | DL6: 2036-02-29 | DM6: 2036-03-31 | DN6: 2036-04-30 | DO6: 2036-05-31 | DP6: 2036-06-30 | DQ6: 2036-07-31 | DR6: 2036-08-31 | DS6: 2036-09-30 | DT6: 2036-10-31 | DU6: 2036-11-30 | DV6: 2036-12-31 | DW6: 2037-01-31 | DX6: 2037-02-28 | DY6: 2037-03-31 | DZ6: 2037-04-30 | EA6: 2037-05-31 | EB6: 2037-06-30 | EC6: 2037-07-31 | ED6: 2037-08-31 | EE6: 2037-09-30 | EF6: 2037-10-31 | EG6: 2037-11-30 | EH6: 2037-12-31 | EI6: 2038-01-31 | EJ6: 2038-02-28 | EK6: 2038-03-31 | EL6: 2038-04-30 | EM6: 2038-05-31 | EN6: 2038-06-30 | EO6: 2038-07-31 | EP6: 2038-08-31 | EQ6: 2038-09-30 | ER6: 2038-10-31 | ES6: 2038-11-30 | ET6: 2038-12-31 | EU6: 2039-01-31 | EV6: 2039-02-28 | EW6: 2039-03-31 | EX6: 2039-04-30 | EY6: 2039-05-31 | EZ6: 2039-06-30 | FA6: 2039-07-31 | FB6: 2039-08-31 | FC6: 2039-09-30 | FD6: 2039-10-31 | FE6: 2039-11-30 | FF6: 2039-12-31 | FG6: 2040-01-31 | FH6: 2040-02-29 | FI6: 2040-03-31 | FJ6: 2040-04-30 | FK6: 2040-05-31 | FL6: 2040-06-30 | FM6: 2040-07-31 | FN6: 2040-08-31 | FO6: 2040-09-30 | FP6: 2040-10-31 | FQ6: 2040-11-30 | FR6: 2040-12-31 | FS6: 2041-01-31 | FT6: 2041-02-28 | FU6: 2041-03-31 | FV6: 2041-04-30 | FW6: 2041-05-31 | FX6: 2041-06-30 | FY6: 2041-07-31 | FZ6: 2041-08-31 | GA6: 2041-09-30 | GB6: 2041-10-31 | GC6: 2041-11-30 | GD6: 2041-12-31 | GE6: 2042-01-31 | GF6: 2042-02-28 | GG6: 2042-03-31 | GH6: 2042-04-30 | GI6: 2042-05-31 | GJ6: 2042-06-30 | GK6: 2042-07-31 | GL6: 2042-08-31 | GM6: 2042-09-30 | GN6: 2042-10-31 | GO6: 2042-11-30 | GP6: 2042-12-31 | GQ6: 2043-01-31 | GR6: 2043-02-28 | GS6: 2043-03-31 | GT6: 2043-04-30 | GU6: 2043-05-31 | GV6: 2043-06-30 | GW6: 2043-07-31 | GX6: 2043-08-31 | GY6: 2043-09-30 | GZ6: 2043-10-31 | HA6: 2043-11-30 | HB6: 2043-12-31 | HC6: 2044-01-31 | HD6: 2044-02-29 | HE6: 2044-03-31 | HF6: 2044-04-30 | HG6: 2044-05-31 | HH6: 2044-06-30 | HI6: 2044-07-31 | HJ6: 2044-08-31 | HK6: 2044-09-30 | HL6: 2044-10-31 | HM6: 2044-11-30 | HN6: 2044-12-31 | HO6: 2045-01-31 | HP6: 2045-02-28 | HQ6: 2045-03-31 | HR6: 2045-04-30 | HS6: 2045-05-31 | HT6: 2045-06-30 | HU6: 2045-07-31 | HV6: 2045-08-31 | HW6: 2045-09-30 | HX6: 2045-10-31 | HY6: 2045-11-30 | HZ6: 2045-12-31 | IA6: 2046-01-31 | IB6: 2046-02-28 | IC6: 2046-03-31 | ID6: 2046-04-30 | IE6: 2046-05-31 | IF6: 2046-06-30 | IG6: 2046-07-31 | IH6: 2046-08-31 | II6: 2046-09-30 | IJ6: 2046-10-31 | IK6: 2046-11-30 | IL6: 2046-12-31 | IM6: 2047-01-31 | IN6: 2047-02-28 | IO6: 2047-03-31 | IP6: 2047-04-30 | IQ6: 2047-05-31 | IR6: 2047-06-30 | IS6: 2047-07-31 | IT6: 2047-08-31 | IU6: 2047-09-30 | IV6: 2047-10-31 | IW6: 2047-11-30 | IX6: 2047-12-31 | IY6: 2048-01-31 | IZ6: 2048-02-29 | JA6: 2048-03-31 | JB6: 2048-04-30 | JC6: 2048-05-31 | JD6: 2048-06-30 | JE6: 2048-07-31 | JF6: 2048-08-31 | JG6: 2048-09-30 | JH6: 2048-10-31 | JI6: 2048-11-30 | JJ6: 2048-12-31 | JK6: 2049-01-31 | JL6: 2049-02-28 | JM6: 2049-03-31 | JN6: 2049-04-30 | JO6: 2049-05-31 | JP6: 2049-06-30 | JQ6: 2049-07-31 | JR6: 2049-08-31 | JS6: 2049-09-30 | JT6: 2049-10-31 | JU6: 2049-11-30 | JV6: 2049-12-31 | JW6: 2050-01-31 | JX6: 2050-02-28 | JY6: 2050-03-31 | JZ6: 2050-04-30 | KA6: 2050-05-31 | KB6: 2050-06-30 | KC6: 2050-07-31 | KD6: 2050-08-31 | KE6: 2050-09-30 | KF6: 2050-10-31 | KG6: 2050-11-30 | KH6: 2050-12-31 | KI6: 2051-01-31 | KJ6: 2051-02-28 | KK6: 2051-03-31 | KL6: 2051-04-30 | KM6: 2051-05-31 | KN6: 2051-06-30 | KO6: 2051-07-31 | KP6: 2051-08-31 | KQ6: 2051-09-30 | KR6: 2051-10-31 | KS6: 2051-11-30 | KT6: 2051-12-31 | KU6: 2052-01-31 | KV6: 2052-02-29 | KW6: 2052-03-31 | KX6: 2052-04-30 | KY6: 2052-05-31 | KZ6: 2052-06-30 | LA6: 2052-07-31 | LB6: 2052-08-31 | LC6: 2052-09-30
B7: Tasa implicita mensual | C7: TIR del activo | D7: 0.0086694967
B8: Flag de devengo del PPDI | D8: 0 | E8: 0 | F8: 0 | G8: 0 | H8: 0 | I8: 0 | J8: 0 | K8: 0 | L8: 0 | M8: 0 | N8: 0 | O8: 0 | P8: 0 | Q8: 0 | R8: 0 | S8: 0 | T8: 0 | U8: 0 | V8: 0 | W8: 0 | X8: 0 | Y8: 0 | Z8: 0 | AA8: 0 | AB8: 0 | AC8: 0 | AD8: 0 | AE8: 0 | AF8: 0 | AG8: 0 | AH8: 0 | AI8: 0 | AJ8: 0 | AK8: 0 | AL8: 0 | AM8: 0 | AN8: 0 | AO8: 0 | AP8: 0 | AQ8: 0 | AR8: 0 | AS8: 0 | AT8: 0 | AU8: 0 | AV8: 0 | AW8: 0 | AX8: 0 | AY8: 0 | AZ8: 1 | BA8: 1 | BB8: 1 | BC8: 1 | BD8: 1 | BE8: 1 | BF8: 1 | BG8: 1 | BH8: 1 | BI8: 1 | BJ8: 1 | BK8: 1 | BL8: 1 | BM8: 1 | BN8: 1 | BO8: 1 | BP8: 1 | BQ8: 1 | BR8: 1 | BS8: 1 | BT8: 1 | BU8: 1 | BV8: 1 | BW8: 1 | BX8: 1 | BY8: 1 | BZ8: 1 | CA8: 1 | CB8: 1 | CC8: 1 | CD8: 1 | CE8: 1 | CF8: 1 | CG8: 1 | CH8: 1 | CI8: 1 | CJ8: 1 | CK8: 1 | CL8: 1 | CM8: 1 | CN8: 1 | CO8: 1 | CP8: 1 | CQ8: 1 | CR8: 1 | CS8: 1 | CT8: 1 | CU8: 1 | CV8: 1 | CW8: 1 | CX8: 1 | CY8: 1 | CZ8: 1 | DA8: 1 | DB8: 1 | DC8: 1 | DD8: 1 | DE8: 1 | DF8: 1 | DG8: 1 | DH8: 1 | DI8: 1 | DJ8: 1 | DK8: 1 | DL8: 1 | DM8: 1 | DN8: 1 | DO8: 1 | DP8: 1 | DQ8: 1 | DR8: 1 | DS8: 1 | DT8: 1 | DU8: 1 | DV8: 1 | DW8: 1 | DX8: 1 | DY8: 1 | DZ8: 1 | EA8: 1 | EB8: 1 | EC8: 1 | ED8: 1 | EE8: 1 | EF8: 1 | EG8: 1 | EH8: 1 | EI8: 1 | EJ8: 1 | EK8: 1 | EL8: 1 | EM8: 1 | EN8: 1 | EO8: 1 | EP8: 1 | EQ8: 1 | ER8: 1 | ES8: 1 | ET8: 1 | EU8: 1 | EV8: 1 | EW8: 1 | EX8: 1 | EY8: 1 | EZ8: 1 | FA8: 1 | FB8: 1 | FC8: 1 | FD8: 1 | FE8: 1 | FF8: 1 | FG8: 1 | FH8: 1 | FI8: 1 | FJ8: 1 | FK8: 1 | FL8: 1 | FM8: 1 | FN8: 1 | FO8: 1 | FP8: 1 | FQ8: 1 | FR8: 1 | FS8: 1 | FT8: 1 | FU8: 1 | FV8: 1 | FW8: 1 | FX8: 1 | FY8: 1 | FZ8: 1 | GA8: 1 | GB8: 1 | GC8: 1 | GD8: 1 | GE8: 1 | GF8: 1 | GG8: 1 | GH8: 1 | GI8: 1 | GJ8: 1 | GK8: 1 | GL8: 1 | GM8: 1 | GN8: 1 | GO8: 1 | GP8: 1 | GQ8: 1 | GR8: 1 | GS8: 1 | GT8: 1 | GU8: 1 | GV8: 1 | GW8: 1 | GX8: 1 | GY8: 1 | GZ8: 1 | HA8: 1 | HB8: 1 | HC8: 1 | HD8: 1 | HE8: 1 | HF8: 1 | HG8: 1 | HH8: 1 | HI8: 1 | HJ8: 1 | HK8: 1 | HL8: 1 | HM8: 1 | HN8: 1 | HO8: 1 | HP8: 1 | HQ8: 1 | HR8: 1 | HS8: 1 | HT8: 1 | HU8: 1 | HV8: 1 | HW8: 1 | HX8: 0 | HY8: 0 | HZ8: 0 | IA8: 0 | IB8: 0 | IC8: 0 | ID8: 0 | IE8: 0 | IF8: 0 | IG8: 0 | IH8: 0 | II8: 0 | IJ8: 0 | IK8: 0 | IL8: 0 | IM8: 0 | IN8: 0 | IO8: 0 | IP8: 0 | IQ8: 0 | IR8: 0 | IS8: 0 | IT8: 0 | IU8: 0 | IV8: 0 | IW8: 0 | IX8: 0 | IY8: 0 | IZ8: 0 | JA8: 0 | JB8: 0 | JC8: 0 | JD8: 0 | JE8: 0 | JF8: 0 | JG8: 0 | JH8: 0 | JI8: 0 | JJ8: 0 | JK8: 0 | JL8: 0 | JM8: 0 | JN8: 0 | JO8: 0 | JP8: 0 | JQ8: 0 | JR8: 0 | JS8: 0 | JT8: 0 | JU8: 0 | JV8: 0 | JW8: 0 | JX8: 0 | JY8: 0 | JZ8: 0 | KA8: 0 | KB8: 0 | KC8: 0 | KD8: 0 | KE8: 0 | KF8: 0 | KG8: 0 | KH8: 0 | KI8: 0 | KJ8: 0 | KK8: 0 | KL8: 0 | KM8: 0 | KN8: 0 | KO8: 0 | KP8: 0 | KQ8: 0 | KR8: 0 | KS8: 0 | KT8: 0 | KU8: 0 | KV8: 0 | KW8: 0 | KX8: 0 | KY8: 0 | KZ8: 0 | LA8: 0 | LB8: 0 | LC8: 0
B9: Flag de cobro (cierre de trimestre) | D9: 0 | E9: 0 | F9: 0 | G9: 0 | H9: 0 | I9: 0 | J9: 0 | K9: 0 | L9: 0 | M9: 0 | N9: 0 | O9: 0 | P9: 0 | Q9: 0 | R9: 0 | S9: 0 | T9: 0 | U9: 0 | V9: 0 | W9: 0 | X9: 0 | Y9: 0 | Z9: 0 | AA9: 0 | AB9: 0 | AC9: 0 | AD9: 0 | AE9: 0 | AF9: 0 | AG9: 0 | AH9: 0 | AI9: 0 | AJ9: 0 | AK9: 0 | AL9: 0 | AM9: 0 | AN9: 0 | AO9: 0 | AP9: 0 | AQ9: 0 | AR9: 0 | AS9: 0 | AT9: 0 | AU9: 0 | AV9: 0 | AW9: 0 | AX9: 0 | AY9: 0 | AZ9: 0 | BA9: 0 | BB9: 1 | BC9: 0 | BD9: 0 | BE9: 1 | BF9: 0 | BG9: 0 | BH9: 1 | BI9: 0 | BJ9: 0 | BK9: 1 | BL9: 0 | BM9: 0 | BN9: 1 | BO9: 0 | BP9: 0 | BQ9: 1 | BR9: 0 | BS9: 0 | BT9: 1 | BU9: 0 | BV9: 0 | BW9: 1 | BX9: 0 | BY9: 0 | BZ9: 1 | CA9: 0 | CB9: 0 | CC9: 1 | CD9: 0 | CE9: 0 | CF9: 1 | CG9: 0 | CH9: 0 | CI9: 1 | CJ9: 0 | CK9: 0 | CL9: 1 | CM9: 0 | CN9: 0 | CO9: 1 | CP9: 0 | CQ9: 0 | CR9: 1 | CS9: 0 | CT9: 0 | CU9: 1 | CV9: 0 | CW9: 0 | CX9: 1 | CY9: 0 | CZ9: 0 | DA9: 1 | DB9: 0 | DC9: 0 | DD9: 1 | DE9: 0 | DF9: 0 | DG9: 1 | DH9: 0 | DI9: 0 | DJ9: 1 | DK9: 0 | DL9: 0 | DM9: 1 | DN9: 0 | DO9: 0 | DP9: 1 | DQ9: 0 | DR9: 0 | DS9: 1 | DT9: 0 | DU9: 0 | DV9: 1 | DW9: 0 | DX9: 0 | DY9: 1 | DZ9: 0 | EA9: 0 | EB9: 1 | EC9: 0 | ED9: 0 | EE9: 1 | EF9: 0 | EG9: 0 | EH9: 1 | EI9: 0 | EJ9: 0 | EK9: 1 | EL9: 0 | EM9: 0 | EN9: 1 | EO9: 0 | EP9: 0 | EQ9: 1 | ER9: 0 | ES9: 0 | ET9: 1 | EU9: 0 | EV9: 0 | EW9: 1 | EX9: 0 | EY9: 0 | EZ9: 1 | FA9: 0 | FB9: 0 | FC9: 1 | FD9: 0 | FE9: 0 | FF9: 1 | FG9: 0 | FH9: 0 | FI9: 1 | FJ9: 0 | FK9: 0 | FL9: 1 | FM9: 0 | FN9: 0 | FO9: 1 | FP9: 0 | FQ9: 0 | FR9: 1 | FS9: 0 | FT9: 0 | FU9: 1 | FV9: 0 | FW9: 0 | FX9: 1 | FY9: 0 | FZ9: 0 | GA9: 1 | GB9: 0 | GC9: 0 | GD9: 1 | GE9: 0 | GF9: 0 | GG9: 1 | GH9: 0 | GI9: 0 | GJ9: 1 | GK9: 0 | GL9: 0 | GM9: 1 | GN9: 0 | GO9: 0 | GP9: 1 | GQ9: 0 | GR9: 0 | GS9: 1 | GT9: 0 | GU9: 0 | GV9: 1 | GW9: 0 | GX9: 0 | GY9: 1 | GZ9: 0 | HA9: 0 | HB9: 1 | HC9: 0 | HD9: 0 | HE9: 1 | HF9: 0 | HG9: 0 | HH9: 1 | HI9: 0 | HJ9: 0 | HK9: 1 | HL9: 0 | HM9: 0 | HN9: 1 | HO9: 0 | HP9: 0 | HQ9: 1 | HR9: 0 | HS9: 0 | HT9: 1 | HU9: 0 | HV9: 0 | HW9: 1 | HX9: 0 | HY9: 0 | HZ9: 0 | IA9: 0 | IB9: 0 | IC9: 0 | ID9: 0 | IE9: 0 | IF9: 0 | IG9: 0 | IH9: 0 | II9: 0 | IJ9: 0 | IK9: 0 | IL9: 0 | IM9: 0 | IN9: 0 | IO9: 0 | IP9: 0 | IQ9: 0 | IR9: 0 | IS9: 0 | IT9: 0 | IU9: 0 | IV9: 0 | IW9: 0 | IX9: 0 | IY9: 0 | IZ9: 0 | JA9: 0 | JB9: 0 | JC9: 0 | JD9: 0 | JE9: 0 | JF9: 0 | JG9: 0 | JH9: 0 | JI9: 0 | JJ9: 0 | JK9: 0 | JL9: 0 | JM9: 0 | JN9: 0 | JO9: 0 | JP9: 0 | JQ9: 0 | JR9: 0 | JS9: 0 | JT9: 0 | JU9: 0 | JV9: 0 | JW9: 0 | JX9: 0 | JY9: 0 | JZ9: 0 | KA9: 0 | KB9: 0 | KC9: 0 | KD9: 0 | KE9: 0 | KF9: 0 | KG9: 0 | KH9: 0 | KI9: 0 | KJ9: 0 | KK9: 0 | KL9: 0 | KM9: 0 | KN9: 0 | KO9: 0 | KP9: 0 | KQ9: 0 | KR9: 0 | KS9: 0 | KT9: 0 | KU9: 0 | KV9: 0 | KW9: 0 | KX9: 0 | KY9: 0 | KZ9: 0 | LA9: 0 | LB9: 0 | LC9: 0
B10: PPDI devengado | D10: =D8*p_ppdi_anual/12 | E10: =E8*p_ppdi_anual/12 | F10: =F8*p_ppdi_anual/12 | G10: =G8*p_ppdi_anual/12 | H10: =H8*p_ppdi_anual/12 | I10: =I8*p_ppdi_anual/12 | J10: =J8*p_ppdi_anual/12 | K10: =K8*p_ppdi_anual/12 | ... LC10: =LC8*p_ppdi_anual/12
B11: PPDI cobrado | D11: =IF(D9=1,0+D10,0) | E11: =IF(E9=1,D12+E10,0) | F11: =IF(F9=1,E12+F10,0) | G11: =IF(G9=1,F12+G10,0) | H11: =IF(H9=1,G12+H10,0) | I11: =IF(I9=1,H12+I10,0) | J11: =IF(J9=1,I12+J10,0) | K11: =IF(K9=1,J12+K10,0) | L11: =IF(L9=1,K12+L10,0) | ... LC11: =IF(LC9=1,LB12+LC10,0)
B12: Devengado pendiente de cobro | D12: =0+D10-D11 | E12: =D12+E10-E11 | F12: =E12+F10-F11 | G12: =F12+G10-G11 | H12: =G12+H10-H11 | I12: =H12+I10-I11 | J12: =I12+J10-J11 | K12: =J12+K10-K11 | L12: =K12+L10-L11 | ... LC12: =LB12+LC10-LC11
B13: Saldo inicial del activo | D13: 0 | E13: =D17 | F13: =E17 | G13: =F17 | H13: =G17 | I13: =H17 | J13: =I17 | K13: =J17 | L13: =K17 | ... LC13: =LB17
B14: Servicio de construccion del periodo | D14: 9871.0611 | E14: 1436.3191 | F14: 1438.6913 | G14: 1441.0674 | H14: 1443.4474 | I14: 1445.8314 | J14: 1456.5526 | K14: 1458.9445 | L14: 1461.3403 | M14: 1381.0649 | N14: 1383.3321 | O14: 1385.603 | P14: 49.876039 | Q14: 49.94465 | R14: 50.013374 | S14: 133.57997 | T14: 8.3333333 | U14: 8.3333333 | V14: 8.3333333 | W14: 8.3333333 | X14: 8.3333333 | Y14: 47218.558 | Z14: 6404.7806 | AA14: 6410.9541 | AB14: 6417.1378 | AC14: 6423.3317 | AD14: 6429.5359 | AE14: 15912.374 | AF14: 15927.957 | AG14: 15943.566 | AH14: 15959.2 | AI14: 15722.754 | AJ14: 15702.765 | AK14: 13733.555 | AL14: 13722.708 | AM14: 13134.641 | AN14: 13147.561 | AO14: 14866.677 | AP14: 14845.547 | AQ14: 2463.9882 | AR14: 2466.4073 | AS14: 1610.093 | AT14: 1611.6721 | AU14: 197.81015 | AV14: 197.99664 | AW14: 198.18343 | AX14: 198.37054 | AY14: 198.55795 | AZ14: 0 | BA14: 0 | BB14: 0 | BC14: 0 | BD14: 0 | BE14: 0 | BF14: 0 | BG14: 0 | BH14: 0 | BI14: 0 | BJ14: 0 | BK14: 0 | BL14: 0 | BM14: 0 | BN14: 0 | BO14: 0 | BP14: 0 | BQ14: 0 | BR14: 0 | BS14: 0 | BT14: 0 | BU14: 0 | BV14: 0 | BW14: 0 | BX14: 0 | BY14: 0 | BZ14: 0 | CA14: 0 | CB14: 0 | CC14: 0 | CD14: 0 | CE14: 0 | CF14: 0 | CG14: 0 | CH14: 0 | CI14: 0 | CJ14: 0 | CK14: 0 | CL14: 0 | CM14: 0 | CN14: 0 | CO14: 0 | CP14: 0 | CQ14: 0 | CR14: 0 | CS14: 0 | CT14: 0 | CU14: 0 | CV14: 0 | CW14: 0 | CX14: 0 | CY14: 0 | CZ14: 0 | DA14: 0 | DB14: 0 | DC14: 0 | DD14: 0 | DE14: 0 | DF14: 0 | DG14: 0 | DH14: 0 | DI14: 0 | DJ14: 0 | DK14: 0 | DL14: 0 | DM14: 0 | DN14: 0 | DO14: 0 | DP14: 0 | DQ14: 0 | DR14: 0 | DS14: 0 | DT14: 0 | DU14: 0 | DV14: 0 | DW14: 0 | DX14: 0 | DY14: 0 | DZ14: 0 | EA14: 0 | EB14: 0 | EC14: 0 | ED14: 0 | EE14: 0 | EF14: 0 | EG14: 0 | EH14: 0 | EI14: 0 | EJ14: 0 | EK14: 0 | EL14: 0 | EM14: 0 | EN14: 0 | EO14: 0 | EP14: 0 | EQ14: 0 | ER14: 0 | ES14: 0 | ET14: 0 | EU14: 0 | EV14: 0 | EW14: 0 | EX14: 0 | EY14: 0 | EZ14: 0 | FA14: 0 | FB14: 0 | FC14: 0 | FD14: 0 | FE14: 0 | FF14: 0 | FG14: 0 | FH14: 0 | FI14: 0 | FJ14: 0 | FK14: 0 | FL14: 0 | FM14: 0 | FN14: 0 | FO14: 0 | FP14: 0 | FQ14: 0 | FR14: 0 | FS14: 0 | FT14: 0 | FU14: 0 | FV14: 0 | FW14: 0 | FX14: 0 | FY14: 0 | FZ14: 0 | GA14: 0 | GB14: 0 | GC14: 0 | GD14: 0 | GE14: 0 | GF14: 0 | GG14: 0 | GH14: 0 | GI14: 0 | GJ14: 0 | GK14: 0 | GL14: 0 | GM14: 0 | GN14: 0 | GO14: 0 | GP14: 0 | GQ14: 0 | GR14: 0 | GS14: 0 | GT14: 0 | GU14: 0 | GV14: 0 | GW14: 0 | GX14: 0 | GY14: 0 | GZ14: 0 | HA14: 0 | HB14: 0 | HC14: 0 | HD14: 0 | HE14: 0 | HF14: 0 | HG14: 0 | HH14: 0 | HI14: 0 | HJ14: 0 | HK14: 0 | HL14: 0 | HM14: 0 | HN14: 0 | HO14: 0 | HP14: 0 | HQ14: 0 | HR14: 0 | HS14: 0 | HT14: 0 | HU14: 0 | HV14: 0 | HW14: 0 | HX14: 0 | HY14: 0 | HZ14: 0 | IA14: 0 | IB14: 0 | IC14: 0 | ID14: 0 | IE14: 0 | IF14: 0 | IG14: 0 | IH14: 0 | II14: 0 | IJ14: 0 | IK14: 0 | IL14: 0 | IM14: 0 | IN14: 0 | IO14: 0 | IP14: 0 | IQ14: 0 | IR14: 0 | IS14: 0 | IT14: 0 | IU14: 0 | IV14: 0 | IW14: 0 | IX14: 0 | IY14: 0 | IZ14: 0 | JA14: 0 | JB14: 0 | JC14: 0 | JD14: 0 | JE14: 0 | JF14: 0 | JG14: 0 | JH14: 0 | JI14: 0 | JJ14: 0 | JK14: 0 | JL14: 0 | JM14: 0 | JN14: 0 | JO14: 0 | JP14: 0 | JQ14: 0 | JR14: 0 | JS14: 0 | JT14: 0 | JU14: 0 | JV14: 0 | JW14: 0 | JX14: 0 | JY14: 0 | JZ14: 0 | KA14: 0 | KB14: 0 | KC14: 0 | KD14: 0 | KE14: 0 | KF14: 0 | KG14: 0 | KH14: 0 | KI14: 0 | KJ14: 0 | KK14: 0 | KL14: 0 | KM14: 0 | KN14: 0 | KO14: 0 | KP14: 0 | KQ14: 0 | KR14: 0 | KS14: 0 | KT14: 0 | KU14: 0 | KV14: 0 | KW14: 0 | KX14: 0 | KY14: 0 | KZ14: 0 | LA14: 0 | LB14: 0 | LC14: 0
B15: Ingreso financiero devengado | D15: =D13*$D$7 | E15: =E13*$D$7 | F15: =F13*$D$7 | G15: =G13*$D$7 | H15: =H13*$D$7 | I15: =I13*$D$7 | J15: =J13*$D$7 | K15: =K13*$D$7 | ... LC15: =LC13*$D$7
B16: Amortizacion del activo (cobro - ingreso financiero) | D16: =D11-D15 | E16: =E11-E15 | F16: =F11-F15 | G16: =G11-G15 | H16: =H11-H15 | I16: =I11-I15 | J16: =J11-J15 | K16: =K11-K15 | ... LC16: =LC11-LC15
B17: Saldo final del activo | D17: =D13+D14+D15-D11 | E17: =E13+E14+E15-E11 | F17: =F13+F14+F15-F11 | G17: =G13+G14+G15-G11 | H17: =H13+H14+H15-H11 | I17: =I13+I14+I15-I11 | J17: =J13+J14+J15-J11 | K17: =K13+K14+K15-K11 | ... LC17: =LC13+LC14+LC15-LC11
B19: Saldo maximo del activo | D19: =MAX($D$17:$LC$17)
B20: Amortizacion acumulada | D20: =SUM($D$16:$LC$16)
B21: Saldo final, debe ser cero | D21: =$LC$17
B22: Meses con amortizacion negativa (el activo crece) | D22: =COUNTIF($D$16:$LC$16,"<0")

Sheet PPDMO
B2: PPD de operacion y mantenimiento
B3: Ingresos reajustados por IPM con gatillo; la pata fija es costo mas margen.
B6: Mes | D6: 2026-10-31 | E6: 2026-11-30 | F6: 2026-12-31 | G6: 2027-01-31 | H6: 2027-02-28 | I6: 2027-03-31 | J6: 2027-04-30 | K6: 2027-05-31 | L6: 2027-06-30 | M6: 2027-07-31 | N6: 2027-08-31 | O6: 2027-09-30 | P6: 2027-10-31 | Q6: 2027-11-30 | R6: 2027-12-31 | S6: 2028-01-31 | T6: 2028-02-29 | U6: 2028-03-31 | V6: 2028-04-30 | W6: 2028-05-31 | X6: 2028-06-30 | Y6: 2028-07-31 | Z6: 2028-08-31 | AA6: 2028-09-30 | AB6: 2028-10-31 | AC6: 2028-11-30 | AD6: 2028-12-31 | AE6: 2029-01-31 | AF6: 2029-02-28 | AG6: 2029-03-31 | AH6: 2029-04-30 | AI6: 2029-05-31 | AJ6: 2029-06-30 | AK6: 2029-07-31 | AL6: 2029-08-31 | AM6: 2029-09-30 | AN6: 2029-10-31 | AO6: 2029-11-30 | AP6: 2029-12-31 | AQ6: 2030-01-31 | AR6: 2030-02-28 | AS6: 2030-03-31 | AT6: 2030-04-30 | AU6: 2030-05-31 | AV6: 2030-06-30 | AW6: 2030-07-31 | AX6: 2030-08-31 | AY6: 2030-09-30 | AZ6: 2030-10-31 | BA6: 2030-11-30 | BB6: 2030-12-31 | BC6: 2031-01-31 | BD6: 2031-02-28 | BE6: 2031-03-31 | BF6: 2031-04-30 | BG6: 2031-05-31 | BH6: 2031-06-30 | BI6: 2031-07-31 | BJ6: 2031-08-31 | BK6: 2031-09-30 | BL6: 2031-10-31 | BM6: 2031-11-30 | BN6: 2031-12-31 | BO6: 2032-01-31 | BP6: 2032-02-29 | BQ6: 2032-03-31 | BR6: 2032-04-30 | BS6: 2032-05-31 | BT6: 2032-06-30 | BU6: 2032-07-31 | BV6: 2032-08-31 | BW6: 2032-09-30 | BX6: 2032-10-31 | BY6: 2032-11-30 | BZ6: 2032-12-31 | CA6: 2033-01-31 | CB6: 2033-02-28 | CC6: 2033-03-31 | CD6: 2033-04-30 | CE6: 2033-05-31 | CF6: 2033-06-30 | CG6: 2033-07-31 | CH6: 2033-08-31 | CI6: 2033-09-30 | CJ6: 2033-10-31 | CK6: 2033-11-30 | CL6: 2033-12-31 | CM6: 2034-01-31 | CN6: 2034-02-28 | CO6: 2034-03-31 | CP6: 2034-04-30 | CQ6: 2034-05-31 | CR6: 2034-06-30 | CS6: 2034-07-31 | CT6: 2034-08-31 | CU6: 2034-09-30 | CV6: 2034-10-31 | CW6: 2034-11-30 | CX6: 2034-12-31 | CY6: 2035-01-31 | CZ6: 2035-02-28 | DA6: 2035-03-31 | DB6: 2035-04-30 | DC6: 2035-05-31 | DD6: 2035-06-30 | DE6: 2035-07-31 | DF6: 2035-08-31 | DG6: 2035-09-30 | DH6: 2035-10-31 | DI6: 2035-11-30 | DJ6: 2035-12-31 | DK6: 2036-01-31 | DL6: 2036-02-29 | DM6: 2036-03-31 | DN6: 2036-04-30 | DO6: 2036-05-31 | DP6: 2036-06-30 | DQ6: 2036-07-31 | DR6: 2036-08-31 | DS6: 2036-09-30 | DT6: 2036-10-31 | DU6: 2036-11-30 | DV6: 2036-12-31 | DW6: 2037-01-31 | DX6: 2037-02-28 | DY6: 2037-03-31 | DZ6: 2037-04-30 | EA6: 2037-05-31 | EB6: 2037-06-30 | EC6: 2037-07-31 | ED6: 2037-08-31 | EE6: 2037-09-30 | EF6: 2037-10-31 | EG6: 2037-11-30 | EH6: 2037-12-31 | EI6: 2038-01-31 | EJ6: 2038-02-28 | EK6: 2038-03-31 | EL6: 2038-04-30 | EM6: 2038-05-31 | EN6: 2038-06-30 | EO6: 2038-07-31 | EP6: 2038-08-31 | EQ6: 2038-09-30 | ER6: 2038-10-31 | ES6: 2038-11-30 | ET6: 2038-12-31 | EU6: 2039-01-31 | EV6: 2039-02-28 | EW6: 2039-03-31 | EX6: 2039-04-30 | EY6: 2039-05-31 | EZ6: 2039-06-30 | FA6: 2039-07-31 | FB6: 2039-08-31 | FC6: 2039-09-30 | FD6: 2039-10-31 | FE6: 2039-11-30 | FF6: 2039-12-31 | FG6: 2040-01-31 | FH6: 2040-02-29 | FI6: 2040-03-31 | FJ6: 2040-04-30 | FK6: 2040-05-31 | FL6: 2040-06-30 | FM6: 2040-07-31 | FN6: 2040-08-31 | FO6: 2040-09-30 | FP6: 2040-10-31 | FQ6: 2040-11-30 | FR6: 2040-12-31 | FS6: 2041-01-31 | FT6: 2041-02-28 | FU6: 2041-03-31 | FV6: 2041-04-30 | FW6: 2041-05-31 | FX6: 2041-06-30 | FY6: 2041-07-31 | FZ6: 2041-08-31 | GA6: 2041-09-30 | GB6: 2041-10-31 | GC6: 2041-11-30 | GD6: 2041-12-31 | GE6: 2042-01-31 | GF6: 2042-02-28 | GG6: 2042-03-31 | GH6: 2042-04-30 | GI6: 2042-05-31 | GJ6: 2042-06-30 | GK6: 2042-07-31 | GL6: 2042-08-31 | GM6: 2042-09-30 | GN6: 2042-10-31 | GO6: 2042-11-30 | GP6: 2042-12-31 | GQ6: 2043-01-31 | GR6: 2043-02-28 | GS6: 2043-03-31 | GT6: 2043-04-30 | GU6: 2043-05-31 | GV6: 2043-06-30 | GW6: 2043-07-31 | GX6: 2043-08-31 | GY6: 2043-09-30 | GZ6: 2043-10-31 | HA6: 2043-11-30 | HB6: 2043-12-31 | HC6: 2044-01-31 | HD6: 2044-02-29 | HE6: 2044-03-31 | HF6: 2044-04-30 | HG6: 2044-05-31 | HH6: 2044-06-30 | HI6: 2044-07-31 | HJ6: 2044-08-31 | HK6: 2044-09-30 | HL6: 2044-10-31 | HM6: 2044-11-30 | HN6: 2044-12-31 | HO6: 2045-01-31 | HP6: 2045-02-28 | HQ6: 2045-03-31 | HR6: 2045-04-30 | HS6: 2045-05-31 | HT6: 2045-06-30 | HU6: 2045-07-31 | HV6: 2045-08-31 | HW6: 2045-09-30 | HX6: 2045-10-31 | HY6: 2045-11-30 | HZ6: 2045-12-31 | IA6: 2046-01-31 | IB6: 2046-02-28 | IC6: 2046-03-31 | ID6: 2046-04-30 | IE6: 2046-05-31 | IF6: 2046-06-30 | IG6: 2046-07-31 | IH6: 2046-08-31 | II6: 2046-09-30 | IJ6: 2046-10-31 | IK6: 2046-11-30 | IL6: 2046-12-31 | IM6: 2047-01-31 | IN6: 2047-02-28 | IO6: 2047-03-31 | IP6: 2047-04-30 | IQ6: 2047-05-31 | IR6: 2047-06-30 | IS6: 2047-07-31 | IT6: 2047-08-31 | IU6: 2047-09-30 | IV6: 2047-10-31 | IW6: 2047-11-30 | IX6: 2047-12-31 | IY6: 2048-01-31 | IZ6: 2048-02-29 | JA6: 2048-03-31 | JB6: 2048-04-30 | JC6: 2048-05-31 | JD6: 2048-06-30 | JE6: 2048-07-31 | JF6: 2048-08-31 | JG6: 2048-09-30 | JH6: 2048-10-31 | JI6: 2048-11-30 | JJ6: 2048-12-31 | JK6: 2049-01-31 | JL6: 2049-02-28 | JM6: 2049-03-31 | JN6: 2049-04-30 | JO6: 2049-05-31 | JP6: 2049-06-30 | JQ6: 2049-07-31 | JR6: 2049-08-31 | JS6: 2049-09-30 | JT6: 2049-10-31 | JU6: 2049-11-30 | JV6: 2049-12-31 | JW6: 2050-01-31 | JX6: 2050-02-28 | JY6: 2050-03-31 | JZ6: 2050-04-30 | KA6: 2050-05-31 | KB6: 2050-06-30 | KC6: 2050-07-31 | KD6: 2050-08-31 | KE6: 2050-09-30 | KF6: 2050-10-31 | KG6: 2050-11-30 | KH6: 2050-12-31 | KI6: 2051-01-31 | KJ6: 2051-02-28 | KK6: 2051-03-31 | KL6: 2051-04-30 | KM6: 2051-05-31 | KN6: 2051-06-30 | KO6: 2051-07-31 | KP6: 2051-08-31 | KQ6: 2051-09-30 | KR6: 2051-10-31 | KS6: 2051-11-30 | KT6: 2051-12-31 | KU6: 2052-01-31 | KV6: 2052-02-29 | KW6: 2052-03-31 | KX6: 2052-04-30 | KY6: 2052-05-31 | KZ6: 2052-06-30 | LA6: 2052-07-31 | LB6: 2052-08-31 | LC6: 2052-09-30 | LD6: 2052-10-31 | LE6: 2052-11-30 | LF6: 2052-12-31 | LG6: 2053-01-31 | LH6: 2053-02-28 | LI6: 2053-03-31
B7: Flag de operacion | D7: 0 | E7: 0 | F7: 0 | G7: 0 | H7: 0 | I7: 0 | J7: 0 | K7: 0 | L7: 0 | M7: 0 | N7: 0 | O7: 0 | P7: 0 | Q7: 0 | R7: 0 | S7: 0 | T7: 0 | U7: 0 | V7: 0 | W7: 0 | X7: 0 | Y7: 0 | Z7: 0 | AA7: 0 | AB7: 0 | AC7: 0 | AD7: 0 | AE7: 0 | AF7: 0 | AG7: 0 | AH7: 0 | AI7: 0 | AJ7: 0 | AK7: 0 | AL7: 0 | AM7: 0 | AN7: 0 | AO7: 0 | AP7: 0 | AQ7: 0 | AR7: 0 | AS7: 0 | AT7: 0 | AU7: 0 | AV7: 0 | AW7: 0 | AX7: 0 | AY7: 0 | AZ7: 1 | BA7: 1 | BB7: 1 | BC7: 1 | BD7: 1 | BE7: 1 | BF7: 1 | BG7: 1 | BH7: 1 | BI7: 1 | BJ7: 1 | BK7: 1 | BL7: 1 | BM7: 1 | BN7: 1 | BO7: 1 | BP7: 1 | BQ7: 1 | BR7: 1 | BS7: 1 | BT7: 1 | BU7: 1 | BV7: 1 | BW7: 1 | BX7: 1 | BY7: 1 | BZ7: 1 | CA7: 1 | CB7: 1 | CC7: 1 | CD7: 1 | CE7: 1 | CF7: 1 | CG7: 1 | CH7: 1 | CI7: 1 | CJ7: 1 | CK7: 1 | CL7: 1 | CM7: 1 | CN7: 1 | CO7: 1 | CP7: 1 | CQ7: 1 | CR7: 1 | CS7: 1 | CT7: 1 | CU7: 1 | CV7: 1 | CW7: 1 | CX7: 1 | CY7: 1 | CZ7: 1 | DA7: 1 | DB7: 1 | DC7: 1 | DD7: 1 | DE7: 1 | DF7: 1 | DG7: 1 | DH7: 1 | DI7: 1 | DJ7: 1 | DK7: 1 | DL7: 1 | DM7: 1 | DN7: 1 | DO7: 1 | DP7: 1 | DQ7: 1 | DR7: 1 | DS7: 1 | DT7: 1 | DU7: 1 | DV7: 1 | DW7: 1 | DX7: 1 | DY7: 1 | DZ7: 1 | EA7: 1 | EB7: 1 | EC7: 1 | ED7: 1 | EE7: 1 | EF7: 1 | EG7: 1 | EH7: 1 | EI7: 1 | EJ7: 1 | EK7: 1 | EL7: 1 | EM7: 1 | EN7: 1 | EO7: 1 | EP7: 1 | EQ7: 1 | ER7: 1 | ES7: 1 | ET7: 1 | EU7: 1 | EV7: 1 | EW7: 1 | EX7: 1 | EY7: 1 | EZ7: 1 | FA7: 1 | FB7: 1 | FC7: 1 | FD7: 1 | FE7: 1 | FF7: 1 | FG7: 1 | FH7: 1 | FI7: 1 | FJ7: 1 | FK7: 1 | FL7: 1 | FM7: 1 | FN7: 1 | FO7: 1 | FP7: 1 | FQ7: 1 | FR7: 1 | FS7: 1 | FT7: 1 | FU7: 1 | FV7: 1 | FW7: 1 | FX7: 1 | FY7: 1 | FZ7: 1 | GA7: 1 | GB7: 1 | GC7: 1 | GD7: 1 | GE7: 1 | GF7: 1 | GG7: 1 | GH7: 1 | GI7: 1 | GJ7: 1 | GK7: 1 | GL7: 1 | GM7: 1 | GN7: 1 | GO7: 1 | GP7: 1 | GQ7: 1 | GR7: 1 | GS7: 1 | GT7: 1 | GU7: 1 | GV7: 1 | GW7: 1 | GX7: 1 | GY7: 1 | GZ7: 1 | HA7: 1 | HB7: 1 | HC7: 1 | HD7: 1 | HE7: 1 | HF7: 1 | HG7: 1 | HH7: 1 | HI7: 1 | HJ7: 1 | HK7: 1 | HL7: 1 | HM7: 1 | HN7: 1 | HO7: 1 | HP7: 1 | HQ7: 1 | HR7: 1 | HS7: 1 | HT7: 1 | HU7: 1 | HV7: 1 | HW7: 1 | HX7: 1 | HY7: 1 | HZ7: 1 | IA7: 1 | IB7: 1 | IC7: 1 | ID7: 1 | IE7: 1 | IF7: 1 | IG7: 1 | IH7: 1 | II7: 1 | IJ7: 1 | IK7: 1 | IL7: 1 | IM7: 1 | IN7: 1 | IO7: 1 | IP7: 1 | IQ7: 1 | IR7: 1 | IS7: 1 | IT7: 1 | IU7: 1 | IV7: 1 | IW7: 1 | IX7: 1 | IY7: 1 | IZ7: 1 | JA7: 1 | JB7: 1 | JC7: 1 | JD7: 1 | JE7: 1 | JF7: 1 | JG7: 1 | JH7: 1 | JI7: 1 | JJ7: 1 | JK7: 1 | JL7: 1 | JM7: 1 | JN7: 1 | JO7: 1 | JP7: 1 | JQ7: 1 | JR7: 1 | JS7: 1 | JT7: 1 | JU7: 1 | JV7: 1 | JW7: 1 | JX7: 1 | JY7: 1 | JZ7: 1 | KA7: 1 | KB7: 1 | KC7: 1 | KD7: 1 | KE7: 1 | KF7: 1 | KG7: 1 | KH7: 1 | KI7: 1 | KJ7: 1 | KK7: 1 | KL7: 1 | KM7: 1 | KN7: 1 | KO7: 1 | KP7: 1 | KQ7: 1 | KR7: 1 | KS7: 1 | KT7: 1 | KU7: 1 | KV7: 1 | KW7: 1 | KX7: 1 | KY7: 1 | KZ7: 1 | LA7: 1 | LB7: 1 | LC7: 1 | LD7: 0 | LE7: 0 | LF7: 0 | LG7: 0 | LH7: 0 | LI7: 0
B8: Flag trimestral | D8: 0 | E8: 0 | F8: 0 | G8: 0 | H8: 0 | I8: 0 | J8: 0 | K8: 0 | L8: 0 | M8: 0 | N8: 0 | O8: 0 | P8: 0 | Q8: 0 | R8: 0 | S8: 0 | T8: 0 | U8: 0 | V8: 0 | W8: 0 | X8: 0 | Y8: 0 | Z8: 0 | AA8: 0 | AB8: 0 | AC8: 0 | AD8: 0 | AE8: 0 | AF8: 0 | AG8: 0 | AH8: 0 | AI8: 0 | AJ8: 0 | AK8: 0 | AL8: 0 | AM8: 0 | AN8: 0 | AO8: 0 | AP8: 0 | AQ8: 0 | AR8: 0 | AS8: 0 | AT8: 0 | AU8: 0 | AV8: 0 | AW8: 0 | AX8: 0 | AY8: 0 | AZ8: 0 | BA8: 0 | BB8: 1 | BC8: 0 | BD8: 0 | BE8: 1 | BF8: 0 | BG8: 0 | BH8: 1 | BI8: 0 | BJ8: 0 | BK8: 1 | BL8: 0 | BM8: 0 | BN8: 1 | BO8: 0 | BP8: 0 | BQ8: 1 | BR8: 0 | BS8: 0 | BT8: 1 | BU8: 0 | BV8: 0 | BW8: 1 | BX8: 0 | BY8: 0 | BZ8: 1 | CA8: 0 | CB8: 0 | CC8: 1 | CD8: 0 | CE8: 0 | CF8: 1 | CG8: 0 | CH8: 0 | CI8: 1 | CJ8: 0 | CK8: 0 | CL8: 1 | CM8: 0 | CN8: 0 | CO8: 1 | CP8: 0 | CQ8: 0 | CR8: 1 | CS8: 0 | CT8: 0 | CU8: 1 | CV8: 0 | CW8: 0 | CX8: 1 | CY8: 0 | CZ8: 0 | DA8: 1 | DB8: 0 | DC8: 0 | DD8: 1 | DE8: 0 | DF8: 0 | DG8: 1 | DH8: 0 | DI8: 0 | DJ8: 1 | DK8: 0 | DL8: 0 | DM8: 1 | DN8: 0 | DO8: 0 | DP8: 1 | DQ8: 0 | DR8: 0 | DS8: 1 | DT8: 0 | DU8: 0 | DV8: 1 | DW8: 0 | DX8: 0 | DY8: 1 | DZ8: 0 | EA8: 0 | EB8: 1 | EC8: 0 | ED8: 0 | EE8: 1 | EF8: 0 | EG8: 0 | EH8: 1 | EI8: 0 | EJ8: 0 | EK8: 1 | EL8: 0 | EM8: 0 | EN8: 1 | EO8: 0 | EP8: 0 | EQ8: 1 | ER8: 0 | ES8: 0 | ET8: 1 | EU8: 0 | EV8: 0 | EW8: 1 | EX8: 0 | EY8: 0 | EZ8: 1 | FA8: 0 | FB8: 0 | FC8: 1 | FD8: 0 | FE8: 0 | FF8: 1 | FG8: 0 | FH8: 0 | FI8: 1 | FJ8: 0 | FK8: 0 | FL8: 1 | FM8: 0 | FN8: 0 | FO8: 1 | FP8: 0 | FQ8: 0 | FR8: 1 | FS8: 0 | FT8: 0 | FU8: 1 | FV8: 0 | FW8: 0 | FX8: 1 | FY8: 0 | FZ8: 0 | GA8: 1 | GB8: 0 | GC8: 0 | GD8: 1 | GE8: 0 | GF8: 0 | GG8: 1 | GH8: 0 | GI8: 0 | GJ8: 1 | GK8: 0 | GL8: 0 | GM8: 1 | GN8: 0 | GO8: 0 | GP8: 1 | GQ8: 0 | GR8: 0 | GS8: 1 | GT8: 0 | GU8: 0 | GV8: 1 | GW8: 0 | GX8: 0 | GY8: 1 | GZ8: 0 | HA8: 0 | HB8: 1 | HC8: 0 | HD8: 0 | HE8: 1 | HF8: 0 | HG8: 0 | HH8: 1 | HI8: 0 | HJ8: 0 | HK8: 1 | HL8: 0 | HM8: 0 | HN8: 1 | HO8: 0 | HP8: 0 | HQ8: 1 | HR8: 0 | HS8: 0 | HT8: 1 | HU8: 0 | HV8: 0 | HW8: 1 | HX8: 0 | HY8: 0 | HZ8: 1 | IA8: 0 | IB8: 0 | IC8: 1 | ID8: 0 | IE8: 0 | IF8: 1 | IG8: 0 | IH8: 0 | II8: 1 | IJ8: 0 | IK8: 0 | IL8: 1 | IM8: 0 | IN8: 0 | IO8: 1 | IP8: 0 | IQ8: 0 | IR8: 1 | IS8: 0 | IT8: 0 | IU8: 1 | IV8: 0 | IW8: 0 | IX8: 1 | IY8: 0 | IZ8: 0 | JA8: 1 | JB8: 0 | JC8: 0 | JD8: 1 | JE8: 0 | JF8: 0 | JG8: 1 | JH8: 0 | JI8: 0 | JJ8: 1 | JK8: 0 | JL8: 0 | JM8: 1 | JN8: 0 | JO8: 0 | JP8: 1 | JQ8: 0 | JR8: 0 | JS8: 1 | JT8: 0 | JU8: 0 | JV8: 1 | JW8: 0 | JX8: 0 | JY8: 1 | JZ8: 0 | KA8: 0 | KB8: 1 | KC8: 0 | KD8: 0 | KE8: 1 | KF8: 0 | KG8: 0 | KH8: 1 | KI8: 0 | KJ8: 0 | KK8: 1 | KL8: 0 | KM8: 0 | KN8: 1 | KO8: 0 | KP8: 0 | KQ8: 1 | KR8: 0 | KS8: 0 | KT8: 1 | KU8: 0 | KV8: 0 | KW8: 1 | KX8: 0 | KY8: 0 | KZ8: 1 | LA8: 0 | LB8: 0 | LC8: 1 | LD8: 0 | LE8: 0 | LF8: 0 | LG8: 0 | LH8: 0 | LI8: 0
B9: Flag de pago del PPDMO | D9: 0 | E9: 0 | F9: 0 | G9: 0 | H9: 0 | I9: 0 | J9: 0 | K9: 0 | L9: 0 | M9: 0 | N9: 0 | O9: 0 | P9: 0 | Q9: 0 | R9: 0 | S9: 0 | T9: 0 | U9: 0 | V9: 0 | W9: 0 | X9: 0 | Y9: 0 | Z9: 0 | AA9: 0 | AB9: 0 | AC9: 0 | AD9: 0 | AE9: 0 | AF9: 0 | AG9: 0 | AH9: 0 | AI9: 0 | AJ9: 0 | AK9: 0 | AL9: 0 | AM9: 0 | AN9: 0 | AO9: 0 | AP9: 0 | AQ9: 0 | AR9: 0 | AS9: 0 | AT9: 0 | AU9: 0 | AV9: 0 | AW9: 0 | AX9: 0 | AY9: 0 | AZ9: 0 | BA9: 0 | BB9: 0 | BC9: 1 | BD9: 1 | BE9: 1 | BF9: 1 | BG9: 1 | BH9: 1 | BI9: 1 | BJ9: 1 | BK9: 1 | BL9: 1 | BM9: 1 | BN9: 1 | BO9: 1 | BP9: 1 | BQ9: 1 | BR9: 1 | BS9: 1 | BT9: 1 | BU9: 1 | BV9: 1 | BW9: 1 | BX9: 1 | BY9: 1 | BZ9: 1 | CA9: 1 | CB9: 1 | CC9: 1 | CD9: 1 | CE9: 1 | CF9: 1 | CG9: 1 | CH9: 1 | CI9: 1 | CJ9: 1 | CK9: 1 | CL9: 1 | CM9: 1 | CN9: 1 | CO9: 1 | CP9: 1 | CQ9: 1 | CR9: 1 | CS9: 1 | CT9: 1 | CU9: 1 | CV9: 1 | CW9: 1 | CX9: 1 | CY9: 1 | CZ9: 1 | DA9: 1 | DB9: 1 | DC9: 1 | DD9: 1 | DE9: 1 | DF9: 1 | DG9: 1 | DH9: 1 | DI9: 1 | DJ9: 1 | DK9: 1 | DL9: 1 | DM9: 1 | DN9: 1 | DO9: 1 | DP9: 1 | DQ9: 1 | DR9: 1 | DS9: 1 | DT9: 1 | DU9: 1 | DV9: 1 | DW9: 1 | DX9: 1 | DY9: 1 | DZ9: 1 | EA9: 1 | EB9: 1 | EC9: 1 | ED9: 1 | EE9: 1 | EF9: 1 | EG9: 1 | EH9: 1 | EI9: 1 | EJ9: 1 | EK9: 1 | EL9: 1 | EM9: 1 | EN9: 1 | EO9: 1 | EP9: 1 | EQ9: 1 | ER9: 1 | ES9: 1 | ET9: 1 | EU9: 1 | EV9: 1 | EW9: 1 | EX9: 1 | EY9: 1 | EZ9: 1 | FA9: 1 | FB9: 1 | FC9: 1 | FD9: 1 | FE9: 1 | FF9: 1 | FG9: 1 | FH9: 1 | FI9: 1 | FJ9: 1 | FK9: 1 | FL9: 1 | FM9: 1 | FN9: 1 | FO9: 1 | FP9: 1 | FQ9: 1 | FR9: 1 | FS9: 1 | FT9: 1 | FU9: 1 | FV9: 1 | FW9: 1 | FX9: 1 | FY9: 1 | FZ9: 1 | GA9: 1 | GB9: 1 | GC9: 1 | GD9: 1 | GE9: 1 | GF9: 1 | GG9: 1 | GH9: 1 | GI9: 1 | GJ9: 1 | GK9: 1 | GL9: 1 | GM9: 1 | GN9: 1 | GO9: 1 | GP9: 1 | GQ9: 1 | GR9: 1 | GS9: 1 | GT9: 1 | GU9: 1 | GV9: 1 | GW9: 1 | GX9: 1 | GY9: 1 | GZ9: 1 | HA9: 1 | HB9: 1 | HC9: 1 | HD9: 1 | HE9: 1 | HF9: 1 | HG9: 1 | HH9: 1 | HI9: 1 | HJ9: 1 | HK9: 1 | HL9: 1 | HM9: 1 | HN9: 1 | HO9: 1 | HP9: 1 | HQ9: 1 | HR9: 1 | HS9: 1 | HT9: 1 | HU9: 1 | HV9: 1 | HW9: 1 | HX9: 1 | HY9: 1 | HZ9: 1 | IA9: 1 | IB9: 1 | IC9: 1 | ID9: 1 | IE9: 1 | IF9: 1 | IG9: 1 | IH9: 1 | II9: 1 | IJ9: 1 | IK9: 1 | IL9: 1 | IM9: 1 | IN9: 1 | IO9: 1 | IP9: 1 | IQ9: 1 | IR9: 1 | IS9: 1 | IT9: 1 | IU9: 1 | IV9: 1 | IW9: 1 | IX9: 1 | IY9: 1 | IZ9: 1 | JA9: 1 | JB9: 1 | JC9: 1 | JD9: 1 | JE9: 1 | JF9: 1 | JG9: 1 | JH9: 1 | JI9: 1 | JJ9: 1 | JK9: 1 | JL9: 1 | JM9: 1 | JN9: 1 | JO9: 1 | JP9: 1 | JQ9: 1 | JR9: 1 | JS9: 1 | JT9: 1 | JU9: 1 | JV9: 1 | JW9: 1 | JX9: 1 | JY9: 1 | JZ9: 1 | KA9: 1 | KB9: 1 | KC9: 1 | KD9: 1 | KE9: 1 | KF9: 1 | KG9: 1 | KH9: 1 | KI9: 1 | KJ9: 1 | KK9: 1 | KL9: 1 | KM9: 1 | KN9: 1 | KO9: 1 | KP9: 1 | KQ9: 1 | KR9: 1 | KS9: 1 | KT9: 1 | KU9: 1 | KV9: 1 | KW9: 1 | KX9: 1 | KY9: 1 | KZ9: 1 | LA9: 1 | LB9: 1 | LC9: 1 | LD9: 1 | LE9: 1 | LF9: 1 | LG9: 0 | LH9: 0 | LI9: 0
B10: Produccion efectiva, kg DBO5 | D10: 0 | E10: 0 | F10: 0 | G10: 0 | H10: 0 | I10: 0 | J10: 0 | K10: 0 | L10: 0 | M10: 0 | N10: 0 | O10: 0 | P10: 0 | Q10: 0 | R10: 0 | S10: 0 | T10: 0 | U10: 0 | V10: 0 | W10: 0 | X10: 0 | Y10: 0 | Z10: 0 | AA10: 0 | AB10: 0 | AC10: 0 | AD10: 0 | AE10: 0 | AF10: 0 | AG10: 0 | AH10: 0 | AI10: 0 | AJ10: 0 | AK10: 0 | AL10: 0 | AM10: 0 | AN10: 0 | AO10: 0 | AP10: 0 | AQ10: 0 | AR10: 0 | AS10: 0 | AT10: 0 | AU10: 0 | AV10: 0 | AW10: 0 | AX10: 0 | AY10: 0 | AZ10: 558467.34 | BA10: 558467.34 | BB10: 558467.34 | BC10: 565769.15 | BD10: 565769.15 | BE10: 565769.15 | BF10: 565769.15 | BG10: 565769.15 | BH10: 565769.15 | BI10: 565769.15 | BJ10: 565769.15 | BK10: 565769.15 | BL10: 565769.15 | BM10: 565769.15 | BN10: 565769.15 | BO10: 571854 | BP10: 571854 | BQ10: 571854 | BR10: 571854 | BS10: 571854 | BT10: 571854 | BU10: 571854 | BV10: 571854 | BW10: 571854 | BX10: 571854 | BY10: 571854 | BZ10: 571854 | CA10: 576721.88 | CB10: 576721.88 | CC10: 576721.88 | CD10: 576721.88 | CE10: 576721.88 | CF10: 576721.88 | CG10: 576721.88 | CH10: 576721.88 | CI10: 576721.88 | CJ10: 576721.88 | CK10: 576721.88 | CL10: 576721.88 | CM10: 581589.76 | CN10: 581589.76 | CO10: 581589.76 | CP10: 581589.76 | CQ10: 581589.76 | CR10: 581589.76 | CS10: 581589.76 | CT10: 581589.76 | CU10: 581589.76 | CV10: 581589.76 | CW10: 581589.76 | CX10: 581589.76 | CY10: 586457.64 | CZ10: 586457.64 | DA10: 586457.64 | DB10: 586457.64 | DC10: 586457.64 | DD10: 586457.64 | DE10: 586457.64 | DF10: 586457.64 | DG10: 586457.64 | DH10: 586457.64 | DI10: 586457.64 | DJ10: 586457.64 | DK10: 591325.51 | DL10: 591325.51 | DM10: 591325.51 | DN10: 591325.51 | DO10: 591325.51 | DP10: 591325.51 | DQ10: 591325.51 | DR10: 591325.51 | DS10: 591325.51 | DT10: 591325.51 | DU10: 591325.51 | DV10: 591325.51 | DW10: 620532.78 | DX10: 620532.78 | DY10: 620532.78 | DZ10: 620532.78 | EA10: 620532.78 | EB10: 620532.78 | EC10: 620532.78 | ED10: 620532.78 | EE10: 620532.78 | EF10: 620532.78 | EG10: 620532.78 | EH10: 620532.78 | EI10: 626617.63 | EJ10: 626617.63 | EK10: 626617.63 | EL10: 626617.63 | EM10: 626617.63 | EN10: 626617.63 | EO10: 626617.63 | EP10: 626617.63 | EQ10: 626617.63 | ER10: 626617.63 | ES10: 626617.63 | ET10: 626617.63 | EU10: 632702.48 | EV10: 632702.48 | EW10: 632702.48 | EX10: 632702.48 | EY10: 632702.48 | EZ10: 632702.48 | FA10: 632702.48 | FB10: 632702.48 | FC10: 632702.48 | FD10: 632702.48 | FE10: 632702.48 | FF10: 632702.48 | FG10: 640004.3 | FH10: 640004.3 | FI10: 640004.3 | FJ10: 640004.3 | FK10: 640004.3 | FL10: 640004.3 | FM10: 640004.3 | FN10: 640004.3 | FO10: 640004.3 | FP10: 640004.3 | FQ10: 640004.3 | FR10: 640004.3 | FS10: 646089.14 | FT10: 646089.14 | FU10: 646089.14 | FV10: 646089.14 | FW10: 646089.14 | FX10: 646089.14 | FY10: 646089.14 | FZ10: 646089.14 | GA10: 646089.14 | GB10: 646089.14 | GC10: 646089.14 | GD10: 646089.14 | GE10: 653390.96 | GF10: 653390.96 | GG10: 653390.96 | GH10: 653390.96 | GI10: 653390.96 | GJ10: 653390.96 | GK10: 653390.96 | GL10: 653390.96 | GM10: 653390.96 | GN10: 653390.96 | GO10: 653390.96 | GP10: 653390.96 | GQ10: 659475.81 | GR10: 659475.81 | GS10: 659475.81 | GT10: 659475.81 | GU10: 659475.81 | GV10: 659475.81 | GW10: 659475.81 | GX10: 659475.81 | GY10: 659475.81 | GZ10: 659475.81 | HA10: 659475.81 | HB10: 659475.81 | HC10: 666777.63 | HD10: 666777.63 | HE10: 666777.63 | HF10: 666777.63 | HG10: 666777.63 | HH10: 666777.63 | HI10: 666777.63 | HJ10: 666777.63 | HK10: 666777.63 | HL10: 666777.63 | HM10: 666777.63 | HN10: 666777.63 | HO10: 674079.44 | HP10: 674079.44 | HQ10: 674079.44 | HR10: 674079.44 | HS10: 674079.44 | HT10: 674079.44 | HU10: 674079.44 | HV10: 674079.44 | HW10: 674079.44 | HX10: 674079.44 | HY10: 674079.44 | HZ10: 674079.44 | IA10: 681381.26 | IB10: 681381.26 | IC10: 681381.26 | ID10: 681381.26 | IE10: 681381.26 | IF10: 681381.26 | IG10: 681381.26 | IH10: 681381.26 | II10: 681381.26 | IJ10: 681381.26 | IK10: 681381.26 | IL10: 681381.26 | IM10: 688683.08 | IN10: 688683.08 | IO10: 688683.08 | IP10: 688683.08 | IQ10: 688683.08 | IR10: 688683.08 | IS10: 688683.08 | IT10: 688683.08 | IU10: 688683.08 | IV10: 688683.08 | IW10: 688683.08 | IX10: 688683.08 | IY10: 695984.9 | IZ10: 695984.9 | JA10: 695984.9 | JB10: 695984.9 | JC10: 695984.9 | JD10: 695984.9 | JE10: 695984.9 | JF10: 695984.9 | JG10: 695984.9 | JH10: 695984.9 | JI10: 695984.9 | JJ10: 695984.9 | JK10: 703286.71 | JL10: 703286.71 | JM10: 703286.71 | JN10: 703286.71 | JO10: 703286.71 | JP10: 703286.71 | JQ10: 703286.71 | JR10: 703286.71 | JS10: 703286.71 | JT10: 703286.71 | JU10: 703286.71 | JV10: 703286.71 | JW10: 711805.5 | JX10: 711805.5 | JY10: 711805.5 | JZ10: 711805.5 | KA10: 711805.5 | KB10: 711805.5 | KC10: 711805.5 | KD10: 711805.5 | KE10: 711805.5 | KF10: 711805.5 | KG10: 711805.5 | KH10: 711805.5 | KI10: 720324.29 | KJ10: 720324.29 | KK10: 720324.29 | KL10: 720324.29 | KM10: 720324.29 | KN10: 720324.29 | KO10: 720324.29 | KP10: 720324.29 | KQ10: 720324.29 | KR10: 720324.29 | KS10: 720324.29 | KT10: 720324.29 | KU10: 720324.29 | KV10: 720324.29 | KW10: 720324.29 | KX10: 720324.29 | KY10: 720324.29 | KZ10: 720324.29 | LA10: 720324.29 | LB10: 720324.29 | LC10: 720324.29 | LD10: 0 | LE10: 0 | LF10: 0 | LG10: 0 | LH10: 0 | LI10: 0
B11: IPM mensual | D11: =((1+p_ipm)^(1/12)-1)*D7 | E11: =((1+p_ipm)^(1/12)-1)*E7 | F11: =((1+p_ipm)^(1/12)-1)*F7 | G11: =((1+p_ipm)^(1/12)-1)*G7 | H11: =((1+p_ipm)^(1/12)-1)*H7 | I11: =((1+p_ipm)^(1/12)-1)*I7 | J11: =((1+p_ipm)^(1/12)-1)*J7 | K11: =((1+p_ipm)^(1/12)-1)*K7 | ... LI11: =((1+p_ipm)^(1/12)-1)*LI7
B12: Acumulado pendiente | D12: =IF($D11=0,0,$D11) | E12: =IF(E11=0,0,SUM($D11:E11)-SUM($D13:D13)) | F12: =IF(F11=0,0,SUM($D11:F11)-SUM($D13:E13)) | G12: =IF(G11=0,0,SUM($D11:G11)-SUM($D13:F13)) | H12: =IF(H11=0,0,SUM($D11:H11)-SUM($D13:G13)) | I12: =IF(I11=0,0,SUM($D11:I11)-SUM($D13:H13)) | J12: =IF(J11=0,0,SUM($D11:J11)-SUM($D13:I13)) | K12: =IF(K11=0,0,SUM($D11:K11)-SUM($D13:J13)) | L12: =IF(L11=0,0,SUM($D11:L11)-SUM($D13:K13)) | ... LI12: =IF(LI11=0,0,SUM($D11:LI11)-SUM($D13:LH13))
B13: Ajuste liberado | D13: =IF(D12>=p_gatillo,D12,0) | E13: =IF(E12>=p_gatillo,E12,0) | F13: =IF(F12>=p_gatillo,F12,0) | G13: =IF(G12>=p_gatillo,G12,0) | H13: =IF(H12>=p_gatillo,H12,0) | I13: =IF(I12>=p_gatillo,I12,0) | J13: =IF(J12>=p_gatillo,J12,0) | K13: =IF(K12>=p_gatillo,K12,0) | ... LI13: =IF(LI12>=p_gatillo,LI12,0)
B14: Factor de reajuste | D14: =TRUNC(IF(D7=0,1,1*(1+D13)*D7),5) | E14: =TRUNC(IF(E7=0,1,D14*(1+E13)*E7),5) | F14: =TRUNC(IF(F7=0,1,E14*(1+F13)*F7),5) | G14: =TRUNC(IF(G7=0,1,F14*(1+G13)*G7),5) | H14: =TRUNC(IF(H7=0,1,G14*(1+H13)*H7),5) | I14: =TRUNC(IF(I7=0,1,H14*(1+I13)*I7),5) | J14: =TRUNC(IF(J7=0,1,I14*(1+J13)*J7),5) | K14: =TRUNC(IF(K7=0,1,J14*(1+K13)*K7),5) | L14: =TRUNC(IF(L7=0,1,K14*(1+L13)*L7),5) | ... LI14: =TRUNC(IF(LI7=0,1,LH14*(1+LI13)*LI7),5)
B15: PPDMO fijo mensual | D15: =p_fijo_base*D14*D7 | E15: =p_fijo_base*E14*E7 | F15: =p_fijo_base*F14*F7 | G15: =p_fijo_base*G14*G7 | H15: =p_fijo_base*H14*H7 | I15: =p_fijo_base*I14*I7 | J15: =p_fijo_base*J14*J7 | K15: =p_fijo_base*K14*K7 | ... LI15: =p_fijo_base*LI14*LI7
